{
  "version": 8,
  "blockIdVersion": 11,
  "anchorX": 0,
  "anchorY": 0,
  "anchorZ": 0,
  "blocks": [
    {
      "x": -4,
      "y": 0,
      "z": -3,
      "name": "Rock_Cyberverse_Brick_Half",
      "rotation": 7
    },
    {
      "x": -4,
      "y": 1,
      "z": -3,
      "name": "Rock_Cyberverse_Brick_Half",
      "rotation": 7
    },
    {
      "x": -4,
      "y": 2,
      "z": -3,
      "name": "Rock_Cyberverse_Brick_Half",
      "rotation": 7
    },
    {
      "x": -4,
      "y": 3,
      "z": -3,
      "name": "Rock_Cyberverse_Brick_Half",
      "rotation": 7
    },
    {
      "x": -4,
      "y": 4,
      "z": -3,
      "name": "Rock_Cyberverse_Brick_Half",
      "rotation": 7
    },
    {
      "x": -4,
      "y": 5,
      "z": -3,
      "name": "Rock_Cyberverse_Brick_Half",
      "rotation": 7
    },
    {
      "x": -4,
      "y": 6,
      "z": -3,
      "name": "Rock_Cyberverse_Brick_Half",
      "rotation": 7
    },
    {
      "x": -4,
      "y": 7,
      "z": -3,
      "name": "Rock_Cyberverse_Brick_Half",
      "rotation": 7
    },
    {
      "x": -4,
      "y": 0,
      "z": -2,
      "name": "Build_Lightsource_Cyan"
    },
    {
      "x": -4,
      "y": 1,
      "z": -2,
      "name": "Build_Lightsource_Cyan"
    },
    {
      "x": -4,
      "y": 2,
      "z": -2,
      "name": "Build_Lightsource_Cyan"
    },
    {
      "x": -4,
      "y": 3,
      "z": -2,
      "name": "Build_Lightsource_Cyan"
    },
    {
      "x": -4,
      "y": 4,
      "z": -2,
      "name": "Build_Lightsource_Cyan"
    },
    {
      "x": -4,
      "y": 5,
      "z": -2,
      "name": "Build_Lightsource_Cyan"
    },
    {
      "x": -4,
      "y": 6,
      "z": -2,
      "name": "Build_Lightsource_Cyan"
    },
    {
      "x": -4,
      "y": 7,
      "z": -2,
      "name": "Build_Lightsource_Cyan"
    },
    {
      "x": -4,
      "y": 0,
      "z": -1,
      "name": "Rock_Cyberverse_Brick_Half",
      "rotation": 4
    },
    {
      "x": -4,
      "y": 1,
      "z": -1,
      "name": "Rock_Cyberverse_Brick_Half",
      "rotation": 4
    },
    {
      "x": -4,
      "y": 2,
      "z": -1,
      "name": "Rock_Stone_Cyberverse_Brick"
    },
    {
      "x": -4,
      "y": 3,
      "z": -1,
      "name": "Rock_Stone_Cyberverse_Brick"
    },
    {
      "x": -4,
      "y": 4,
      "z": -1,
      "name": "Rock_Stone_Cyberverse_Brick"
    },
    {
      "x": -4,
      "y": 5,
      "z": -1,
      "name": "Rock_Stone_Cyberverse_Brick"
    },
    {
      "x": -4,
      "y": 6,
      "z": -1,
      "name": "Rock_Stone_Cyberverse_Brick"
    },
    {
      "x": -4,
      "y": 7,
      "z": -1,
      "name": "Rock_Stone_Cyberverse_Brick"
    },
    {
      "x": -4,
      "y": 2,
      "z": 0,
      "name": "Rock_Cyberverse_Brick_Half",
      "rotation": 8
    },
    {
      "x": -4,
      "y": 3,
      "z": 0,
      "name": "Circuit_Wire"
    },
    {
      "x": -4,
      "y": 4,
      "z": 0,
      "name": "Rock_Stone_Cyberverse_Brick"
    },
    {
      "x": -4,
      "y": 5,
      "z": 0,
      "name": "Rock_Stone_Cyberverse_Brick"
    },
    {
      "x": -4,
      "y": 6,
      "z": 0,
      "name": "Rock_Stone_Cyberverse_Brick"
    },
    {
      "x": -4,
      "y": 7,
      "z": 0,
      "name": "Rock_Stone_Cyberverse_Brick"
    },
    {
      "x": -4,
      "y": 0,
      "z": 1,
      "name": "Rock_Cyberverse_Brick_Half",
      "rotation": 6
    },
    {
      "x": -4,
      "y": 1,
      "z": 1,
      "name": "Rock_Cyberverse_Brick_Half",
      "rotation": 6
    },
    {
      "x": -4,
      "y": 2,
      "z": 1,
      "name": "Rock_Stone_Cyberverse_Brick"
    },
    {
      "x": -4,
      "y": 3,
      "z": 1,
      "name": "Rock_Stone_Cyberverse_Brick"
    },
    {
      "x": -4,
      "y": 4,
      "z": 1,
      "name": "Rock_Stone_Cyberverse_Brick"
    },
    {
      "x": -4,
      "y": 5,
      "z": 1,
      "name": "Rock_Stone_Cyberverse_Brick"
    },
    {
      "x": -4,
      "y": 6,
      "z": 1,
      "name": "Rock_Stone_Cyberverse_Brick"
    },
    {
      "x": -4,
      "y": 7,
      "z": 1,
      "name": "Rock_Stone_Cyberverse_Brick"
    },
    {
      "x": -4,
      "y": 0,
      "z": 2,
      "name": "Build_Lightsource_Cyan"
    },
    {
      "x": -4,
      "y": 1,
      "z": 2,
      "name": "Build_Lightsource_Cyan"
    },
    {
      "x": -4,
      "y": 2,
      "z": 2,
      "name": "Build_Lightsource_Cyan"
    },
    {
      "x": -4,
      "y": 3,
      "z": 2,
      "name": "Build_Lightsource_Cyan"
    },
    {
      "x": -4,
      "y": 4,
      "z": 2,
      "name": "Build_Lightsource_Cyan"
    },
    {
      "x": -4,
      "y": 5,
      "z": 2,
      "name": "Build_Lightsource_Cyan"
    },
    {
      "x": -4,
      "y": 6,
      "z": 2,
      "name": "Build_Lightsource_Cyan"
    },
    {
      "x": -4,
      "y": 7,
      "z": 2,
      "name": "Build_Lightsource_Cyan"
    },
    {
      "x": -4,
      "y": 0,
      "z": 3,
      "name": "Rock_Cyberverse_Brick_Half",
      "rotation": 7
    },
    {
      "x": -4,
      "y": 1,
      "z": 3,
      "name": "Rock_Cyberverse_Brick_Half",
      "rotation": 7
    },
    {
      "x": -4,
      "y": 2,
      "z": 3,
      "name": "Rock_Cyberverse_Brick_Half",
      "rotation": 7
    },
    {
      "x": -4,
      "y": 3,
      "z": 3,
      "name": "Rock_Cyberverse_Brick_Half",
      "rotation": 7
    },
    {
      "x": -4,
      "y": 4,
      "z": 3,
      "name": "Rock_Cyberverse_Brick_Half",
      "rotation": 7
    },
    {
      "x": -4,
      "y": 5,
      "z": 3,
      "name": "Rock_Cyberverse_Brick_Half",
      "rotation": 7
    },
    {
      "x": -4,
      "y": 6,
      "z": 3,
      "name": "Rock_Cyberverse_Brick_Half",
      "rotation": 7
    },
    {
      "x": -4,
      "y": 7,
      "z": 3,
      "name": "Rock_Cyberverse_Brick_Half",
      "rotation": 7
    },
    {
      "x": -3,
      "y": 0,
      "z": -4,
      "name": "Rock_Cyberverse_Brick_Half",
      "rotation": 6
    },
    {
      "x": -3,
      "y": 1,
      "z": -4,
      "name": "Rock_Cyberverse_Brick_Half",
      "rotation": 6
    },
    {
      "x": -3,
      "y": 2,
      "z": -4,
      "name": "Rock_Cyberverse_Brick_Half",
      "rotation": 6
    },
    {
      "x": -3,
      "y": 3,
      "z": -4,
      "name": "Rock_Cyberverse_Brick_Half",
      "rotation": 6
    },
    {
      "x": -3,
      "y": 4,
      "z": -4,
      "name": "Rock_Cyberverse_Brick_Half",
      "rotation": 6
    },
    {
      "x": -3,
      "y": 5,
      "z": -4,
      "name": "Rock_Cyberverse_Brick_Half",
      "rotation": 6
    },
    {
      "x": -3,
      "y": 6,
      "z": -4,
      "name": "Rock_Cyberverse_Brick_Half",
      "rotation": 6
    },
    {
      "x": -3,
      "y": 7,
      "z": -4,
      "name": "Rock_Cyberverse_Brick_Half",
      "rotation": 6
    },
    {
      "x": -3,
      "y": 0,
      "z": -3,
      "name": "Computer_Casing_Glow"
    },
    {
      "x": -3,
      "y": 1,
      "z": -3,
      "name": "Computer_Casing_Glow"
    },
    {
      "x": -3,
      "y": 2,
      "z": -3,
      "name": "Computer_Casing_Glow"
    },
    {
      "x": -3,
      "y": 3,
      "z": -3,
      "name": "Computer_Casing_Glow"
    },
    {
      "x": -3,
      "y": 4,
      "z": -3,
      "name": "Computer_Casing_Glow"
    },
    {
      "x": -3,
      "y": 5,
      "z": -3,
      "name": "Computer_Casing_Glow"
    },
    {
      "x": -3,
      "y": 6,
      "z": -3,
      "name": "Computer_Casing_Glow"
    },
    {
      "x": -3,
      "y": 7,
      "z": -3,
      "name": "Computer_Casing_Glow"
    },
    {
      "x": -3,
      "y": 0,
      "z": -2,
      "name": "Rock_Cyberverse_Brick_Half",
      "rotation": 5
    },
    {
      "x": -3,
      "y": 1,
      "z": -2,
      "name": "Rock_Cyberverse_Brick_Half",
      "rotation": 5
    },
    {
      "x": -3,
      "y": 2,
      "z": -2,
      "name": "Rock_Cyberverse_Brick_Half",
      "rotation": 5
    },
    {
      "x": -3,
      "y": 3,
      "z": -2,
      "name": "Rock_Cyberverse_Brick_Half",
      "rotation": 5
    },
    {
      "x": -3,
      "y": 4,
      "z": -2,
      "name": "Rock_Cyberverse_Brick_Half",
      "rotation": 5
    },
    {
      "x": -3,
      "y": 5,
      "z": -2,
      "name": "Rock_Cyberverse_Brick_Half",
      "rotation": 5
    },
    {
      "x": -3,
      "y": 6,
      "z": -2,
      "name": "Rock_Cyberverse_Brick_Half",
      "rotation": 5
    },
    {
      "x": -3,
      "y": 7,
      "z": -2,
      "name": "Rock_Stone_Cyberverse_Brick"
    },
    {
      "x": -3,
      "y": 7,
      "z": -1,
      "name": "Rock_Stone_Cyberverse_Brick"
    },
    {
      "x": -3,
      "y": 7,
      "z": 0,
      "name": "Rock_Stone_Cyberverse_Brick"
    },
    {
      "x": -3,
      "y": 7,
      "z": 1,
      "name": "Rock_Stone_Cyberverse_Brick"
    },
    {
      "x": -3,
      "y": 0,
      "z": 2,
      "name": "Rock_Cyberverse_Brick_Half",
      "rotation": 5
    },
    {
      "x": -3,
      "y": 1,
      "z": 2,
      "name": "Rock_Cyberverse_Brick_Half",
      "rotation": 5
    },
    {
      "x": -3,
      "y": 2,
      "z": 2,
      "name": "Rock_Cyberverse_Brick_Half",
      "rotation": 5
    },
    {
      "x": -3,
      "y": 3,
      "z": 2,
      "name": "Rock_Cyberverse_Brick_Half",
      "rotation": 5
    },
    {
      "x": -3,
      "y": 4,
      "z": 2,
      "name": "Rock_Cyberverse_Brick_Half",
      "rotation": 5
    },
    {
      "x": -3,
      "y": 5,
      "z": 2,
      "name": "Rock_Cyberverse_Brick_Half",
      "rotation": 5
    },
    {
      "x": -3,
      "y": 6,
      "z": 2,
      "name": "Rock_Cyberverse_Brick_Half",
      "rotation": 5
    },
    {
      "x": -3,
      "y": 7,
      "z": 2,
      "name": "Rock_Stone_Cyberverse_Brick"
    },
    {
      "x": -3,
      "y": 0,
      "z": 3,
      "name": "Computer_Casing_Glow"
    },
    {
      "x": -3,
      "y": 1,
      "z": 3,
      "name": "Computer_Casing_Glow"
    },
    {
      "x": -3,
      "y": 2,
      "z": 3,
      "name": "Computer_Casing_Glow"
    },
    {
      "x": -3,
      "y": 3,
      "z": 3,
      "name": "Computer_Casing_Glow"
    },
    {
      "x": -3,
      "y": 4,
      "z": 3,
      "name": "Computer_Casing_Glow"
    },
    {
      "x": -3,
      "y": 5,
      "z": 3,
      "name": "Computer_Casing_Glow"
    },
    {
      "x": -3,
      "y": 6,
      "z": 3,
      "name": "Computer_Casing_Glow"
    },
    {
      "x": -3,
      "y": 7,
      "z": 3,
      "name": "Computer_Casing_Glow"
    },
    {
      "x": -3,
      "y": 0,
      "z": 4,
      "name": "Rock_Cyberverse_Brick_Half",
      "rotation": 4
    },
    {
      "x": -3,
      "y": 1,
      "z": 4,
      "name": "Rock_Cyberverse_Brick_Half",
      "rotation": 4
    },
    {
      "x": -3,
      "y": 2,
      "z": 4,
      "name": "Rock_Cyberverse_Brick_Half",
      "rotation": 4
    },
    {
      "x": -3,
      "y": 3,
      "z": 4,
      "name": "Rock_Cyberverse_Brick_Half",
      "rotation": 4
    },
    {
      "x": -3,
      "y": 4,
      "z": 4,
      "name": "Rock_Cyberverse_Brick_Half",
      "rotation": 4
    },
    {
      "x": -3,
      "y": 5,
      "z": 4,
      "name": "Rock_Cyberverse_Brick_Half",
      "rotation": 4
    },
    {
      "x": -3,
      "y": 6,
      "z": 4,
      "name": "Rock_Cyberverse_Brick_Half",
      "rotation": 4
    },
    {
      "x": -3,
      "y": 7,
      "z": 4,
      "name": "Rock_Cyberverse_Brick_Half",
      "rotation": 4
    },
    {
      "x": -2,
      "y": 0,
      "z": -4,
      "name": "Build_Lightsource_Cyan"
    },
    {
      "x": -2,
      "y": 1,
      "z": -4,
      "name": "Build_Lightsource_Cyan"
    },
    {
      "x": -2,
      "y": 2,
      "z": -4,
      "name": "Build_Lightsource_Cyan"
    },
    {
      "x": -2,
      "y": 3,
      "z": -4,
      "name": "Build_Lightsource_Cyan"
    },
    {
      "x": -2,
      "y": 4,
      "z": -4,
      "name": "Build_Lightsource_Cyan"
    },
    {
      "x": -2,
      "y": 5,
      "z": -4,
      "name": "Build_Lightsource_Cyan"
    },
    {
      "x": -2,
      "y": 6,
      "z": -4,
      "name": "Build_Lightsource_Cyan"
    },
    {
      "x": -2,
      "y": 7,
      "z": -4,
      "name": "Build_Lightsource_Cyan"
    },
    {
      "x": -2,
      "y": 0,
      "z": -3,
      "name": "Rock_Cyberverse_Brick_Half",
      "rotation": 4
    },
    {
      "x": -2,
      "y": 1,
      "z": -3,
      "name": "Rock_Cyberverse_Brick_Half",
      "rotation": 4
    },
    {
      "x": -2,
      "y": 2,
      "z": -3,
      "name": "Rock_Cyberverse_Brick_Half",
      "rotation": 4
    },
    {
      "x": -2,
      "y": 3,
      "z": -3,
      "name": "Rock_Cyberverse_Brick_Half",
      "rotation": 4
    },
    {
      "x": -2,
      "y": 4,
      "z": -3,
      "name": "Rock_Cyberverse_Brick_Half",
      "rotation": 4
    },
    {
      "x": -2,
      "y": 5,
      "z": -3,
      "name": "Rock_Cyberverse_Brick_Half",
      "rotation": 4
    },
    {
      "x": -2,
      "y": 6,
      "z": -3,
      "name": "Rock_Cyberverse_Brick_Half",
      "rotation": 4
    },
    {
      "x": -2,
      "y": 7,
      "z": -3,
      "name": "Rock_Stone_Cyberverse_Brick"
    },
    {
      "x": -2,
      "y": 7,
      "z": -2,
      "name": "Rock_Stone_Cyberverse_Brick"
    },
    {
      "x": -2,
      "y": 7,
      "z": -1,
      "name": "Rock_Stone_Cyberverse_Brick"
    },
    {
      "x": -2,
      "y": 7,
      "z": 0,
      "name": "Rock_Stone_Cyberverse_Brick"
    },
    {
      "x": -2,
      "y": 7,
      "z": 1,
      "name": "Rock_Stone_Cyberverse_Brick"
    },
    {
      "x": -2,
      "y": 7,
      "z": 2,
      "name": "Rock_Stone_Cyberverse_Brick"
    },
    {
      "x": -2,
      "y": 0,
      "z": 3,
      "name": "Rock_Cyberverse_Brick_Half",
      "rotation": 6
    },
    {
      "x": -2,
      "y": 1,
      "z": 3,
      "name": "Rock_Cyberverse_Brick_Half",
      "rotation": 6
    },
    {
      "x": -2,
      "y": 2,
      "z": 3,
      "name": "Rock_Cyberverse_Brick_Half",
      "rotation": 6
    },
    {
      "x": -2,
      "y": 3,
      "z": 3,
      "name": "Rock_Cyberverse_Brick_Half",
      "rotation": 6
    },
    {
      "x": -2,
      "y": 4,
      "z": 3,
      "name": "Rock_Cyberverse_Brick_Half",
      "rotation": 6
    },
    {
      "x": -2,
      "y": 5,
      "z": 3,
      "name": "Rock_Cyberverse_Brick_Half",
      "rotation": 6
    },
    {
      "x": -2,
      "y": 6,
      "z": 3,
      "name": "Rock_Cyberverse_Brick_Half",
      "rotation": 6
    },
    {
      "x": -2,
      "y": 7,
      "z": 3,
      "name": "Rock_Stone_Cyberverse_Brick"
    },
    {
      "x": -2,
      "y": 0,
      "z": 4,
      "name": "Build_Lightsource_Cyan"
    },
    {
      "x": -2,
      "y": 1,
      "z": 4,
      "name": "Build_Lightsource_Cyan"
    },
    {
      "x": -2,
      "y": 2,
      "z": 4,
      "name": "Build_Lightsource_Cyan"
    },
    {
      "x": -2,
      "y": 3,
      "z": 4,
      "name": "Build_Lightsource_Cyan"
    },
    {
      "x": -2,
      "y": 4,
      "z": 4,
      "name": "Build_Lightsource_Cyan"
    },
    {
      "x": -2,
      "y": 5,
      "z": 4,
      "name": "Build_Lightsource_Cyan"
    },
    {
      "x": -2,
      "y": 6,
      "z": 4,
      "name": "Build_Lightsource_Cyan"
    },
    {
      "x": -2,
      "y": 7,
      "z": 4,
      "name": "Build_Lightsource_Cyan"
    },
    {
      "x": -1,
      "y": 0,
      "z": -4,
      "name": "Rock_Cyberverse_Brick_Half",
      "rotation": 5
    },
    {
      "x": -1,
      "y": 1,
      "z": -4,
      "name": "Rock_Cyberverse_Brick_Half",
      "rotation": 5
    },
    {
      "x": -1,
      "y": 2,
      "z": -4,
      "name": "Rock_Stone_Cyberverse_Brick"
    },
    {
      "x": -1,
      "y": 3,
      "z": -4,
      "name": "Rock_Stone_Cyberverse_Brick"
    },
    {
      "x": -1,
      "y": 4,
      "z": -4,
      "name": "Rock_Stone_Cyberverse_Brick"
    },
    {
      "x": -1,
      "y": 5,
      "z": -4,
      "name": "Rock_Stone_Cyberverse_Brick"
    },
    {
      "x": -1,
      "y": 6,
      "z": -4,
      "name": "Rock_Stone_Cyberverse_Brick"
    },
    {
      "x": -1,
      "y": 7,
      "z": -4,
      "name": "Rock_Stone_Cyberverse_Brick"
    },
    {
      "x": -1,
      "y": 4,
      "z": -3,
      "name": "Rock_Cyberverse_Brick_Half",
      "rotation": 8
    },
    {
      "x": -1,
      "y": 5,
      "z": -3,
      "name": "File_Folder",
      "components": {
        "Components": {
          "PlacedByInteraction": {
            "WhoPlacedUuid": {
              "$binary": "MPHUpLOaS6efxfnko+aohw==",
              "$type": "04"
            }
          },
          "ItemContainerBlock": {
            "ItemContainer": {
              "Capacity": 9,
              "Items": {
                "1": {
                  "Id": "Spaghetti_Code",
                  "Quantity": 4,
                  "Durability": 0.0,
                  "MaxDurability": 0.0,
                  "OverrideDroppedItemAnimation": false
                },
                "2": {
                  "Id": "Spaghetti_Code",
                  "Quantity": 3,
                  "Durability": 0.0,
                  "MaxDurability": 0.0,
                  "OverrideDroppedItemAnimation": false
                },
                "4": {
                  "Id": "Spaghetti_Code",
                  "Quantity": 3,
                  "Durability": 0.0,
                  "MaxDurability": 0.0,
                  "OverrideDroppedItemAnimation": false
                },
                "5": {
                  "Id": "Featore",
                  "Quantity": 2,
                  "Durability": 0.0,
                  "MaxDurability": 0.0,
                  "OverrideDroppedItemAnimation": false
                }
              }
            },
            "Capacity": 9
          }
        }
      },
      "rotation": 2
    },
    {
      "x": -1,
      "y": 7,
      "z": -3,
      "name": "Rock_Stone_Cyberverse_Brick"
    },
    {
      "x": -1,
      "y": 7,
      "z": -2,
      "name": "Rock_Stone_Cyberverse_Brick"
    },
    {
      "x": -1,
      "y": 2,
      "z": -1,
      "name": "Rock_Cyberverse_Brick_Half",
      "rotation": 8
    },
    {
      "x": -1,
      "y": 3,
      "z": -1,
      "name": "Rock_Cyberverse_Brick_Half",
      "rotation": 8
    },
    {
      "x": -1,
      "y": 6,
      "z": -1,
      "name": "Rock_Cyberverse_Brick_Half",
      "rotation": 8
    },
    {
      "x": -1,
      "y": 7,
      "z": -1,
      "name": "Rock_Cyberverse_Brick_Half",
      "rotation": 8
    },
    {
      "x": -1,
      "y": 0,
      "z": 0,
      "name": "Rock_Cyberverse_Brick_Half"
    },
    {
      "x": -1,
      "y": 4,
      "z": 0,
      "name": "Rock_Cyberverse_Brick_Half"
    },
    {
      "x": -1,
      "y": 0,
      "z": 1,
      "name": "Rock_Cyberverse_Brick_Half",
      "rotation": 8
    },
    {
      "x": -1,
      "y": 4,
      "z": 1,
      "name": "Rock_Cyberverse_Brick_Half",
      "rotation": 8
    },
    {
      "x": -1,
      "y": 7,
      "z": 2,
      "name": "Rock_Stone_Cyberverse_Brick"
    },
    {
      "x": -1,
      "y": 7,
      "z": 3,
      "name": "Rock_Stone_Cyberverse_Brick"
    },
    {
      "x": -1,
      "y": 0,
      "z": 4,
      "name": "Rock_Cyberverse_Brick_Half",
      "rotation": 5
    },
    {
      "x": -1,
      "y": 1,
      "z": 4,
      "name": "Rock_Cyberverse_Brick_Half",
      "rotation": 5
    },
    {
      "x": -1,
      "y": 2,
      "z": 4,
      "name": "Rock_Stone_Cyberverse_Brick"
    },
    {
      "x": -1,
      "y": 3,
      "z": 4,
      "name": "Rock_Stone_Cyberverse_Brick"
    },
    {
      "x": -1,
      "y": 4,
      "z": 4,
      "name": "Rock_Stone_Cyberverse_Brick"
    },
    {
      "x": -1,
      "y": 5,
      "z": 4,
      "name": "Rock_Stone_Cyberverse_Brick"
    },
    {
      "x": -1,
      "y": 6,
      "z": 4,
      "name": "Rock_Stone_Cyberverse_Brick"
    },
    {
      "x": -1,
      "y": 7,
      "z": 4,
      "name": "Rock_Stone_Cyberverse_Brick"
    },
    {
      "x": 0,
      "y": 2,
      "z": -4,
      "name": "Rock_Cyberverse_Brick_Half",
      "rotation": 8
    },
    {
      "x": 0,
      "y": 3,
      "z": -4,
      "name": "Circuit_Wire"
    },
    {
      "x": 0,
      "y": 4,
      "z": -4,
      "name": "Rock_Stone_Cyberverse_Brick"
    },
    {
      "x": 0,
      "y": 5,
      "z": -4,
      "name": "Rock_Stone_Cyberverse_Brick"
    },
    {
      "x": 0,
      "y": 6,
      "z": -4,
      "name": "Rock_Stone_Cyberverse_Brick"
    },
    {
      "x": 0,
      "y": 7,
      "z": -4,
      "name": "Rock_Stone_Cyberverse_Brick"
    },
    {
      "x": 0,
      "y": 4,
      "z": -3,
      "name": "Rock_Cyberverse_Brick_Half",
      "rotation": 8
    },
    {
      "x": 0,
      "y": 7,
      "z": -3,
      "name": "Rock_Stone_Cyberverse_Brick"
    },
    {
      "x": 0,
      "y": 7,
      "z": -2,
      "name": "Rock_Stone_Cyberverse_Brick"
    },
    {
      "x": 0,
      "y": 2,
      "z": -1,
      "name": "Rock_Cyberverse_Brick_Half"
    },
    {
      "x": 0,
      "y": 3,
      "z": -1,
      "name": "Rock_Cyberverse_Brick_Half"
    },
    {
      "x": 0,
      "y": 6,
      "z": -1,
      "name": "Rock_Cyberverse_Brick_Half"
    },
    {
      "x": 0,
      "y": 7,
      "z": -1,
      "name": "Rock_Cyberverse_Brick_Half"
    },
    {
      "x": 0,
      "y": 0,
      "z": 0,
      "name": "Build_Lightsource_Blue"
    },
    {
      "x": 0,
      "y": 1,
      "z": 0,
      "name": "Build_Lightsource_Blue"
    },
    {
      "x": 0,
      "y": 2,
      "z": 0,
      "name": "Build_Lightsource_Blue"
    },
    {
      "x": 0,
      "y": 3,
      "z": 0,
      "name": "Build_Lightsource_Blue"
    },
    {
      "x": 0,
      "y": 4,
      "z": 0,
      "name": "Build_Lightsource_Blue"
    },
    {
      "x": 0,
      "y": 5,
      "z": 0,
      "name": "Build_Lightsource_Blue"
    },
    {
      "x": 0,
      "y": 6,
      "z": 0,
      "name": "Build_Lightsource_Blue"
    },
    {
      "x": 0,
      "y": 7,
      "z": 0,
      "name": "Build_Lightsource_Blue"
    },
    {
      "x": 0,
      "y": 0,
      "z": 1,
      "name": "Rock_Cyberverse_Brick_Half"
    },
    {
      "x": 0,
      "y": 1,
      "z": 1,
      "name": "Rock_Cyberverse_Brick_Half"
    },
    {
      "x": 0,
      "y": 4,
      "z": 1,
      "name": "Rock_Cyberverse_Brick_Half"
    },
    {
      "x": 0,
      "y": 5,
      "z": 1,
      "name": "Rock_Cyberverse_Brick_Half"
    },
    {
      "x": 0,
      "y": 7,
      "z": 2,
      "name": "Rock_Stone_Cyberverse_Brick"
    },
    {
      "x": 0,
      "y": 7,
      "z": 3,
      "name": "Rock_Stone_Cyberverse_Brick"
    },
    {
      "x": 0,
      "y": 2,
      "z": 4,
      "name": "Rock_Cyberverse_Brick_Half",
      "rotation": 8
    },
    {
      "x": 0,
      "y": 3,
      "z": 4,
      "name": "Circuit_Wire"
    },
    {
      "x": 0,
      "y": 4,
      "z": 4,
      "name": "Rock_Stone_Cyberverse_Brick"
    },
    {
      "x": 0,
      "y": 5,
      "z": 4,
      "name": "Rock_Stone_Cyberverse_Brick"
    },
    {
      "x": 0,
      "y": 6,
      "z": 4,
      "name": "Rock_Stone_Cyberverse_Brick"
    },
    {
      "x": 0,
      "y": 7,
      "z": 4,
      "name": "Rock_Stone_Cyberverse_Brick"
    },
    {
      "x": 1,
      "y": 0,
      "z": -4,
      "name": "Rock_Cyberverse_Brick_Half",
      "rotation": 7
    },
    {
      "x": 1,
      "y": 1,
      "z": -4,
      "name": "Rock_Cyberverse_Brick_Half",
      "rotation": 7
    },
    {
      "x": 1,
      "y": 2,
      "z": -4,
      "name": "Rock_Stone_Cyberverse_Brick"
    },
    {
      "x": 1,
      "y": 3,
      "z": -4,
      "name": "Rock_Stone_Cyberverse_Brick"
    },
    {
      "x": 1,
      "y": 4,
      "z": -4,
      "name": "Rock_Stone_Cyberverse_Brick"
    },
    {
      "x": 1,
      "y": 5,
      "z": -4,
      "name": "Rock_Stone_Cyberverse_Brick"
    },
    {
      "x": 1,
      "y": 6,
      "z": -4,
      "name": "Rock_Stone_Cyberverse_Brick"
    },
    {
      "x": 1,
      "y": 7,
      "z": -4,
      "name": "Rock_Stone_Cyberverse_Brick"
    },
    {
      "x": 1,
      "y": 4,
      "z": -3,
      "name": "Rock_Cyberverse_Brick_Half",
      "rotation": 8
    },
    {
      "x": 1,
      "y": 7,
      "z": -3,
      "name": "Rock_Stone_Cyberverse_Brick"
    },
    {
      "x": 1,
      "y": 7,
      "z": -2,
      "name": "Rock_Stone_Cyberverse_Brick"
    },
    {
      "x": 1,
      "y": 1,
      "z": -1,
      "name": "Rock_Cyberverse_Brick_Half",
      "rotation": 8
    },
    {
      "x": 1,
      "y": 2,
      "z": -1,
      "name": "Rock_Cyberverse_Brick_Half",
      "rotation": 8
    },
    {
      "x": 1,
      "y": 5,
      "z": -1,
      "name": "Rock_Cyberverse_Brick_Half",
      "rotation": 8
    },
    {
      "x": 1,
      "y": 6,
      "z": -1,
      "name": "Rock_Cyberverse_Brick_Half",
      "rotation": 8
    },
    {
      "x": 1,
      "y": 1,
      "z": 0,
      "name": "Rock_Cyberverse_Brick_Half"
    },
    {
      "x": 1,
      "y": 2,
      "z": 0,
      "name": "Rock_Cyberverse_Brick_Half"
    },
    {
      "x": 1,
      "y": 5,
      "z": 0,
      "name": "Rock_Cyberverse_Brick_Half"
    },
    {
      "x": 1,
      "y": 6,
      "z": 0,
      "name": "Rock_Cyberverse_Brick_Half"
    },
    {
      "x": 1,
      "y": 0,
      "z": 1,
      "name": "Rock_Cyberverse_Brick_Half",
      "rotation": 8
    },
    {
      "x": 1,
      "y": 1,
      "z": 1,
      "name": "Rock_Cyberverse_Brick_Half",
      "rotation": 8
    },
    {
      "x": 1,
      "y": 4,
      "z": 1,
      "name": "Rock_Cyberverse_Brick_Half",
      "rotation": 8
    },
    {
      "x": 1,
      "y": 5,
      "z": 1,
      "name": "Rock_Cyberverse_Brick_Half",
      "rotation": 8
    },
    {
      "x": 1,
      "y": 7,
      "z": 2,
      "name": "Rock_Stone_Cyberverse_Brick"
    },
    {
      "x": 1,
      "y": 7,
      "z": 3,
      "name": "Rock_Stone_Cyberverse_Brick"
    },
    {
      "x": 1,
      "y": 0,
      "z": 4,
      "name": "Rock_Cyberverse_Brick_Half",
      "rotation": 7
    },
    {
      "x": 1,
      "y": 1,
      "z": 4,
      "name": "Rock_Cyberverse_Brick_Half",
      "rotation": 7
    },
    {
      "x": 1,
      "y": 2,
      "z": 4,
      "name": "Rock_Stone_Cyberverse_Brick"
    },
    {
      "x": 1,
      "y": 3,
      "z": 4,
      "name": "Rock_Stone_Cyberverse_Brick"
    },
    {
      "x": 1,
      "y": 4,
      "z": 4,
      "name": "Rock_Stone_Cyberverse_Brick"
    },
    {
      "x": 1,
      "y": 5,
      "z": 4,
      "name": "Rock_Stone_Cyberverse_Brick"
    },
    {
      "x": 1,
      "y": 6,
      "z": 4,
      "name": "Rock_Stone_Cyberverse_Brick"
    },
    {
      "x": 1,
      "y": 7,
      "z": 4,
      "name": "Rock_Stone_Cyberverse_Brick"
    },
    {
      "x": 2,
      "y": 0,
      "z": -4,
      "name": "Build_Lightsource_Cyan"
    },
    {
      "x": 2,
      "y": 1,
      "z": -4,
      "name": "Build_Lightsource_Cyan"
    },
    {
      "x": 2,
      "y": 2,
      "z": -4,
      "name": "Build_Lightsource_Cyan"
    },
    {
      "x": 2,
      "y": 3,
      "z": -4,
      "name": "Build_Lightsource_Cyan"
    },
    {
      "x": 2,
      "y": 4,
      "z": -4,
      "name": "Build_Lightsource_Cyan"
    },
    {
      "x": 2,
      "y": 5,
      "z": -4,
      "name": "Build_Lightsource_Cyan"
    },
    {
      "x": 2,
      "y": 6,
      "z": -4,
      "name": "Build_Lightsource_Cyan"
    },
    {
      "x": 2,
      "y": 7,
      "z": -4,
      "name": "Build_Lightsource_Cyan"
    },
    {
      "x": 2,
      "y": 0,
      "z": -3,
      "name": "Rock_Cyberverse_Brick_Half",
      "rotation": 4
    },
    {
      "x": 2,
      "y": 1,
      "z": -3,
      "name": "Rock_Cyberverse_Brick_Half",
      "rotation": 4
    },
    {
      "x": 2,
      "y": 2,
      "z": -3,
      "name": "Rock_Cyberverse_Brick_Half",
      "rotation": 4
    },
    {
      "x": 2,
      "y": 3,
      "z": -3,
      "name": "Rock_Cyberverse_Brick_Half",
      "rotation": 4
    },
    {
      "x": 2,
      "y": 4,
      "z": -3,
      "name": "Rock_Cyberverse_Brick_Half",
      "rotation": 4
    },
    {
      "x": 2,
      "y": 5,
      "z": -3,
      "name": "Rock_Cyberverse_Brick_Half",
      "rotation": 4
    },
    {
      "x": 2,
      "y": 6,
      "z": -3,
      "name": "Rock_Cyberverse_Brick_Half",
      "rotation": 4
    },
    {
      "x": 2,
      "y": 7,
      "z": -3,
      "name": "Rock_Stone_Cyberverse_Brick"
    },
    {
      "x": 2,
      "y": 7,
      "z": -2,
      "name": "Rock_Stone_Cyberverse_Brick"
    },
    {
      "x": 2,
      "y": 7,
      "z": -1,
      "name": "Rock_Stone_Cyberverse_Brick"
    },
    {
      "x": 2,
      "y": 7,
      "z": 0,
      "name": "Rock_Stone_Cyberverse_Brick"
    },
    {
      "x": 2,
      "y": 7,
      "z": 1,
      "name": "Rock_Stone_Cyberverse_Brick"
    },
    {
      "x": 2,
      "y": 7,
      "z": 2,
      "name": "Rock_Stone_Cyberverse_Brick"
    },
    {
      "x": 2,
      "y": 0,
      "z": 3,
      "name": "Rock_Cyberverse_Brick_Half",
      "rotation": 6
    },
    {
      "x": 2,
      "y": 1,
      "z": 3,
      "name": "Rock_Cyberverse_Brick_Half",
      "rotation": 6
    },
    {
      "x": 2,
      "y": 2,
      "z": 3,
      "name": "Rock_Cyberverse_Brick_Half",
      "rotation": 6
    },
    {
      "x": 2,
      "y": 3,
      "z": 3,
      "name": "Rock_Cyberverse_Brick_Half",
      "rotation": 6
    },
    {
      "x": 2,
      "y": 4,
      "z": 3,
      "name": "Rock_Cyberverse_Brick_Half",
      "rotation": 6
    },
    {
      "x": 2,
      "y": 5,
      "z": 3,
      "name": "Rock_Cyberverse_Brick_Half",
      "rotation": 6
    },
    {
      "x": 2,
      "y": 6,
      "z": 3,
      "name": "Rock_Cyberverse_Brick_Half",
      "rotation": 6
    },
    {
      "x": 2,
      "y": 7,
      "z": 3,
      "name": "Rock_Stone_Cyberverse_Brick"
    },
    {
      "x": 2,
      "y": 0,
      "z": 4,
      "name": "Build_Lightsource_Cyan"
    },
    {
      "x": 2,
      "y": 1,
      "z": 4,
      "name": "Build_Lightsource_Cyan"
    },
    {
      "x": 2,
      "y": 2,
      "z": 4,
      "name": "Build_Lightsource_Cyan"
    },
    {
      "x": 2,
      "y": 3,
      "z": 4,
      "name": "Build_Lightsource_Cyan"
    },
    {
      "x": 2,
      "y": 4,
      "z": 4,
      "name": "Build_Lightsource_Cyan"
    },
    {
      "x": 2,
      "y": 5,
      "z": 4,
      "name": "Build_Lightsource_Cyan"
    },
    {
      "x": 2,
      "y": 6,
      "z": 4,
      "name": "Build_Lightsource_Cyan"
    },
    {
      "x": 2,
      "y": 7,
      "z": 4,
      "name": "Build_Lightsource_Cyan"
    },
    {
      "x": 3,
      "y": 0,
      "z": -4,
      "name": "Rock_Cyberverse_Brick_Half",
      "rotation": 6
    },
    {
      "x": 3,
      "y": 1,
      "z": -4,
      "name": "Rock_Cyberverse_Brick_Half",
      "rotation": 6
    },
    {
      "x": 3,
      "y": 2,
      "z": -4,
      "name": "Rock_Cyberverse_Brick_Half",
      "rotation": 6
    },
    {
      "x": 3,
      "y": 3,
      "z": -4,
      "name": "Rock_Cyberverse_Brick_Half",
      "rotation": 6
    },
    {
      "x": 3,
      "y": 4,
      "z": -4,
      "name": "Rock_Cyberverse_Brick_Half",
      "rotation": 6
    },
    {
      "x": 3,
      "y": 5,
      "z": -4,
      "name": "Rock_Cyberverse_Brick_Half",
      "rotation": 6
    },
    {
      "x": 3,
      "y": 6,
      "z": -4,
      "name": "Rock_Cyberverse_Brick_Half",
      "rotation": 6
    },
    {
      "x": 3,
      "y": 7,
      "z": -4,
      "name": "Rock_Cyberverse_Brick_Half",
      "rotation": 6
    },
    {
      "x": 3,
      "y": 0,
      "z": -3,
      "name": "Computer_Casing_Glow"
    },
    {
      "x": 3,
      "y": 1,
      "z": -3,
      "name": "Computer_Casing_Glow"
    },
    {
      "x": 3,
      "y": 2,
      "z": -3,
      "name": "Computer_Casing_Glow"
    },
    {
      "x": 3,
      "y": 3,
      "z": -3,
      "name": "Computer_Casing_Glow"
    },
    {
      "x": 3,
      "y": 4,
      "z": -3,
      "name": "Computer_Casing_Glow"
    },
    {
      "x": 3,
      "y": 5,
      "z": -3,
      "name": "Computer_Casing_Glow"
    },
    {
      "x": 3,
      "y": 6,
      "z": -3,
      "name": "Computer_Casing_Glow"
    },
    {
      "x": 3,
      "y": 7,
      "z": -3,
      "name": "Computer_Casing_Glow"
    },
    {
      "x": 3,
      "y": 0,
      "z": -2,
      "name": "Rock_Cyberverse_Brick_Half",
      "rotation": 7
    },
    {
      "x": 3,
      "y": 1,
      "z": -2,
      "name": "Rock_Cyberverse_Brick_Half",
      "rotation": 7
    },
    {
      "x": 3,
      "y": 2,
      "z": -2,
      "name": "Rock_Cyberverse_Brick_Half",
      "rotation": 7
    },
    {
      "x": 3,
      "y": 3,
      "z": -2,
      "name": "Rock_Cyberverse_Brick_Half",
      "rotation": 7
    },
    {
      "x": 3,
      "y": 4,
      "z": -2,
      "name": "Rock_Cyberverse_Brick_Half",
      "rotation": 7
    },
    {
      "x": 3,
      "y": 5,
      "z": -2,
      "name": "Rock_Cyberverse_Brick_Half",
      "rotation": 7
    },
    {
      "x": 3,
      "y": 6,
      "z": -2,
      "name": "Rock_Cyberverse_Brick_Half",
      "rotation": 7
    },
    {
      "x": 3,
      "y": 7,
      "z": -2,
      "name": "Rock_Stone_Cyberverse_Brick"
    },
    {
      "x": 3,
      "y": 7,
      "z": -1,
      "name": "Rock_Stone_Cyberverse_Brick"
    },
    {
      "x": 3,
      "y": 7,
      "z": 0,
      "name": "Rock_Stone_Cyberverse_Brick"
    },
    {
      "x": 3,
      "y": 7,
      "z": 1,
      "name": "Rock_Stone_Cyberverse_Brick"
    },
    {
      "x": 3,
      "y": 0,
      "z": 2,
      "name": "Rock_Cyberverse_Brick_Half",
      "rotation": 7
    },
    {
      "x": 3,
      "y": 1,
      "z": 2,
      "name": "Rock_Cyberverse_Brick_Half",
      "rotation": 7
    },
    {
      "x": 3,
      "y": 2,
      "z": 2,
      "name": "Rock_Cyberverse_Brick_Half",
      "rotation": 7
    },
    {
      "x": 3,
      "y": 3,
      "z": 2,
      "name": "Rock_Cyberverse_Brick_Half",
      "rotation": 7
    },
    {
      "x": 3,
      "y": 4,
      "z": 2,
      "name": "Rock_Cyberverse_Brick_Half",
      "rotation": 7
    },
    {
      "x": 3,
      "y": 5,
      "z": 2,
      "name": "Rock_Cyberverse_Brick_Half",
      "rotation": 7
    },
    {
      "x": 3,
      "y": 6,
      "z": 2,
      "name": "Rock_Cyberverse_Brick_Half",
      "rotation": 7
    },
    {
      "x": 3,
      "y": 7,
      "z": 2,
      "name": "Rock_Stone_Cyberverse_Brick"
    },
    {
      "x": 3,
      "y": 0,
      "z": 3,
      "name": "Computer_Casing_Glow"
    },
    {
      "x": 3,
      "y": 1,
      "z": 3,
      "name": "Computer_Casing_Glow"
    },
    {
      "x": 3,
      "y": 2,
      "z": 3,
      "name": "Computer_Casing_Glow"
    },
    {
      "x": 3,
      "y": 3,
      "z": 3,
      "name": "Computer_Casing_Glow"
    },
    {
      "x": 3,
      "y": 4,
      "z": 3,
      "name": "Computer_Casing_Glow"
    },
    {
      "x": 3,
      "y": 5,
      "z": 3,
      "name": "Computer_Casing_Glow"
    },
    {
      "x": 3,
      "y": 6,
      "z": 3,
      "name": "Computer_Casing_Glow"
    },
    {
      "x": 3,
      "y": 7,
      "z": 3,
      "name": "Computer_Casing_Glow"
    },
    {
      "x": 3,
      "y": 0,
      "z": 4,
      "name": "Rock_Cyberverse_Brick_Half",
      "rotation": 4
    },
    {
      "x": 3,
      "y": 1,
      "z": 4,
      "name": "Rock_Cyberverse_Brick_Half",
      "rotation": 4
    },
    {
      "x": 3,
      "y": 2,
      "z": 4,
      "name": "Rock_Cyberverse_Brick_Half",
      "rotation": 4
    },
    {
      "x": 3,
      "y": 3,
      "z": 4,
      "name": "Rock_Cyberverse_Brick_Half",
      "rotation": 4
    },
    {
      "x": 3,
      "y": 4,
      "z": 4,
      "name": "Rock_Cyberverse_Brick_Half",
      "rotation": 4
    },
    {
      "x": 3,
      "y": 5,
      "z": 4,
      "name": "Rock_Cyberverse_Brick_Half",
      "rotation": 4
    },
    {
      "x": 3,
      "y": 6,
      "z": 4,
      "name": "Rock_Cyberverse_Brick_Half",
      "rotation": 4
    },
    {
      "x": 3,
      "y": 7,
      "z": 4,
      "name": "Rock_Cyberverse_Brick_Half",
      "rotation": 4
    },
    {
      "x": 4,
      "y": 0,
      "z": -3,
      "name": "Rock_Cyberverse_Brick_Half",
      "rotation": 5
    },
    {
      "x": 4,
      "y": 1,
      "z": -3,
      "name": "Rock_Cyberverse_Brick_Half",
      "rotation": 5
    },
    {
      "x": 4,
      "y": 2,
      "z": -3,
      "name": "Rock_Cyberverse_Brick_Half",
      "rotation": 5
    },
    {
      "x": 4,
      "y": 3,
      "z": -3,
      "name": "Rock_Cyberverse_Brick_Half",
      "rotation": 5
    },
    {
      "x": 4,
      "y": 4,
      "z": -3,
      "name": "Rock_Cyberverse_Brick_Half",
      "rotation": 5
    },
    {
      "x": 4,
      "y": 5,
      "z": -3,
      "name": "Rock_Cyberverse_Brick_Half",
      "rotation": 5
    },
    {
      "x": 4,
      "y": 6,
      "z": -3,
      "name": "Rock_Cyberverse_Brick_Half",
      "rotation": 5
    },
    {
      "x": 4,
      "y": 7,
      "z": -3,
      "name": "Rock_Cyberverse_Brick_Half",
      "rotation": 5
    },
    {
      "x": 4,
      "y": 0,
      "z": -2,
      "name": "Build_Lightsource_Cyan"
    },
    {
      "x": 4,
      "y": 1,
      "z": -2,
      "name": "Build_Lightsource_Cyan"
    },
    {
      "x": 4,
      "y": 2,
      "z": -2,
      "name": "Build_Lightsource_Cyan"
    },
    {
      "x": 4,
      "y": 3,
      "z": -2,
      "name": "Build_Lightsource_Cyan"
    },
    {
      "x": 4,
      "y": 4,
      "z": -2,
      "name": "Build_Lightsource_Cyan"
    },
    {
      "x": 4,
      "y": 5,
      "z": -2,
      "name": "Build_Lightsource_Cyan"
    },
    {
      "x": 4,
      "y": 6,
      "z": -2,
      "name": "Build_Lightsource_Cyan"
    },
    {
      "x": 4,
      "y": 7,
      "z": -2,
      "name": "Build_Lightsource_Cyan"
    },
    {
      "x": 4,
      "y": 0,
      "z": -1,
      "name": "Rock_Cyberverse_Brick_Half",
      "rotation": 4
    },
    {
      "x": 4,
      "y": 1,
      "z": -1,
      "name": "Rock_Cyberverse_Brick_Half",
      "rotation": 4
    },
    {
      "x": 4,
      "y": 2,
      "z": -1,
      "name": "Rock_Stone_Cyberverse_Brick"
    },
    {
      "x": 4,
      "y": 3,
      "z": -1,
      "name": "Rock_Stone_Cyberverse_Brick"
    },
    {
      "x": 4,
      "y": 4,
      "z": -1,
      "name": "Rock_Stone_Cyberverse_Brick"
    },
    {
      "x": 4,
      "y": 5,
      "z": -1,
      "name": "Rock_Stone_Cyberverse_Brick"
    },
    {
      "x": 4,
      "y": 6,
      "z": -1,
      "name": "Rock_Stone_Cyberverse_Brick"
    },
    {
      "x": 4,
      "y": 7,
      "z": -1,
      "name": "Rock_Stone_Cyberverse_Brick"
    },
    {
      "x": 4,
      "y": 2,
      "z": 0,
      "name": "Rock_Cyberverse_Brick_Half",
      "rotation": 8
    },
    {
      "x": 4,
      "y": 3,
      "z": 0,
      "name": "Circuit_Wire"
    },
    {
      "x": 4,
      "y": 4,
      "z": 0,
      "name": "Rock_Stone_Cyberverse_Brick"
    },
    {
      "x": 4,
      "y": 5,
      "z": 0,
      "name": "Rock_Stone_Cyberverse_Brick"
    },
    {
      "x": 4,
      "y": 6,
      "z": 0,
      "name": "Rock_Stone_Cyberverse_Brick"
    },
    {
      "x": 4,
      "y": 7,
      "z": 0,
      "name": "Rock_Stone_Cyberverse_Brick"
    },
    {
      "x": 4,
      "y": 0,
      "z": 1,
      "name": "Rock_Cyberverse_Brick_Half",
      "rotation": 6
    },
    {
      "x": 4,
      "y": 1,
      "z": 1,
      "name": "Rock_Cyberverse_Brick_Half",
      "rotation": 6
    },
    {
      "x": 4,
      "y": 2,
      "z": 1,
      "name": "Rock_Stone_Cyberverse_Brick"
    },
    {
      "x": 4,
      "y": 3,
      "z": 1,
      "name": "Rock_Stone_Cyberverse_Brick"
    },
    {
      "x": 4,
      "y": 4,
      "z": 1,
      "name": "Rock_Stone_Cyberverse_Brick"
    },
    {
      "x": 4,
      "y": 5,
      "z": 1,
      "name": "Rock_Stone_Cyberverse_Brick"
    },
    {
      "x": 4,
      "y": 6,
      "z": 1,
      "name": "Rock_Stone_Cyberverse_Brick"
    },
    {
      "x": 4,
      "y": 7,
      "z": 1,
      "name": "Rock_Stone_Cyberverse_Brick"
    },
    {
      "x": 4,
      "y": 0,
      "z": 2,
      "name": "Build_Lightsource_Cyan"
    },
    {
      "x": 4,
      "y": 1,
      "z": 2,
      "name": "Build_Lightsource_Cyan"
    },
    {
      "x": 4,
      "y": 2,
      "z": 2,
      "name": "Build_Lightsource_Cyan"
    },
    {
      "x": 4,
      "y": 3,
      "z": 2,
      "name": "Build_Lightsource_Cyan"
    },
    {
      "x": 4,
      "y": 4,
      "z": 2,
      "name": "Build_Lightsource_Cyan"
    },
    {
      "x": 4,
      "y": 5,
      "z": 2,
      "name": "Build_Lightsource_Cyan"
    },
    {
      "x": 4,
      "y": 6,
      "z": 2,
      "name": "Build_Lightsource_Cyan"
    },
    {
      "x": 4,
      "y": 7,
      "z": 2,
      "name": "Build_Lightsource_Cyan"
    },
    {
      "x": 4,
      "y": 0,
      "z": 3,
      "name": "Rock_Cyberverse_Brick_Half",
      "rotation": 5
    },
    {
      "x": 4,
      "y": 1,
      "z": 3,
      "name": "Rock_Cyberverse_Brick_Half",
      "rotation": 5
    },
    {
      "x": 4,
      "y": 2,
      "z": 3,
      "name": "Rock_Cyberverse_Brick_Half",
      "rotation": 5
    },
    {
      "x": 4,
      "y": 3,
      "z": 3,
      "name": "Rock_Cyberverse_Brick_Half",
      "rotation": 5
    },
    {
      "x": 4,
      "y": 4,
      "z": 3,
      "name": "Rock_Cyberverse_Brick_Half",
      "rotation": 5
    },
    {
      "x": 4,
      "y": 5,
      "z": 3,
      "name": "Rock_Cyberverse_Brick_Half",
      "rotation": 5
    },
    {
      "x": 4,
      "y": 6,
      "z": 3,
      "name": "Rock_Cyberverse_Brick_Half",
      "rotation": 5
    },
    {
      "x": 4,
      "y": 7,
      "z": 3,
      "name": "Rock_Cyberverse_Brick_Half",
      "rotation": 5
    }
  ],
  "fluids": [
    {
      "x": -4,
      "y": 0,
      "z": -3,
      "name": "Empty",
      "level": 0
    },
    {
      "x": -4,
      "y": 1,
      "z": -3,
      "name": "Empty",
      "level": 0
    },
    {
      "x": -4,
      "y": 2,
      "z": -3,
      "name": "Empty",
      "level": 0
    },
    {
      "x": -4,
      "y": 3,
      "z": -3,
      "name": "Empty",
      "level": 0
    },
    {
      "x": -4,
      "y": 4,
      "z": -3,
      "name": "Empty",
      "level": 0
    },
    {
      "x": -4,
      "y": 5,
      "z": -3,
      "name": "Empty",
      "level": 0
    },
    {
      "x": -4,
      "y": 6,
      "z": -3,
      "name": "Empty",
      "level": 0
    },
    {
      "x": -4,
      "y": 7,
      "z": -3,
      "name": "Empty",
      "level": 0
    },
    {
      "x": -4,
      "y": 0,
      "z": -2,
      "name": "Empty",
      "level": 0
    },
    {
      "x": -4,
      "y": 1,
      "z": -2,
      "name": "Empty",
      "level": 0
    },
    {
      "x": -4,
      "y": 2,
      "z": -2,
      "name": "Empty",
      "level": 0
    },
    {
      "x": -4,
      "y": 3,
      "z": -2,
      "name": "Empty",
      "level": 0
    },
    {
      "x": -4,
      "y": 4,
      "z": -2,
      "name": "Empty",
      "level": 0
    },
    {
      "x": -4,
      "y": 5,
      "z": -2,
      "name": "Empty",
      "level": 0
    },
    {
      "x": -4,
      "y": 6,
      "z": -2,
      "name": "Empty",
      "level": 0
    },
    {
      "x": -4,
      "y": 7,
      "z": -2,
      "name": "Empty",
      "level": 0
    },
    {
      "x": -4,
      "y": 0,
      "z": -1,
      "name": "Empty",
      "level": 0
    },
    {
      "x": -4,
      "y": 1,
      "z": -1,
      "name": "Empty",
      "level": 0
    },
    {
      "x": -4,
      "y": 2,
      "z": -1,
      "name": "Empty",
      "level": 0
    },
    {
      "x": -4,
      "y": 3,
      "z": -1,
      "name": "Empty",
      "level": 0
    },
    {
      "x": -4,
      "y": 4,
      "z": -1,
      "name": "Empty",
      "level": 0
    },
    {
      "x": -4,
      "y": 5,
      "z": -1,
      "name": "Empty",
      "level": 0
    },
    {
      "x": -4,
      "y": 6,
      "z": -1,
      "name": "Empty",
      "level": 0
    },
    {
      "x": -4,
      "y": 7,
      "z": -1,
      "name": "Empty",
      "level": 0
    },
    {
      "x": -4,
      "y": 2,
      "z": 0,
      "name": "Empty",
      "level": 0
    },
    {
      "x": -4,
      "y": 3,
      "z": 0,
      "name": "Empty",
      "level": 0
    },
    {
      "x": -4,
      "y": 4,
      "z": 0,
      "name": "Empty",
      "level": 0
    },
    {
      "x": -4,
      "y": 5,
      "z": 0,
      "name": "Empty",
      "level": 0
    },
    {
      "x": -4,
      "y": 6,
      "z": 0,
      "name": "Empty",
      "level": 0
    },
    {
      "x": -4,
      "y": 7,
      "z": 0,
      "name": "Empty",
      "level": 0
    },
    {
      "x": -4,
      "y": 0,
      "z": 1,
      "name": "Empty",
      "level": 0
    },
    {
      "x": -4,
      "y": 1,
      "z": 1,
      "name": "Empty",
      "level": 0
    },
    {
      "x": -4,
      "y": 2,
      "z": 1,
      "name": "Empty",
      "level": 0
    },
    {
      "x": -4,
      "y": 3,
      "z": 1,
      "name": "Empty",
      "level": 0
    },
    {
      "x": -4,
      "y": 4,
      "z": 1,
      "name": "Empty",
      "level": 0
    },
    {
      "x": -4,
      "y": 5,
      "z": 1,
      "name": "Empty",
      "level": 0
    },
    {
      "x": -4,
      "y": 6,
      "z": 1,
      "name": "Empty",
      "level": 0
    },
    {
      "x": -4,
      "y": 7,
      "z": 1,
      "name": "Empty",
      "level": 0
    },
    {
      "x": -4,
      "y": 0,
      "z": 2,
      "name": "Empty",
      "level": 0
    },
    {
      "x": -4,
      "y": 1,
      "z": 2,
      "name": "Empty",
      "level": 0
    },
    {
      "x": -4,
      "y": 2,
      "z": 2,
      "name": "Empty",
      "level": 0
    },
    {
      "x": -4,
      "y": 3,
      "z": 2,
      "name": "Empty",
      "level": 0
    },
    {
      "x": -4,
      "y": 4,
      "z": 2,
      "name": "Empty",
      "level": 0
    },
    {
      "x": -4,
      "y": 5,
      "z": 2,
      "name": "Empty",
      "level": 0
    },
    {
      "x": -4,
      "y": 6,
      "z": 2,
      "name": "Empty",
      "level": 0
    },
    {
      "x": -4,
      "y": 7,
      "z": 2,
      "name": "Empty",
      "level": 0
    },
    {
      "x": -4,
      "y": 0,
      "z": 3,
      "name": "Empty",
      "level": 0
    },
    {
      "x": -4,
      "y": 1,
      "z": 3,
      "name": "Empty",
      "level": 0
    },
    {
      "x": -4,
      "y": 2,
      "z": 3,
      "name": "Empty",
      "level": 0
    },
    {
      "x": -4,
      "y": 3,
      "z": 3,
      "name": "Empty",
      "level": 0
    },
    {
      "x": -4,
      "y": 4,
      "z": 3,
      "name": "Empty",
      "level": 0
    },
    {
      "x": -4,
      "y": 5,
      "z": 3,
      "name": "Empty",
      "level": 0
    },
    {
      "x": -4,
      "y": 6,
      "z": 3,
      "name": "Empty",
      "level": 0
    },
    {
      "x": -4,
      "y": 7,
      "z": 3,
      "name": "Empty",
      "level": 0
    },
    {
      "x": -3,
      "y": 0,
      "z": -4,
      "name": "Empty",
      "level": 0
    },
    {
      "x": -3,
      "y": 1,
      "z": -4,
      "name": "Empty",
      "level": 0
    },
    {
      "x": -3,
      "y": 2,
      "z": -4,
      "name": "Empty",
      "level": 0
    },
    {
      "x": -3,
      "y": 3,
      "z": -4,
      "name": "Empty",
      "level": 0
    },
    {
      "x": -3,
      "y": 4,
      "z": -4,
      "name": "Empty",
      "level": 0
    },
    {
      "x": -3,
      "y": 5,
      "z": -4,
      "name": "Empty",
      "level": 0
    },
    {
      "x": -3,
      "y": 6,
      "z": -4,
      "name": "Empty",
      "level": 0
    },
    {
      "x": -3,
      "y": 7,
      "z": -4,
      "name": "Empty",
      "level": 0
    },
    {
      "x": -3,
      "y": 0,
      "z": -3,
      "name": "Empty",
      "level": 0
    },
    {
      "x": -3,
      "y": 1,
      "z": -3,
      "name": "Empty",
      "level": 0
    },
    {
      "x": -3,
      "y": 2,
      "z": -3,
      "name": "Empty",
      "level": 0
    },
    {
      "x": -3,
      "y": 3,
      "z": -3,
      "name": "Empty",
      "level": 0
    },
    {
      "x": -3,
      "y": 4,
      "z": -3,
      "name": "Empty",
      "level": 0
    },
    {
      "x": -3,
      "y": 5,
      "z": -3,
      "name": "Empty",
      "level": 0
    },
    {
      "x": -3,
      "y": 6,
      "z": -3,
      "name": "Empty",
      "level": 0
    },
    {
      "x": -3,
      "y": 7,
      "z": -3,
      "name": "Empty",
      "level": 0
    },
    {
      "x": -3,
      "y": 0,
      "z": -2,
      "name": "Empty",
      "level": 0
    },
    {
      "x": -3,
      "y": 1,
      "z": -2,
      "name": "Empty",
      "level": 0
    },
    {
      "x": -3,
      "y": 2,
      "z": -2,
      "name": "Empty",
      "level": 0
    },
    {
      "x": -3,
      "y": 3,
      "z": -2,
      "name": "Empty",
      "level": 0
    },
    {
      "x": -3,
      "y": 4,
      "z": -2,
      "name": "Empty",
      "level": 0
    },
    {
      "x": -3,
      "y": 5,
      "z": -2,
      "name": "Empty",
      "level": 0
    },
    {
      "x": -3,
      "y": 6,
      "z": -2,
      "name": "Empty",
      "level": 0
    },
    {
      "x": -3,
      "y": 7,
      "z": -2,
      "name": "Empty",
      "level": 0
    },
    {
      "x": -3,
      "y": 7,
      "z": -1,
      "name": "Empty",
      "level": 0
    },
    {
      "x": -3,
      "y": 7,
      "z": 0,
      "name": "Empty",
      "level": 0
    },
    {
      "x": -3,
      "y": 7,
      "z": 1,
      "name": "Empty",
      "level": 0
    },
    {
      "x": -3,
      "y": 0,
      "z": 2,
      "name": "Empty",
      "level": 0
    },
    {
      "x": -3,
      "y": 1,
      "z": 2,
      "name": "Empty",
      "level": 0
    },
    {
      "x": -3,
      "y": 2,
      "z": 2,
      "name": "Empty",
      "level": 0
    },
    {
      "x": -3,
      "y": 3,
      "z": 2,
      "name": "Empty",
      "level": 0
    },
    {
      "x": -3,
      "y": 4,
      "z": 2,
      "name": "Empty",
      "level": 0
    },
    {
      "x": -3,
      "y": 5,
      "z": 2,
      "name": "Empty",
      "level": 0
    },
    {
      "x": -3,
      "y": 6,
      "z": 2,
      "name": "Empty",
      "level": 0
    },
    {
      "x": -3,
      "y": 7,
      "z": 2,
      "name": "Empty",
      "level": 0
    },
    {
      "x": -3,
      "y": 0,
      "z": 3,
      "name": "Empty",
      "level": 0
    },
    {
      "x": -3,
      "y": 1,
      "z": 3,
      "name": "Empty",
      "level": 0
    },
    {
      "x": -3,
      "y": 2,
      "z": 3,
      "name": "Empty",
      "level": 0
    },
    {
      "x": -3,
      "y": 3,
      "z": 3,
      "name": "Empty",
      "level": 0
    },
    {
      "x": -3,
      "y": 4,
      "z": 3,
      "name": "Empty",
      "level": 0
    },
    {
      "x": -3,
      "y": 5,
      "z": 3,
      "name": "Empty",
      "level": 0
    },
    {
      "x": -3,
      "y": 6,
      "z": 3,
      "name": "Empty",
      "level": 0
    },
    {
      "x": -3,
      "y": 7,
      "z": 3,
      "name": "Empty",
      "level": 0
    },
    {
      "x": -3,
      "y": 0,
      "z": 4,
      "name": "Empty",
      "level": 0
    },
    {
      "x": -3,
      "y": 1,
      "z": 4,
      "name": "Empty",
      "level": 0
    },
    {
      "x": -3,
      "y": 2,
      "z": 4,
      "name": "Empty",
      "level": 0
    },
    {
      "x": -3,
      "y": 3,
      "z": 4,
      "name": "Empty",
      "level": 0
    },
    {
      "x": -3,
      "y": 4,
      "z": 4,
      "name": "Empty",
      "level": 0
    },
    {
      "x": -3,
      "y": 5,
      "z": 4,
      "name": "Empty",
      "level": 0
    },
    {
      "x": -3,
      "y": 6,
      "z": 4,
      "name": "Empty",
      "level": 0
    },
    {
      "x": -3,
      "y": 7,
      "z": 4,
      "name": "Empty",
      "level": 0
    },
    {
      "x": -2,
      "y": 0,
      "z": -4,
      "name": "Empty",
      "level": 0
    },
    {
      "x": -2,
      "y": 1,
      "z": -4,
      "name": "Empty",
      "level": 0
    },
    {
      "x": -2,
      "y": 2,
      "z": -4,
      "name": "Empty",
      "level": 0
    },
    {
      "x": -2,
      "y": 3,
      "z": -4,
      "name": "Empty",
      "level": 0
    },
    {
      "x": -2,
      "y": 4,
      "z": -4,
      "name": "Empty",
      "level": 0
    },
    {
      "x": -2,
      "y": 5,
      "z": -4,
      "name": "Empty",
      "level": 0
    },
    {
      "x": -2,
      "y": 6,
      "z": -4,
      "name": "Empty",
      "level": 0
    },
    {
      "x": -2,
      "y": 7,
      "z": -4,
      "name": "Empty",
      "level": 0
    },
    {
      "x": -2,
      "y": 0,
      "z": -3,
      "name": "Empty",
      "level": 0
    },
    {
      "x": -2,
      "y": 1,
      "z": -3,
      "name": "Empty",
      "level": 0
    },
    {
      "x": -2,
      "y": 2,
      "z": -3,
      "name": "Empty",
      "level": 0
    },
    {
      "x": -2,
      "y": 3,
      "z": -3,
      "name": "Empty",
      "level": 0
    },
    {
      "x": -2,
      "y": 4,
      "z": -3,
      "name": "Empty",
      "level": 0
    },
    {
      "x": -2,
      "y": 5,
      "z": -3,
      "name": "Empty",
      "level": 0
    },
    {
      "x": -2,
      "y": 6,
      "z": -3,
      "name": "Empty",
      "level": 0
    },
    {
      "x": -2,
      "y": 7,
      "z": -3,
      "name": "Empty",
      "level": 0
    },
    {
      "x": -2,
      "y": 7,
      "z": -2,
      "name": "Empty",
      "level": 0
    },
    {
      "x": -2,
      "y": 7,
      "z": -1,
      "name": "Empty",
      "level": 0
    },
    {
      "x": -2,
      "y": 7,
      "z": 0,
      "name": "Empty",
      "level": 0
    },
    {
      "x": -2,
      "y": 7,
      "z": 1,
      "name": "Empty",
      "level": 0
    },
    {
      "x": -2,
      "y": 7,
      "z": 2,
      "name": "Empty",
      "level": 0
    },
    {
      "x": -2,
      "y": 0,
      "z": 3,
      "name": "Empty",
      "level": 0
    },
    {
      "x": -2,
      "y": 1,
      "z": 3,
      "name": "Empty",
      "level": 0
    },
    {
      "x": -2,
      "y": 2,
      "z": 3,
      "name": "Empty",
      "level": 0
    },
    {
      "x": -2,
      "y": 3,
      "z": 3,
      "name": "Empty",
      "level": 0
    },
    {
      "x": -2,
      "y": 4,
      "z": 3,
      "name": "Empty",
      "level": 0
    },
    {
      "x": -2,
      "y": 5,
      "z": 3,
      "name": "Empty",
      "level": 0
    },
    {
      "x": -2,
      "y": 6,
      "z": 3,
      "name": "Empty",
      "level": 0
    },
    {
      "x": -2,
      "y": 7,
      "z": 3,
      "name": "Empty",
      "level": 0
    },
    {
      "x": -2,
      "y": 0,
      "z": 4,
      "name": "Empty",
      "level": 0
    },
    {
      "x": -2,
      "y": 1,
      "z": 4,
      "name": "Empty",
      "level": 0
    },
    {
      "x": -2,
      "y": 2,
      "z": 4,
      "name": "Empty",
      "level": 0
    },
    {
      "x": -2,
      "y": 3,
      "z": 4,
      "name": "Empty",
      "level": 0
    },
    {
      "x": -2,
      "y": 4,
      "z": 4,
      "name": "Empty",
      "level": 0
    },
    {
      "x": -2,
      "y": 5,
      "z": 4,
      "name": "Empty",
      "level": 0
    },
    {
      "x": -2,
      "y": 6,
      "z": 4,
      "name": "Empty",
      "level": 0
    },
    {
      "x": -2,
      "y": 7,
      "z": 4,
      "name": "Empty",
      "level": 0
    },
    {
      "x": -1,
      "y": 0,
      "z": -4,
      "name": "Empty",
      "level": 0
    },
    {
      "x": -1,
      "y": 1,
      "z": -4,
      "name": "Empty",
      "level": 0
    },
    {
      "x": -1,
      "y": 2,
      "z": -4,
      "name": "Empty",
      "level": 0
    },
    {
      "x": -1,
      "y": 3,
      "z": -4,
      "name": "Empty",
      "level": 0
    },
    {
      "x": -1,
      "y": 4,
      "z": -4,
      "name": "Empty",
      "level": 0
    },
    {
      "x": -1,
      "y": 5,
      "z": -4,
      "name": "Empty",
      "level": 0
    },
    {
      "x": -1,
      "y": 6,
      "z": -4,
      "name": "Empty",
      "level": 0
    },
    {
      "x": -1,
      "y": 7,
      "z": -4,
      "name": "Empty",
      "level": 0
    },
    {
      "x": -1,
      "y": 4,
      "z": -3,
      "name": "Empty",
      "level": 0
    },
    {
      "x": -1,
      "y": 5,
      "z": -3,
      "name": "Empty",
      "level": 0
    },
    {
      "x": -1,
      "y": 7,
      "z": -3,
      "name": "Empty",
      "level": 0
    },
    {
      "x": -1,
      "y": 7,
      "z": -2,
      "name": "Empty",
      "level": 0
    },
    {
      "x": -1,
      "y": 2,
      "z": -1,
      "name": "Empty",
      "level": 0
    },
    {
      "x": -1,
      "y": 3,
      "z": -1,
      "name": "Empty",
      "level": 0
    },
    {
      "x": -1,
      "y": 6,
      "z": -1,
      "name": "Empty",
      "level": 0
    },
    {
      "x": -1,
      "y": 7,
      "z": -1,
      "name": "Empty",
      "level": 0
    },
    {
      "x": -1,
      "y": 0,
      "z": 0,
      "name": "Empty",
      "level": 0
    },
    {
      "x": -1,
      "y": 4,
      "z": 0,
      "name": "Empty",
      "level": 0
    },
    {
      "x": -1,
      "y": 0,
      "z": 1,
      "name": "Empty",
      "level": 0
    },
    {
      "x": -1,
      "y": 4,
      "z": 1,
      "name": "Empty",
      "level": 0
    },
    {
      "x": -1,
      "y": 7,
      "z": 2,
      "name": "Empty",
      "level": 0
    },
    {
      "x": -1,
      "y": 7,
      "z": 3,
      "name": "Empty",
      "level": 0
    },
    {
      "x": -1,
      "y": 0,
      "z": 4,
      "name": "Empty",
      "level": 0
    },
    {
      "x": -1,
      "y": 1,
      "z": 4,
      "name": "Empty",
      "level": 0
    },
    {
      "x": -1,
      "y": 2,
      "z": 4,
      "name": "Empty",
      "level": 0
    },
    {
      "x": -1,
      "y": 3,
      "z": 4,
      "name": "Empty",
      "level": 0
    },
    {
      "x": -1,
      "y": 4,
      "z": 4,
      "name": "Empty",
      "level": 0
    },
    {
      "x": -1,
      "y": 5,
      "z": 4,
      "name": "Empty",
      "level": 0
    },
    {
      "x": -1,
      "y": 6,
      "z": 4,
      "name": "Empty",
      "level": 0
    },
    {
      "x": -1,
      "y": 7,
      "z": 4,
      "name": "Empty",
      "level": 0
    },
    {
      "x": 0,
      "y": 2,
      "z": -4,
      "name": "Empty",
      "level": 0
    },
    {
      "x": 0,
      "y": 3,
      "z": -4,
      "name": "Empty",
      "level": 0
    },
    {
      "x": 0,
      "y": 4,
      "z": -4,
      "name": "Empty",
      "level": 0
    },
    {
      "x": 0,
      "y": 5,
      "z": -4,
      "name": "Empty",
      "level": 0
    },
    {
      "x": 0,
      "y": 6,
      "z": -4,
      "name": "Empty",
      "level": 0
    },
    {
      "x": 0,
      "y": 7,
      "z": -4,
      "name": "Empty",
      "level": 0
    },
    {
      "x": 0,
      "y": 4,
      "z": -3,
      "name": "Empty",
      "level": 0
    },
    {
      "x": 0,
      "y": 7,
      "z": -3,
      "name": "Empty",
      "level": 0
    },
    {
      "x": 0,
      "y": 7,
      "z": -2,
      "name": "Empty",
      "level": 0
    },
    {
      "x": 0,
      "y": 2,
      "z": -1,
      "name": "Empty",
      "level": 0
    },
    {
      "x": 0,
      "y": 3,
      "z": -1,
      "name": "Empty",
      "level": 0
    },
    {
      "x": 0,
      "y": 6,
      "z": -1,
      "name": "Empty",
      "level": 0
    },
    {
      "x": 0,
      "y": 7,
      "z": -1,
      "name": "Empty",
      "level": 0
    },
    {
      "x": 0,
      "y": 0,
      "z": 0,
      "name": "Empty",
      "level": 0
    },
    {
      "x": 0,
      "y": 1,
      "z": 0,
      "name": "Empty",
      "level": 0
    },
    {
      "x": 0,
      "y": 2,
      "z": 0,
      "name": "Empty",
      "level": 0
    },
    {
      "x": 0,
      "y": 3,
      "z": 0,
      "name": "Empty",
      "level": 0
    },
    {
      "x": 0,
      "y": 4,
      "z": 0,
      "name": "Empty",
      "level": 0
    },
    {
      "x": 0,
      "y": 5,
      "z": 0,
      "name": "Empty",
      "level": 0
    },
    {
      "x": 0,
      "y": 6,
      "z": 0,
      "name": "Empty",
      "level": 0
    },
    {
      "x": 0,
      "y": 7,
      "z": 0,
      "name": "Empty",
      "level": 0
    },
    {
      "x": 0,
      "y": 0,
      "z": 1,
      "name": "Empty",
      "level": 0
    },
    {
      "x": 0,
      "y": 1,
      "z": 1,
      "name": "Empty",
      "level": 0
    },
    {
      "x": 0,
      "y": 4,
      "z": 1,
      "name": "Empty",
      "level": 0
    },
    {
      "x": 0,
      "y": 5,
      "z": 1,
      "name": "Empty",
      "level": 0
    },
    {
      "x": 0,
      "y": 7,
      "z": 2,
      "name": "Empty",
      "level": 0
    },
    {
      "x": 0,
      "y": 7,
      "z": 3,
      "name": "Empty",
      "level": 0
    },
    {
      "x": 0,
      "y": 2,
      "z": 4,
      "name": "Empty",
      "level": 0
    },
    {
      "x": 0,
      "y": 3,
      "z": 4,
      "name": "Empty",
      "level": 0
    },
    {
      "x": 0,
      "y": 4,
      "z": 4,
      "name": "Empty",
      "level": 0
    },
    {
      "x": 0,
      "y": 5,
      "z": 4,
      "name": "Empty",
      "level": 0
    },
    {
      "x": 0,
      "y": 6,
      "z": 4,
      "name": "Empty",
      "level": 0
    },
    {
      "x": 0,
      "y": 7,
      "z": 4,
      "name": "Empty",
      "level": 0
    },
    {
      "x": 1,
      "y": 0,
      "z": -4,
      "name": "Empty",
      "level": 0
    },
    {
      "x": 1,
      "y": 1,
      "z": -4,
      "name": "Empty",
      "level": 0
    },
    {
      "x": 1,
      "y": 2,
      "z": -4,
      "name": "Empty",
      "level": 0
    },
    {
      "x": 1,
      "y": 3,
      "z": -4,
      "name": "Empty",
      "level": 0
    },
    {
      "x": 1,
      "y": 4,
      "z": -4,
      "name": "Empty",
      "level": 0
    },
    {
      "x": 1,
      "y": 5,
      "z": -4,
      "name": "Empty",
      "level": 0
    },
    {
      "x": 1,
      "y": 6,
      "z": -4,
      "name": "Empty",
      "level": 0
    },
    {
      "x": 1,
      "y": 7,
      "z": -4,
      "name": "Empty",
      "level": 0
    },
    {
      "x": 1,
      "y": 4,
      "z": -3,
      "name": "Empty",
      "level": 0
    },
    {
      "x": 1,
      "y": 7,
      "z": -3,
      "name": "Empty",
      "level": 0
    },
    {
      "x": 1,
      "y": 7,
      "z": -2,
      "name": "Empty",
      "level": 0
    },
    {
      "x": 1,
      "y": 1,
      "z": -1,
      "name": "Empty",
      "level": 0
    },
    {
      "x": 1,
      "y": 2,
      "z": -1,
      "name": "Empty",
      "level": 0
    },
    {
      "x": 1,
      "y": 5,
      "z": -1,
      "name": "Empty",
      "level": 0
    },
    {
      "x": 1,
      "y": 6,
      "z": -1,
      "name": "Empty",
      "level": 0
    },
    {
      "x": 1,
      "y": 1,
      "z": 0,
      "name": "Empty",
      "level": 0
    },
    {
      "x": 1,
      "y": 2,
      "z": 0,
      "name": "Empty",
      "level": 0
    },
    {
      "x": 1,
      "y": 5,
      "z": 0,
      "name": "Empty",
      "level": 0
    },
    {
      "x": 1,
      "y": 6,
      "z": 0,
      "name": "Empty",
      "level": 0
    },
    {
      "x": 1,
      "y": 0,
      "z": 1,
      "name": "Empty",
      "level": 0
    },
    {
      "x": 1,
      "y": 1,
      "z": 1,
      "name": "Empty",
      "level": 0
    },
    {
      "x": 1,
      "y": 4,
      "z": 1,
      "name": "Empty",
      "level": 0
    },
    {
      "x": 1,
      "y": 5,
      "z": 1,
      "name": "Empty",
      "level": 0
    },
    {
      "x": 1,
      "y": 7,
      "z": 2,
      "name": "Empty",
      "level": 0
    },
    {
      "x": 1,
      "y": 7,
      "z": 3,
      "name": "Empty",
      "level": 0
    },
    {
      "x": 1,
      "y": 0,
      "z": 4,
      "name": "Empty",
      "level": 0
    },
    {
      "x": 1,
      "y": 1,
      "z": 4,
      "name": "Empty",
      "level": 0
    },
    {
      "x": 1,
      "y": 2,
      "z": 4,
      "name": "Empty",
      "level": 0
    },
    {
      "x": 1,
      "y": 3,
      "z": 4,
      "name": "Empty",
      "level": 0
    },
    {
      "x": 1,
      "y": 4,
      "z": 4,
      "name": "Empty",
      "level": 0
    },
    {
      "x": 1,
      "y": 5,
      "z": 4,
      "name": "Empty",
      "level": 0
    },
    {
      "x": 1,
      "y": 6,
      "z": 4,
      "name": "Empty",
      "level": 0
    },
    {
      "x": 1,
      "y": 7,
      "z": 4,
      "name": "Empty",
      "level": 0
    },
    {
      "x": 2,
      "y": 0,
      "z": -4,
      "name": "Empty",
      "level": 0
    },
    {
      "x": 2,
      "y": 1,
      "z": -4,
      "name": "Empty",
      "level": 0
    },
    {
      "x": 2,
      "y": 2,
      "z": -4,
      "name": "Empty",
      "level": 0
    },
    {
      "x": 2,
      "y": 3,
      "z": -4,
      "name": "Empty",
      "level": 0
    },
    {
      "x": 2,
      "y": 4,
      "z": -4,
      "name": "Empty",
      "level": 0
    },
    {
      "x": 2,
      "y": 5,
      "z": -4,
      "name": "Empty",
      "level": 0
    },
    {
      "x": 2,
      "y": 6,
      "z": -4,
      "name": "Empty",
      "level": 0
    },
    {
      "x": 2,
      "y": 7,
      "z": -4,
      "name": "Empty",
      "level": 0
    },
    {
      "x": 2,
      "y": 0,
      "z": -3,
      "name": "Empty",
      "level": 0
    },
    {
      "x": 2,
      "y": 1,
      "z": -3,
      "name": "Empty",
      "level": 0
    },
    {
      "x": 2,
      "y": 2,
      "z": -3,
      "name": "Empty",
      "level": 0
    },
    {
      "x": 2,
      "y": 3,
      "z": -3,
      "name": "Empty",
      "level": 0
    },
    {
      "x": 2,
      "y": 4,
      "z": -3,
      "name": "Empty",
      "level": 0
    },
    {
      "x": 2,
      "y": 5,
      "z": -3,
      "name": "Empty",
      "level": 0
    },
    {
      "x": 2,
      "y": 6,
      "z": -3,
      "name": "Empty",
      "level": 0
    },
    {
      "x": 2,
      "y": 7,
      "z": -3,
      "name": "Empty",
      "level": 0
    },
    {
      "x": 2,
      "y": 7,
      "z": -2,
      "name": "Empty",
      "level": 0
    },
    {
      "x": 2,
      "y": 7,
      "z": -1,
      "name": "Empty",
      "level": 0
    },
    {
      "x": 2,
      "y": 7,
      "z": 0,
      "name": "Empty",
      "level": 0
    },
    {
      "x": 2,
      "y": 7,
      "z": 1,
      "name": "Empty",
      "level": 0
    },
    {
      "x": 2,
      "y": 7,
      "z": 2,
      "name": "Empty",
      "level": 0
    },
    {
      "x": 2,
      "y": 0,
      "z": 3,
      "name": "Empty",
      "level": 0
    },
    {
      "x": 2,
      "y": 1,
      "z": 3,
      "name": "Empty",
      "level": 0
    },
    {
      "x": 2,
      "y": 2,
      "z": 3,
      "name": "Empty",
      "level": 0
    },
    {
      "x": 2,
      "y": 3,
      "z": 3,
      "name": "Empty",
      "level": 0
    },
    {
      "x": 2,
      "y": 4,
      "z": 3,
      "name": "Empty",
      "level": 0
    },
    {
      "x": 2,
      "y": 5,
      "z": 3,
      "name": "Empty",
      "level": 0
    },
    {
      "x": 2,
      "y": 6,
      "z": 3,
      "name": "Empty",
      "level": 0
    },
    {
      "x": 2,
      "y": 7,
      "z": 3,
      "name": "Empty",
      "level": 0
    },
    {
      "x": 2,
      "y": 0,
      "z": 4,
      "name": "Empty",
      "level": 0
    },
    {
      "x": 2,
      "y": 1,
      "z": 4,
      "name": "Empty",
      "level": 0
    },
    {
      "x": 2,
      "y": 2,
      "z": 4,
      "name": "Empty",
      "level": 0
    },
    {
      "x": 2,
      "y": 3,
      "z": 4,
      "name": "Empty",
      "level": 0
    },
    {
      "x": 2,
      "y": 4,
      "z": 4,
      "name": "Empty",
      "level": 0
    },
    {
      "x": 2,
      "y": 5,
      "z": 4,
      "name": "Empty",
      "level": 0
    },
    {
      "x": 2,
      "y": 6,
      "z": 4,
      "name": "Empty",
      "level": 0
    },
    {
      "x": 2,
      "y": 7,
      "z": 4,
      "name": "Empty",
      "level": 0
    },
    {
      "x": 3,
      "y": 0,
      "z": -4,
      "name": "Empty",
      "level": 0
    },
    {
      "x": 3,
      "y": 1,
      "z": -4,
      "name": "Empty",
      "level": 0
    },
    {
      "x": 3,
      "y": 2,
      "z": -4,
      "name": "Empty",
      "level": 0
    },
    {
      "x": 3,
      "y": 3,
      "z": -4,
      "name": "Empty",
      "level": 0
    },
    {
      "x": 3,
      "y": 4,
      "z": -4,
      "name": "Empty",
      "level": 0
    },
    {
      "x": 3,
      "y": 5,
      "z": -4,
      "name": "Empty",
      "level": 0
    },
    {
      "x": 3,
      "y": 6,
      "z": -4,
      "name": "Empty",
      "level": 0
    },
    {
      "x": 3,
      "y": 7,
      "z": -4,
      "name": "Empty",
      "level": 0
    },
    {
      "x": 3,
      "y": 0,
      "z": -3,
      "name": "Empty",
      "level": 0
    },
    {
      "x": 3,
      "y": 1,
      "z": -3,
      "name": "Empty",
      "level": 0
    },
    {
      "x": 3,
      "y": 2,
      "z": -3,
      "name": "Empty",
      "level": 0
    },
    {
      "x": 3,
      "y": 3,
      "z": -3,
      "name": "Empty",
      "level": 0
    },
    {
      "x": 3,
      "y": 4,
      "z": -3,
      "name": "Empty",
      "level": 0
    },
    {
      "x": 3,
      "y": 5,
      "z": -3,
      "name": "Empty",
      "level": 0
    },
    {
      "x": 3,
      "y": 6,
      "z": -3,
      "name": "Empty",
      "level": 0
    },
    {
      "x": 3,
      "y": 7,
      "z": -3,
      "name": "Empty",
      "level": 0
    },
    {
      "x": 3,
      "y": 0,
      "z": -2,
      "name": "Empty",
      "level": 0
    },
    {
      "x": 3,
      "y": 1,
      "z": -2,
      "name": "Empty",
      "level": 0
    },
    {
      "x": 3,
      "y": 2,
      "z": -2,
      "name": "Empty",
      "level": 0
    },
    {
      "x": 3,
      "y": 3,
      "z": -2,
      "name": "Empty",
      "level": 0
    },
    {
      "x": 3,
      "y": 4,
      "z": -2,
      "name": "Empty",
      "level": 0
    },
    {
      "x": 3,
      "y": 5,
      "z": -2,
      "name": "Empty",
      "level": 0
    },
    {
      "x": 3,
      "y": 6,
      "z": -2,
      "name": "Empty",
      "level": 0
    },
    {
      "x": 3,
      "y": 7,
      "z": -2,
      "name": "Empty",
      "level": 0
    },
    {
      "x": 3,
      "y": 7,
      "z": -1,
      "name": "Empty",
      "level": 0
    },
    {
      "x": 3,
      "y": 7,
      "z": 0,
      "name": "Empty",
      "level": 0
    },
    {
      "x": 3,
      "y": 7,
      "z": 1,
      "name": "Empty",
      "level": 0
    },
    {
      "x": 3,
      "y": 0,
      "z": 2,
      "name": "Empty",
      "level": 0
    },
    {
      "x": 3,
      "y": 1,
      "z": 2,
      "name": "Empty",
      "level": 0
    },
    {
      "x": 3,
      "y": 2,
      "z": 2,
      "name": "Empty",
      "level": 0
    },
    {
      "x": 3,
      "y": 3,
      "z": 2,
      "name": "Empty",
      "level": 0
    },
    {
      "x": 3,
      "y": 4,
      "z": 2,
      "name": "Empty",
      "level": 0
    },
    {
      "x": 3,
      "y": 5,
      "z": 2,
      "name": "Empty",
      "level": 0
    },
    {
      "x": 3,
      "y": 6,
      "z": 2,
      "name": "Empty",
      "level": 0
    },
    {
      "x": 3,
      "y": 7,
      "z": 2,
      "name": "Empty",
      "level": 0
    },
    {
      "x": 3,
      "y": 0,
      "z": 3,
      "name": "Empty",
      "level": 0
    },
    {
      "x": 3,
      "y": 1,
      "z": 3,
      "name": "Empty",
      "level": 0
    },
    {
      "x": 3,
      "y": 2,
      "z": 3,
      "name": "Empty",
      "level": 0
    },
    {
      "x": 3,
      "y": 3,
      "z": 3,
      "name": "Empty",
      "level": 0
    },
    {
      "x": 3,
      "y": 4,
      "z": 3,
      "name": "Empty",
      "level": 0
    },
    {
      "x": 3,
      "y": 5,
      "z": 3,
      "name": "Empty",
      "level": 0
    },
    {
      "x": 3,
      "y": 6,
      "z": 3,
      "name": "Empty",
      "level": 0
    },
    {
      "x": 3,
      "y": 7,
      "z": 3,
      "name": "Empty",
      "level": 0
    },
    {
      "x": 3,
      "y": 0,
      "z": 4,
      "name": "Empty",
      "level": 0
    },
    {
      "x": 3,
      "y": 1,
      "z": 4,
      "name": "Empty",
      "level": 0
    },
    {
      "x": 3,
      "y": 2,
      "z": 4,
      "name": "Empty",
      "level": 0
    },
    {
      "x": 3,
      "y": 3,
      "z": 4,
      "name": "Empty",
      "level": 0
    },
    {
      "x": 3,
      "y": 4,
      "z": 4,
      "name": "Empty",
      "level": 0
    },
    {
      "x": 3,
      "y": 5,
      "z": 4,
      "name": "Empty",
      "level": 0
    },
    {
      "x": 3,
      "y": 6,
      "z": 4,
      "name": "Empty",
      "level": 0
    },
    {
      "x": 3,
      "y": 7,
      "z": 4,
      "name": "Empty",
      "level": 0
    },
    {
      "x": 4,
      "y": 0,
      "z": -3,
      "name": "Empty",
      "level": 0
    },
    {
      "x": 4,
      "y": 1,
      "z": -3,
      "name": "Empty",
      "level": 0
    },
    {
      "x": 4,
      "y": 2,
      "z": -3,
      "name": "Empty",
      "level": 0
    },
    {
      "x": 4,
      "y": 3,
      "z": -3,
      "name": "Empty",
      "level": 0
    },
    {
      "x": 4,
      "y": 4,
      "z": -3,
      "name": "Empty",
      "level": 0
    },
    {
      "x": 4,
      "y": 5,
      "z": -3,
      "name": "Empty",
      "level": 0
    },
    {
      "x": 4,
      "y": 6,
      "z": -3,
      "name": "Empty",
      "level": 0
    },
    {
      "x": 4,
      "y": 7,
      "z": -3,
      "name": "Empty",
      "level": 0
    },
    {
      "x": 4,
      "y": 0,
      "z": -2,
      "name": "Empty",
      "level": 0
    },
    {
      "x": 4,
      "y": 1,
      "z": -2,
      "name": "Empty",
      "level": 0
    },
    {
      "x": 4,
      "y": 2,
      "z": -2,
      "name": "Empty",
      "level": 0
    },
    {
      "x": 4,
      "y": 3,
      "z": -2,
      "name": "Empty",
      "level": 0
    },
    {
      "x": 4,
      "y": 4,
      "z": -2,
      "name": "Empty",
      "level": 0
    },
    {
      "x": 4,
      "y": 5,
      "z": -2,
      "name": "Empty",
      "level": 0
    },
    {
      "x": 4,
      "y": 6,
      "z": -2,
      "name": "Empty",
      "level": 0
    },
    {
      "x": 4,
      "y": 7,
      "z": -2,
      "name": "Empty",
      "level": 0
    },
    {
      "x": 4,
      "y": 0,
      "z": -1,
      "name": "Empty",
      "level": 0
    },
    {
      "x": 4,
      "y": 1,
      "z": -1,
      "name": "Empty",
      "level": 0
    },
    {
      "x": 4,
      "y": 2,
      "z": -1,
      "name": "Empty",
      "level": 0
    },
    {
      "x": 4,
      "y": 3,
      "z": -1,
      "name": "Empty",
      "level": 0
    },
    {
      "x": 4,
      "y": 4,
      "z": -1,
      "name": "Empty",
      "level": 0
    },
    {
      "x": 4,
      "y": 5,
      "z": -1,
      "name": "Empty",
      "level": 0
    },
    {
      "x": 4,
      "y": 6,
      "z": -1,
      "name": "Empty",
      "level": 0
    },
    {
      "x": 4,
      "y": 7,
      "z": -1,
      "name": "Empty",
      "level": 0
    },
    {
      "x": 4,
      "y": 2,
      "z": 0,
      "name": "Empty",
      "level": 0
    },
    {
      "x": 4,
      "y": 3,
      "z": 0,
      "name": "Empty",
      "level": 0
    },
    {
      "x": 4,
      "y": 4,
      "z": 0,
      "name": "Empty",
      "level": 0
    },
    {
      "x": 4,
      "y": 5,
      "z": 0,
      "name": "Empty",
      "level": 0
    },
    {
      "x": 4,
      "y": 6,
      "z": 0,
      "name": "Empty",
      "level": 0
    },
    {
      "x": 4,
      "y": 7,
      "z": 0,
      "name": "Empty",
      "level": 0
    },
    {
      "x": 4,
      "y": 0,
      "z": 1,
      "name": "Empty",
      "level": 0
    },
    {
      "x": 4,
      "y": 1,
      "z": 1,
      "name": "Empty",
      "level": 0
    },
    {
      "x": 4,
      "y": 2,
      "z": 1,
      "name": "Empty",
      "level": 0
    },
    {
      "x": 4,
      "y": 3,
      "z": 1,
      "name": "Empty",
      "level": 0
    },
    {
      "x": 4,
      "y": 4,
      "z": 1,
      "name": "Empty",
      "level": 0
    },
    {
      "x": 4,
      "y": 5,
      "z": 1,
      "name": "Empty",
      "level": 0
    },
    {
      "x": 4,
      "y": 6,
      "z": 1,
      "name": "Empty",
      "level": 0
    },
    {
      "x": 4,
      "y": 7,
      "z": 1,
      "name": "Empty",
      "level": 0
    },
    {
      "x": 4,
      "y": 0,
      "z": 2,
      "name": "Empty",
      "level": 0
    },
    {
      "x": 4,
      "y": 1,
      "z": 2,
      "name": "Empty",
      "level": 0
    },
    {
      "x": 4,
      "y": 2,
      "z": 2,
      "name": "Empty",
      "level": 0
    },
    {
      "x": 4,
      "y": 3,
      "z": 2,
      "name": "Empty",
      "level": 0
    },
    {
      "x": 4,
      "y": 4,
      "z": 2,
      "name": "Empty",
      "level": 0
    },
    {
      "x": 4,
      "y": 5,
      "z": 2,
      "name": "Empty",
      "level": 0
    },
    {
      "x": 4,
      "y": 6,
      "z": 2,
      "name": "Empty",
      "level": 0
    },
    {
      "x": 4,
      "y": 7,
      "z": 2,
      "name": "Empty",
      "level": 0
    },
    {
      "x": 4,
      "y": 0,
      "z": 3,
      "name": "Empty",
      "level": 0
    },
    {
      "x": 4,
      "y": 1,
      "z": 3,
      "name": "Empty",
      "level": 0
    },
    {
      "x": 4,
      "y": 2,
      "z": 3,
      "name": "Empty",
      "level": 0
    },
    {
      "x": 4,
      "y": 3,
      "z": 3,
      "name": "Empty",
      "level": 0
    },
    {
      "x": 4,
      "y": 4,
      "z": 3,
      "name": "Empty",
      "level": 0
    },
    {
      "x": 4,
      "y": 5,
      "z": 3,
      "name": "Empty",
      "level": 0
    },
    {
      "x": 4,
      "y": 6,
      "z": 3,
      "name": "Empty",
      "level": 0
    },
    {
      "x": 4,
      "y": 7,
      "z": 3,
      "name": "Empty",
      "level": 0
    }
  ]
}