{
  "version": 8,
  "blockIdVersion": 11,
  "anchorX": 0,
  "anchorY": 0,
  "anchorZ": 0,
  "blocks": [
    {
      "x": -3,
      "y": -9,
      "z": -3,
      "name": "Billboard_Glowing"
    },
    {
      "x": -3,
      "y": -8,
      "z": -3,
      "name": "Billboard_Glowing"
    },
    {
      "x": -3,
      "y": -7,
      "z": -3,
      "name": "Billboard_Glowing"
    },
    {
      "x": -3,
      "y": -6,
      "z": -3,
      "name": "Billboard_Glowing"
    },
    {
      "x": -3,
      "y": -5,
      "z": -3,
      "name": "Billboard_Glowing"
    },
    {
      "x": -3,
      "y": -4,
      "z": -3,
      "name": "Billboard_Glowing"
    },
    {
      "x": -3,
      "y": -3,
      "z": -3,
      "name": "Rock_Stone_Cyberverse"
    },
    {
      "x": -3,
      "y": -2,
      "z": -3,
      "name": "Rock_Stone_Cyberverse"
    },
    {
      "x": -3,
      "y": -1,
      "z": -3,
      "name": "Rock_Stone_Cyberverse"
    },
    {
      "x": -3,
      "y": 0,
      "z": -3,
      "name": "Empty"
    },
    {
      "x": -3,
      "y": -9,
      "z": -2,
      "name": "Rock_Stone_Cyberverse"
    },
    {
      "x": -3,
      "y": -8,
      "z": -2,
      "name": "Rock_Stone_Cyberverse"
    },
    {
      "x": -3,
      "y": -7,
      "z": -2,
      "name": "Rock_Stone_Cyberverse"
    },
    {
      "x": -3,
      "y": -6,
      "z": -2,
      "name": "Rock_Stone_Cyberverse"
    },
    {
      "x": -3,
      "y": -5,
      "z": -2,
      "name": "Rock_Stone_Cyberverse"
    },
    {
      "x": -3,
      "y": -4,
      "z": -2,
      "name": "Rock_Stone_Cyberverse"
    },
    {
      "x": -3,
      "y": -3,
      "z": -2,
      "name": "Rock_Stone_Cyberverse"
    },
    {
      "x": -3,
      "y": -2,
      "z": -2,
      "name": "Rock_Stone_Cyberverse"
    },
    {
      "x": -3,
      "y": -1,
      "z": -2,
      "name": "Rock_Stone_Cyberverse"
    },
    {
      "x": -3,
      "y": 0,
      "z": -2,
      "name": "Empty"
    },
    {
      "x": -3,
      "y": -9,
      "z": -1,
      "name": "Rock_Stone_Cyberverse"
    },
    {
      "x": -3,
      "y": -8,
      "z": -1,
      "name": "Rock_Stone_Cyberverse"
    },
    {
      "x": -3,
      "y": -7,
      "z": -1,
      "name": "Rock_Stone_Cyberverse"
    },
    {
      "x": -3,
      "y": -6,
      "z": -1,
      "name": "Rock_Stone_Cyberverse"
    },
    {
      "x": -3,
      "y": -5,
      "z": -1,
      "name": "Rock_Stone_Cyberverse"
    },
    {
      "x": -3,
      "y": -4,
      "z": -1,
      "name": "Rock_Stone_Cyberverse"
    },
    {
      "x": -3,
      "y": -3,
      "z": -1,
      "name": "Rock_Stone_Cyberverse"
    },
    {
      "x": -3,
      "y": -2,
      "z": -1,
      "name": "Rock_Stone_Cyberverse"
    },
    {
      "x": -3,
      "y": -1,
      "z": -1,
      "name": "Rock_Stone_Cyberverse"
    },
    {
      "x": -3,
      "y": 0,
      "z": -1,
      "name": "Empty"
    },
    {
      "x": -3,
      "y": -9,
      "z": 0,
      "name": "Rock_Stone_Cyberverse"
    },
    {
      "x": -3,
      "y": -8,
      "z": 0,
      "name": "Rock_Stone_Cyberverse"
    },
    {
      "x": -3,
      "y": -7,
      "z": 0,
      "name": "Rock_Stone_Cyberverse"
    },
    {
      "x": -3,
      "y": -6,
      "z": 0,
      "name": "Rock_Stone_Cyberverse"
    },
    {
      "x": -3,
      "y": -5,
      "z": 0,
      "name": "Rock_Stone_Cyberverse"
    },
    {
      "x": -3,
      "y": -4,
      "z": 0,
      "name": "Rock_Stone_Cyberverse_Unstable"
    },
    {
      "x": -3,
      "y": -3,
      "z": 0,
      "name": "Rock_Stone_Cyberverse_Unstable"
    },
    {
      "x": -3,
      "y": -2,
      "z": 0,
      "name": "Rock_Stone_Cyberverse_Unstable"
    },
    {
      "x": -3,
      "y": -1,
      "z": 0,
      "name": "Rock_Stone_Cyberverse_Unstable"
    },
    {
      "x": -3,
      "y": 0,
      "z": 0,
      "name": "Empty"
    },
    {
      "x": -3,
      "y": -9,
      "z": 1,
      "name": "Rock_Stone_Cyberverse"
    },
    {
      "x": -3,
      "y": -8,
      "z": 1,
      "name": "Rock_Stone_Cyberverse"
    },
    {
      "x": -3,
      "y": -7,
      "z": 1,
      "name": "Rock_Stone_Cyberverse"
    },
    {
      "x": -3,
      "y": -6,
      "z": 1,
      "name": "Rock_Stone_Cyberverse"
    },
    {
      "x": -3,
      "y": -5,
      "z": 1,
      "name": "Rock_Stone_Cyberverse"
    },
    {
      "x": -3,
      "y": -4,
      "z": 1,
      "name": "Rock_Stone_Cyberverse"
    },
    {
      "x": -3,
      "y": -3,
      "z": 1,
      "name": "Rock_Stone_Cyberverse"
    },
    {
      "x": -3,
      "y": -2,
      "z": 1,
      "name": "Rock_Stone_Cyberverse"
    },
    {
      "x": -3,
      "y": -1,
      "z": 1,
      "name": "Rock_Stone_Cyberverse"
    },
    {
      "x": -3,
      "y": 0,
      "z": 1,
      "name": "Empty"
    },
    {
      "x": -3,
      "y": -9,
      "z": 2,
      "name": "Rock_Stone_Cyberverse"
    },
    {
      "x": -3,
      "y": -8,
      "z": 2,
      "name": "Rock_Stone_Cyberverse"
    },
    {
      "x": -3,
      "y": -7,
      "z": 2,
      "name": "Rock_Stone_Cyberverse"
    },
    {
      "x": -3,
      "y": -6,
      "z": 2,
      "name": "Rock_Stone_Cyberverse"
    },
    {
      "x": -3,
      "y": -5,
      "z": 2,
      "name": "Rock_Stone_Cyberverse"
    },
    {
      "x": -3,
      "y": -4,
      "z": 2,
      "name": "Rock_Stone_Cyberverse"
    },
    {
      "x": -3,
      "y": -3,
      "z": 2,
      "name": "Rock_Stone_Cyberverse"
    },
    {
      "x": -3,
      "y": -2,
      "z": 2,
      "name": "Rock_Stone_Cyberverse"
    },
    {
      "x": -3,
      "y": -1,
      "z": 2,
      "name": "Rock_Stone_Cyberverse"
    },
    {
      "x": -3,
      "y": 0,
      "z": 2,
      "name": "Empty"
    },
    {
      "x": -3,
      "y": -9,
      "z": 3,
      "name": "Rock_Stone_Cyberverse"
    },
    {
      "x": -3,
      "y": -8,
      "z": 3,
      "name": "Rock_Stone_Cyberverse"
    },
    {
      "x": -3,
      "y": -7,
      "z": 3,
      "name": "Rock_Stone_Cyberverse"
    },
    {
      "x": -3,
      "y": -6,
      "z": 3,
      "name": "Rock_Stone_Cyberverse"
    },
    {
      "x": -3,
      "y": -5,
      "z": 3,
      "name": "Rock_Stone_Cyberverse"
    },
    {
      "x": -3,
      "y": -4,
      "z": 3,
      "name": "Rock_Stone_Cyberverse"
    },
    {
      "x": -3,
      "y": -3,
      "z": 3,
      "name": "Rock_Stone_Cyberverse"
    },
    {
      "x": -3,
      "y": -2,
      "z": 3,
      "name": "Rock_Stone_Cyberverse"
    },
    {
      "x": -3,
      "y": -1,
      "z": 3,
      "name": "Rock_Stone_Cyberverse"
    },
    {
      "x": -3,
      "y": 0,
      "z": 3,
      "name": "Empty"
    },
    {
      "x": -2,
      "y": -9,
      "z": -3,
      "name": "Rock_Stone_Cyberverse"
    },
    {
      "x": -2,
      "y": -8,
      "z": -3,
      "name": "Rock_Stone_Cyberverse"
    },
    {
      "x": -2,
      "y": -7,
      "z": -3,
      "name": "Rock_Stone_Cyberverse"
    },
    {
      "x": -2,
      "y": -6,
      "z": -3,
      "name": "Rock_Stone_Cyberverse"
    },
    {
      "x": -2,
      "y": -5,
      "z": -3,
      "name": "Rock_Stone_Cyberverse"
    },
    {
      "x": -2,
      "y": -4,
      "z": -3,
      "name": "Rock_Stone_Cyberverse"
    },
    {
      "x": -2,
      "y": -3,
      "z": -3,
      "name": "Rock_Stone_Cyberverse"
    },
    {
      "x": -2,
      "y": -2,
      "z": -3,
      "name": "Rock_Stone_Cyberverse"
    },
    {
      "x": -2,
      "y": -1,
      "z": -3,
      "name": "Rock_Stone_Cyberverse"
    },
    {
      "x": -2,
      "y": 0,
      "z": -3,
      "name": "Empty"
    },
    {
      "x": -2,
      "y": -9,
      "z": -2,
      "name": "Live_Wires",
      "support": 15
    },
    {
      "x": -2,
      "y": -8,
      "z": -2,
      "name": "Empty"
    },
    {
      "x": -2,
      "y": -7,
      "z": -2,
      "name": "Empty"
    },
    {
      "x": -2,
      "y": -6,
      "z": -2,
      "name": "Live_Wires",
      "support": 15,
      "rotation": 4
    },
    {
      "x": -2,
      "y": -5,
      "z": -2,
      "name": "Live_Wires",
      "support": 15,
      "rotation": 4
    },
    {
      "x": -2,
      "y": -4,
      "z": -2,
      "name": "Empty"
    },
    {
      "x": -2,
      "y": -3,
      "z": -2,
      "name": "Empty"
    },
    {
      "x": -2,
      "y": -2,
      "z": -2,
      "name": "Empty"
    },
    {
      "x": -2,
      "y": -1,
      "z": -2,
      "name": "Rock_Stone_Cyberverse_Unstable"
    },
    {
      "x": -2,
      "y": 0,
      "z": -2,
      "name": "Empty"
    },
    {
      "x": -2,
      "y": -9,
      "z": -1,
      "name": "Live_Wires",
      "support": 15
    },
    {
      "x": -2,
      "y": -8,
      "z": -1,
      "name": "Empty"
    },
    {
      "x": -2,
      "y": -7,
      "z": -1,
      "name": "Empty"
    },
    {
      "x": -2,
      "y": -6,
      "z": -1,
      "name": "Empty"
    },
    {
      "x": -2,
      "y": -5,
      "z": -1,
      "name": "Empty"
    },
    {
      "x": -2,
      "y": -4,
      "z": -1,
      "name": "Empty"
    },
    {
      "x": -2,
      "y": -3,
      "z": -1,
      "name": "Empty"
    },
    {
      "x": -2,
      "y": -2,
      "z": -1,
      "name": "Empty"
    },
    {
      "x": -2,
      "y": -1,
      "z": -1,
      "name": "Rock_Stone_Cyberverse_Unstable"
    },
    {
      "x": -2,
      "y": 0,
      "z": -1,
      "name": "Empty"
    },
    {
      "x": -2,
      "y": -9,
      "z": 0,
      "name": "Live_Wires",
      "support": 15
    },
    {
      "x": -2,
      "y": -8,
      "z": 0,
      "name": "Empty"
    },
    {
      "x": -2,
      "y": -7,
      "z": 0,
      "name": "Empty"
    },
    {
      "x": -2,
      "y": -6,
      "z": 0,
      "name": "Empty"
    },
    {
      "x": -2,
      "y": -5,
      "z": 0,
      "name": "Empty"
    },
    {
      "x": -2,
      "y": -4,
      "z": 0,
      "name": "Empty"
    },
    {
      "x": -2,
      "y": -3,
      "z": 0,
      "name": "Empty"
    },
    {
      "x": -2,
      "y": -2,
      "z": 0,
      "name": "Empty"
    },
    {
      "x": -2,
      "y": -1,
      "z": 0,
      "name": "Rock_Stone_Cyberverse"
    },
    {
      "x": -2,
      "y": 0,
      "z": 0,
      "name": "Empty"
    },
    {
      "x": -2,
      "y": -9,
      "z": 1,
      "name": "Live_Wires",
      "support": 15
    },
    {
      "x": -2,
      "y": -8,
      "z": 1,
      "name": "Empty"
    },
    {
      "x": -2,
      "y": -7,
      "z": 1,
      "name": "Empty"
    },
    {
      "x": -2,
      "y": -6,
      "z": 1,
      "name": "Empty"
    },
    {
      "x": -2,
      "y": -5,
      "z": 1,
      "name": "Empty"
    },
    {
      "x": -2,
      "y": -4,
      "z": 1,
      "name": "Empty"
    },
    {
      "x": -2,
      "y": -3,
      "z": 1,
      "name": "Empty"
    },
    {
      "x": -2,
      "y": -2,
      "z": 1,
      "name": "Empty"
    },
    {
      "x": -2,
      "y": -1,
      "z": 1,
      "name": "Rock_Stone_Cyberverse_Unstable"
    },
    {
      "x": -2,
      "y": 0,
      "z": 1,
      "name": "Empty"
    },
    {
      "x": -2,
      "y": -9,
      "z": 2,
      "name": "Live_Wires",
      "support": 15
    },
    {
      "x": -2,
      "y": -8,
      "z": 2,
      "name": "Empty"
    },
    {
      "x": -2,
      "y": -7,
      "z": 2,
      "name": "Empty"
    },
    {
      "x": -2,
      "y": -6,
      "z": 2,
      "name": "Empty"
    },
    {
      "x": -2,
      "y": -5,
      "z": 2,
      "name": "Empty"
    },
    {
      "x": -2,
      "y": -4,
      "z": 2,
      "name": "Empty"
    },
    {
      "x": -2,
      "y": -3,
      "z": 2,
      "name": "Empty"
    },
    {
      "x": -2,
      "y": -2,
      "z": 2,
      "name": "Empty"
    },
    {
      "x": -2,
      "y": -1,
      "z": 2,
      "name": "Rock_Stone_Cyberverse_Unstable"
    },
    {
      "x": -2,
      "y": 0,
      "z": 2,
      "name": "Empty"
    },
    {
      "x": -2,
      "y": -9,
      "z": 3,
      "name": "Rock_Stone_Cyberverse"
    },
    {
      "x": -2,
      "y": -8,
      "z": 3,
      "name": "Rock_Stone_Cyberverse"
    },
    {
      "x": -2,
      "y": -7,
      "z": 3,
      "name": "Rock_Stone_Cyberverse"
    },
    {
      "x": -2,
      "y": -6,
      "z": 3,
      "name": "Rock_Stone_Cyberverse"
    },
    {
      "x": -2,
      "y": -5,
      "z": 3,
      "name": "Rock_Stone_Cyberverse"
    },
    {
      "x": -2,
      "y": -4,
      "z": 3,
      "name": "Rock_Stone_Cyberverse"
    },
    {
      "x": -2,
      "y": -3,
      "z": 3,
      "name": "Rock_Stone_Cyberverse"
    },
    {
      "x": -2,
      "y": -2,
      "z": 3,
      "name": "Rock_Stone_Cyberverse"
    },
    {
      "x": -2,
      "y": -1,
      "z": 3,
      "name": "Rock_Stone_Cyberverse"
    },
    {
      "x": -2,
      "y": 0,
      "z": 3,
      "name": "Empty"
    },
    {
      "x": -1,
      "y": -9,
      "z": -3,
      "name": "Rock_Stone_Cyberverse"
    },
    {
      "x": -1,
      "y": -8,
      "z": -3,
      "name": "Rock_Stone_Cyberverse"
    },
    {
      "x": -1,
      "y": -7,
      "z": -3,
      "name": "Rock_Stone_Cyberverse"
    },
    {
      "x": -1,
      "y": -6,
      "z": -3,
      "name": "Rock_Stone_Cyberverse"
    },
    {
      "x": -1,
      "y": -5,
      "z": -3,
      "name": "Rock_Stone_Cyberverse"
    },
    {
      "x": -1,
      "y": -4,
      "z": -3,
      "name": "Rock_Stone_Cyberverse"
    },
    {
      "x": -1,
      "y": -3,
      "z": -3,
      "name": "Rock_Stone_Cyberverse"
    },
    {
      "x": -1,
      "y": -2,
      "z": -3,
      "name": "Rock_Stone_Cyberverse"
    },
    {
      "x": -1,
      "y": -1,
      "z": -3,
      "name": "Rock_Stone_Cyberverse"
    },
    {
      "x": -1,
      "y": 0,
      "z": -3,
      "name": "Empty"
    },
    {
      "x": -1,
      "y": -9,
      "z": -2,
      "name": "Live_Wires",
      "support": 15
    },
    {
      "x": -1,
      "y": -8,
      "z": -2,
      "name": "Empty"
    },
    {
      "x": -1,
      "y": -7,
      "z": -2,
      "name": "Live_Wires",
      "support": 15,
      "rotation": 4
    },
    {
      "x": -1,
      "y": -6,
      "z": -2,
      "name": "Live_Wires",
      "support": 15,
      "rotation": 4
    },
    {
      "x": -1,
      "y": -5,
      "z": -2,
      "name": "Live_Wires",
      "support": 15,
      "rotation": 4
    },
    {
      "x": -1,
      "y": -4,
      "z": -2,
      "name": "Live_Wires",
      "support": 15,
      "rotation": 4
    },
    {
      "x": -1,
      "y": -3,
      "z": -2,
      "name": "Empty"
    },
    {
      "x": -1,
      "y": -2,
      "z": -2,
      "name": "Empty"
    },
    {
      "x": -1,
      "y": -1,
      "z": -2,
      "name": "Rock_Stone_Cyberverse_Unstable"
    },
    {
      "x": -1,
      "y": 0,
      "z": -2,
      "name": "Empty"
    },
    {
      "x": -1,
      "y": -9,
      "z": -1,
      "name": "Live_Wires",
      "support": 15
    },
    {
      "x": -1,
      "y": -8,
      "z": -1,
      "name": "Empty"
    },
    {
      "x": -1,
      "y": -7,
      "z": -1,
      "name": "Empty"
    },
    {
      "x": -1,
      "y": -6,
      "z": -1,
      "name": "Empty"
    },
    {
      "x": -1,
      "y": -5,
      "z": -1,
      "name": "Empty"
    },
    {
      "x": -1,
      "y": -4,
      "z": -1,
      "name": "Empty"
    },
    {
      "x": -1,
      "y": -3,
      "z": -1,
      "name": "Empty"
    },
    {
      "x": -1,
      "y": -2,
      "z": -1,
      "name": "Empty"
    },
    {
      "x": -1,
      "y": -1,
      "z": -1,
      "name": "Rock_Stone_Cyberverse_Unstable"
    },
    {
      "x": -1,
      "y": 0,
      "z": -1,
      "name": "Empty"
    },
    {
      "x": -1,
      "y": -9,
      "z": 0,
      "name": "Live_Wires",
      "support": 15
    },
    {
      "x": -1,
      "y": -8,
      "z": 0,
      "name": "Empty"
    },
    {
      "x": -1,
      "y": -7,
      "z": 0,
      "name": "Empty"
    },
    {
      "x": -1,
      "y": -6,
      "z": 0,
      "name": "Empty"
    },
    {
      "x": -1,
      "y": -5,
      "z": 0,
      "name": "Empty"
    },
    {
      "x": -1,
      "y": -4,
      "z": 0,
      "name": "Empty"
    },
    {
      "x": -1,
      "y": -3,
      "z": 0,
      "name": "Empty"
    },
    {
      "x": -1,
      "y": -2,
      "z": 0,
      "name": "Empty"
    },
    {
      "x": -1,
      "y": -1,
      "z": 0,
      "name": "Rock_Stone_Cyberverse_Unstable"
    },
    {
      "x": -1,
      "y": 0,
      "z": 0,
      "name": "Empty"
    },
    {
      "x": -1,
      "y": -9,
      "z": 1,
      "name": "Live_Wires",
      "support": 15
    },
    {
      "x": -1,
      "y": -8,
      "z": 1,
      "name": "Empty"
    },
    {
      "x": -1,
      "y": -7,
      "z": 1,
      "name": "Empty"
    },
    {
      "x": -1,
      "y": -6,
      "z": 1,
      "name": "Empty"
    },
    {
      "x": -1,
      "y": -5,
      "z": 1,
      "name": "Empty"
    },
    {
      "x": -1,
      "y": -4,
      "z": 1,
      "name": "Empty"
    },
    {
      "x": -1,
      "y": -3,
      "z": 1,
      "name": "Empty"
    },
    {
      "x": -1,
      "y": -2,
      "z": 1,
      "name": "Empty"
    },
    {
      "x": -1,
      "y": -1,
      "z": 1,
      "name": "Rock_Stone_Cyberverse_Unstable"
    },
    {
      "x": -1,
      "y": 0,
      "z": 1,
      "name": "Empty"
    },
    {
      "x": -1,
      "y": -9,
      "z": 2,
      "name": "Live_Wires",
      "support": 15
    },
    {
      "x": -1,
      "y": -8,
      "z": 2,
      "name": "Empty"
    },
    {
      "x": -1,
      "y": -7,
      "z": 2,
      "name": "Empty"
    },
    {
      "x": -1,
      "y": -6,
      "z": 2,
      "name": "Empty"
    },
    {
      "x": -1,
      "y": -5,
      "z": 2,
      "name": "Empty"
    },
    {
      "x": -1,
      "y": -4,
      "z": 2,
      "name": "Empty"
    },
    {
      "x": -1,
      "y": -3,
      "z": 2,
      "name": "Empty"
    },
    {
      "x": -1,
      "y": -2,
      "z": 2,
      "name": "Empty"
    },
    {
      "x": -1,
      "y": -1,
      "z": 2,
      "name": "Rock_Stone_Cyberverse_Unstable"
    },
    {
      "x": -1,
      "y": 0,
      "z": 2,
      "name": "Empty"
    },
    {
      "x": -1,
      "y": -9,
      "z": 3,
      "name": "Rock_Stone_Cyberverse"
    },
    {
      "x": -1,
      "y": -8,
      "z": 3,
      "name": "Rock_Stone_Cyberverse"
    },
    {
      "x": -1,
      "y": -7,
      "z": 3,
      "name": "Rock_Stone_Cyberverse"
    },
    {
      "x": -1,
      "y": -6,
      "z": 3,
      "name": "Rock_Stone_Cyberverse"
    },
    {
      "x": -1,
      "y": -5,
      "z": 3,
      "name": "Rock_Stone_Cyberverse"
    },
    {
      "x": -1,
      "y": -4,
      "z": 3,
      "name": "Rock_Stone_Cyberverse"
    },
    {
      "x": -1,
      "y": -3,
      "z": 3,
      "name": "Rock_Stone_Cyberverse"
    },
    {
      "x": -1,
      "y": -2,
      "z": 3,
      "name": "Rock_Stone_Cyberverse"
    },
    {
      "x": -1,
      "y": -1,
      "z": 3,
      "name": "Rock_Stone_Cyberverse"
    },
    {
      "x": -1,
      "y": 0,
      "z": 3,
      "name": "Empty"
    },
    {
      "x": 0,
      "y": -9,
      "z": -3,
      "name": "Rock_Stone_Cyberverse"
    },
    {
      "x": 0,
      "y": -8,
      "z": -3,
      "name": "Rock_Stone_Cyberverse"
    },
    {
      "x": 0,
      "y": -7,
      "z": -3,
      "name": "Rock_Stone_Cyberverse"
    },
    {
      "x": 0,
      "y": -6,
      "z": -3,
      "name": "Rock_Stone_Cyberverse"
    },
    {
      "x": 0,
      "y": -5,
      "z": -3,
      "name": "Rock_Stone_Cyberverse"
    },
    {
      "x": 0,
      "y": -4,
      "z": -3,
      "name": "Rock_Stone_Cyberverse"
    },
    {
      "x": 0,
      "y": -3,
      "z": -3,
      "name": "Rock_Stone_Cyberverse"
    },
    {
      "x": 0,
      "y": -2,
      "z": -3,
      "name": "Rock_Stone_Cyberverse"
    },
    {
      "x": 0,
      "y": -1,
      "z": -3,
      "name": "Rock_Stone_Cyberverse"
    },
    {
      "x": 0,
      "y": 0,
      "z": -3,
      "name": "Empty"
    },
    {
      "x": 0,
      "y": -9,
      "z": -2,
      "name": "Live_Wires",
      "support": 15
    },
    {
      "x": 0,
      "y": -8,
      "z": -2,
      "name": "Live_Wires",
      "support": 15,
      "rotation": 4
    },
    {
      "x": 0,
      "y": -7,
      "z": -2,
      "name": "Live_Wires",
      "support": 15,
      "rotation": 4
    },
    {
      "x": 0,
      "y": -6,
      "z": -2,
      "name": "Live_Wires",
      "support": 15,
      "rotation": 4
    },
    {
      "x": 0,
      "y": -5,
      "z": -2,
      "name": "Empty"
    },
    {
      "x": 0,
      "y": -4,
      "z": -2,
      "name": "Empty"
    },
    {
      "x": 0,
      "y": -3,
      "z": -2,
      "name": "Empty"
    },
    {
      "x": 0,
      "y": -2,
      "z": -2,
      "name": "Empty"
    },
    {
      "x": 0,
      "y": -1,
      "z": -2,
      "name": "Rock_Stone_Cyberverse_Unstable"
    },
    {
      "x": 0,
      "y": 0,
      "z": -2,
      "name": "Empty"
    },
    {
      "x": 0,
      "y": -9,
      "z": -1,
      "name": "Live_Wires",
      "support": 15
    },
    {
      "x": 0,
      "y": -8,
      "z": -1,
      "name": "Empty"
    },
    {
      "x": 0,
      "y": -7,
      "z": -1,
      "name": "Empty"
    },
    {
      "x": 0,
      "y": -6,
      "z": -1,
      "name": "Empty"
    },
    {
      "x": 0,
      "y": -5,
      "z": -1,
      "name": "Empty"
    },
    {
      "x": 0,
      "y": -4,
      "z": -1,
      "name": "Empty"
    },
    {
      "x": 0,
      "y": -3,
      "z": -1,
      "name": "Empty"
    },
    {
      "x": 0,
      "y": -2,
      "z": -1,
      "name": "Empty"
    },
    {
      "x": 0,
      "y": -1,
      "z": -1,
      "name": "Rock_Stone_Cyberverse_Unstable"
    },
    {
      "x": 0,
      "y": 0,
      "z": -1,
      "name": "Empty"
    },
    {
      "x": 0,
      "y": -9,
      "z": 0,
      "name": "Live_Wires",
      "support": 15
    },
    {
      "x": 0,
      "y": -8,
      "z": 0,
      "name": "Empty"
    },
    {
      "x": 0,
      "y": -7,
      "z": 0,
      "name": "Empty"
    },
    {
      "x": 0,
      "y": -6,
      "z": 0,
      "name": "Empty"
    },
    {
      "x": 0,
      "y": -5,
      "z": 0,
      "name": "Empty"
    },
    {
      "x": 0,
      "y": -4,
      "z": 0,
      "name": "Empty"
    },
    {
      "x": 0,
      "y": -3,
      "z": 0,
      "name": "Empty"
    },
    {
      "x": 0,
      "y": -2,
      "z": 0,
      "name": "Empty"
    },
    {
      "x": 0,
      "y": -1,
      "z": 0,
      "name": "Rock_Stone_Cyberverse_Unstable"
    },
    {
      "x": 0,
      "y": 0,
      "z": 0,
      "name": "File_Folder",
      "components": {
        "Components": {
          "PlacedByInteraction": {
            "WhoPlacedUuid": {
              "$binary": "MPHUpLOaS6efxfnko+aohw==",
              "$type": "04"
            }
          },
          "ItemContainerBlock": {
            "ItemContainer": {
              "Capacity": 9,
              "Items": {
                "0": {
                  "Id": "Spaghetti_Code",
                  "Quantity": 4,
                  "Durability": 0.0,
                  "MaxDurability": 0.0,
                  "OverrideDroppedItemAnimation": false
                },
                "8": {
                  "Id": "Spaghetti_Code",
                  "Quantity": 4,
                  "Durability": 0.0,
                  "MaxDurability": 0.0,
                  "OverrideDroppedItemAnimation": false
                }
              }
            },
            "Capacity": 9
          }
        }
      },
      "rotation": 1
    },
    {
      "x": 0,
      "y": -9,
      "z": 1,
      "name": "Live_Wires",
      "support": 15
    },
    {
      "x": 0,
      "y": -8,
      "z": 1,
      "name": "Empty"
    },
    {
      "x": 0,
      "y": -7,
      "z": 1,
      "name": "Empty"
    },
    {
      "x": 0,
      "y": -6,
      "z": 1,
      "name": "Empty"
    },
    {
      "x": 0,
      "y": -5,
      "z": 1,
      "name": "Empty"
    },
    {
      "x": 0,
      "y": -4,
      "z": 1,
      "name": "Empty"
    },
    {
      "x": 0,
      "y": -3,
      "z": 1,
      "name": "Empty"
    },
    {
      "x": 0,
      "y": -2,
      "z": 1,
      "name": "Empty"
    },
    {
      "x": 0,
      "y": -1,
      "z": 1,
      "name": "Rock_Stone_Cyberverse_Unstable"
    },
    {
      "x": 0,
      "y": 0,
      "z": 1,
      "name": "Empty"
    },
    {
      "x": 0,
      "y": -9,
      "z": 2,
      "name": "Live_Wires",
      "support": 15
    },
    {
      "x": 0,
      "y": -8,
      "z": 2,
      "name": "Empty"
    },
    {
      "x": 0,
      "y": -7,
      "z": 2,
      "name": "Empty"
    },
    {
      "x": 0,
      "y": -6,
      "z": 2,
      "name": "Empty"
    },
    {
      "x": 0,
      "y": -5,
      "z": 2,
      "name": "Empty"
    },
    {
      "x": 0,
      "y": -4,
      "z": 2,
      "name": "Empty"
    },
    {
      "x": 0,
      "y": -3,
      "z": 2,
      "name": "Empty"
    },
    {
      "x": 0,
      "y": -2,
      "z": 2,
      "name": "Empty"
    },
    {
      "x": 0,
      "y": -1,
      "z": 2,
      "name": "Rock_Stone_Cyberverse_Unstable"
    },
    {
      "x": 0,
      "y": 0,
      "z": 2,
      "name": "Empty"
    },
    {
      "x": 0,
      "y": -9,
      "z": 3,
      "name": "Rock_Stone_Cyberverse"
    },
    {
      "x": 0,
      "y": -8,
      "z": 3,
      "name": "Rock_Stone_Cyberverse"
    },
    {
      "x": 0,
      "y": -7,
      "z": 3,
      "name": "Rock_Stone_Cyberverse"
    },
    {
      "x": 0,
      "y": -6,
      "z": 3,
      "name": "Rock_Stone_Cyberverse"
    },
    {
      "x": 0,
      "y": -5,
      "z": 3,
      "name": "Rock_Stone_Cyberverse"
    },
    {
      "x": 0,
      "y": -4,
      "z": 3,
      "name": "Rock_Stone_Cyberverse"
    },
    {
      "x": 0,
      "y": -3,
      "z": 3,
      "name": "Rock_Stone_Cyberverse"
    },
    {
      "x": 0,
      "y": -2,
      "z": 3,
      "name": "Rock_Stone_Cyberverse"
    },
    {
      "x": 0,
      "y": -1,
      "z": 3,
      "name": "Rock_Stone_Cyberverse"
    },
    {
      "x": 0,
      "y": 0,
      "z": 3,
      "name": "Empty"
    },
    {
      "x": 1,
      "y": -9,
      "z": -3,
      "name": "Rock_Stone_Cyberverse"
    },
    {
      "x": 1,
      "y": -8,
      "z": -3,
      "name": "Rock_Stone_Cyberverse"
    },
    {
      "x": 1,
      "y": -7,
      "z": -3,
      "name": "Rock_Stone_Cyberverse"
    },
    {
      "x": 1,
      "y": -6,
      "z": -3,
      "name": "Rock_Stone_Cyberverse"
    },
    {
      "x": 1,
      "y": -5,
      "z": -3,
      "name": "Rock_Stone_Cyberverse"
    },
    {
      "x": 1,
      "y": -4,
      "z": -3,
      "name": "Rock_Stone_Cyberverse"
    },
    {
      "x": 1,
      "y": -3,
      "z": -3,
      "name": "Rock_Stone_Cyberverse"
    },
    {
      "x": 1,
      "y": -2,
      "z": -3,
      "name": "Rock_Stone_Cyberverse"
    },
    {
      "x": 1,
      "y": -1,
      "z": -3,
      "name": "Rock_Stone_Cyberverse"
    },
    {
      "x": 1,
      "y": 0,
      "z": -3,
      "name": "Empty"
    },
    {
      "x": 1,
      "y": -9,
      "z": -2,
      "name": "Live_Wires",
      "support": 15
    },
    {
      "x": 1,
      "y": -8,
      "z": -2,
      "name": "Empty"
    },
    {
      "x": 1,
      "y": -7,
      "z": -2,
      "name": "Empty"
    },
    {
      "x": 1,
      "y": -6,
      "z": -2,
      "name": "Empty"
    },
    {
      "x": 1,
      "y": -5,
      "z": -2,
      "name": "Empty"
    },
    {
      "x": 1,
      "y": -4,
      "z": -2,
      "name": "Empty"
    },
    {
      "x": 1,
      "y": -3,
      "z": -2,
      "name": "Live_Wires",
      "support": 15,
      "rotation": 4
    },
    {
      "x": 1,
      "y": -2,
      "z": -2,
      "name": "Empty"
    },
    {
      "x": 1,
      "y": -1,
      "z": -2,
      "name": "Rock_Stone_Cyberverse_Unstable"
    },
    {
      "x": 1,
      "y": 0,
      "z": -2,
      "name": "Empty"
    },
    {
      "x": 1,
      "y": -9,
      "z": -1,
      "name": "Live_Wires",
      "support": 15
    },
    {
      "x": 1,
      "y": -8,
      "z": -1,
      "name": "Empty"
    },
    {
      "x": 1,
      "y": -7,
      "z": -1,
      "name": "Empty"
    },
    {
      "x": 1,
      "y": -6,
      "z": -1,
      "name": "Empty"
    },
    {
      "x": 1,
      "y": -5,
      "z": -1,
      "name": "Empty"
    },
    {
      "x": 1,
      "y": -4,
      "z": -1,
      "name": "Empty"
    },
    {
      "x": 1,
      "y": -3,
      "z": -1,
      "name": "Empty"
    },
    {
      "x": 1,
      "y": -2,
      "z": -1,
      "name": "Empty"
    },
    {
      "x": 1,
      "y": -1,
      "z": -1,
      "name": "Rock_Stone_Cyberverse_Unstable"
    },
    {
      "x": 1,
      "y": 0,
      "z": -1,
      "name": "Empty"
    },
    {
      "x": 1,
      "y": -9,
      "z": 0,
      "name": "Live_Wires",
      "support": 15
    },
    {
      "x": 1,
      "y": -8,
      "z": 0,
      "name": "Empty"
    },
    {
      "x": 1,
      "y": -7,
      "z": 0,
      "name": "Empty"
    },
    {
      "x": 1,
      "y": -6,
      "z": 0,
      "name": "Empty"
    },
    {
      "x": 1,
      "y": -5,
      "z": 0,
      "name": "Empty"
    },
    {
      "x": 1,
      "y": -4,
      "z": 0,
      "name": "Empty"
    },
    {
      "x": 1,
      "y": -3,
      "z": 0,
      "name": "Empty"
    },
    {
      "x": 1,
      "y": -2,
      "z": 0,
      "name": "Empty"
    },
    {
      "x": 1,
      "y": -1,
      "z": 0,
      "name": "Rock_Stone_Cyberverse"
    },
    {
      "x": 1,
      "y": 0,
      "z": 0,
      "name": "Empty"
    },
    {
      "x": 1,
      "y": -9,
      "z": 1,
      "name": "Live_Wires",
      "support": 15
    },
    {
      "x": 1,
      "y": -8,
      "z": 1,
      "name": "Empty"
    },
    {
      "x": 1,
      "y": -7,
      "z": 1,
      "name": "Empty"
    },
    {
      "x": 1,
      "y": -6,
      "z": 1,
      "name": "Empty"
    },
    {
      "x": 1,
      "y": -5,
      "z": 1,
      "name": "Empty"
    },
    {
      "x": 1,
      "y": -4,
      "z": 1,
      "name": "Empty"
    },
    {
      "x": 1,
      "y": -3,
      "z": 1,
      "name": "Empty"
    },
    {
      "x": 1,
      "y": -2,
      "z": 1,
      "name": "Empty"
    },
    {
      "x": 1,
      "y": -1,
      "z": 1,
      "name": "Rock_Stone_Cyberverse"
    },
    {
      "x": 1,
      "y": 0,
      "z": 1,
      "name": "Empty"
    },
    {
      "x": 1,
      "y": -9,
      "z": 2,
      "name": "Live_Wires",
      "support": 15
    },
    {
      "x": 1,
      "y": -8,
      "z": 2,
      "name": "Empty"
    },
    {
      "x": 1,
      "y": -7,
      "z": 2,
      "name": "Empty"
    },
    {
      "x": 1,
      "y": -6,
      "z": 2,
      "name": "Live_Wires",
      "support": 15,
      "rotation": 6
    },
    {
      "x": 1,
      "y": -5,
      "z": 2,
      "name": "Live_Wires",
      "support": 15,
      "rotation": 6
    },
    {
      "x": 1,
      "y": -4,
      "z": 2,
      "name": "Live_Wires",
      "support": 15,
      "rotation": 6
    },
    {
      "x": 1,
      "y": -3,
      "z": 2,
      "name": "Empty"
    },
    {
      "x": 1,
      "y": -2,
      "z": 2,
      "name": "Empty"
    },
    {
      "x": 1,
      "y": -1,
      "z": 2,
      "name": "Rock_Stone_Cyberverse_Unstable"
    },
    {
      "x": 1,
      "y": 0,
      "z": 2,
      "name": "Empty"
    },
    {
      "x": 1,
      "y": -9,
      "z": 3,
      "name": "Rock_Stone_Cyberverse"
    },
    {
      "x": 1,
      "y": -8,
      "z": 3,
      "name": "Rock_Stone_Cyberverse"
    },
    {
      "x": 1,
      "y": -7,
      "z": 3,
      "name": "Rock_Stone_Cyberverse"
    },
    {
      "x": 1,
      "y": -6,
      "z": 3,
      "name": "Rock_Stone_Cyberverse"
    },
    {
      "x": 1,
      "y": -5,
      "z": 3,
      "name": "Rock_Stone_Cyberverse"
    },
    {
      "x": 1,
      "y": -4,
      "z": 3,
      "name": "Rock_Stone_Cyberverse"
    },
    {
      "x": 1,
      "y": -3,
      "z": 3,
      "name": "Rock_Stone_Cyberverse"
    },
    {
      "x": 1,
      "y": -2,
      "z": 3,
      "name": "Rock_Stone_Cyberverse"
    },
    {
      "x": 1,
      "y": -1,
      "z": 3,
      "name": "Rock_Stone_Cyberverse"
    },
    {
      "x": 1,
      "y": 0,
      "z": 3,
      "name": "Empty"
    },
    {
      "x": 2,
      "y": -9,
      "z": -3,
      "name": "Rock_Stone_Cyberverse"
    },
    {
      "x": 2,
      "y": -8,
      "z": -3,
      "name": "Rock_Stone_Cyberverse"
    },
    {
      "x": 2,
      "y": -7,
      "z": -3,
      "name": "Rock_Stone_Cyberverse"
    },
    {
      "x": 2,
      "y": -6,
      "z": -3,
      "name": "Rock_Stone_Cyberverse"
    },
    {
      "x": 2,
      "y": -5,
      "z": -3,
      "name": "Rock_Stone_Cyberverse"
    },
    {
      "x": 2,
      "y": -4,
      "z": -3,
      "name": "Rock_Stone_Cyberverse"
    },
    {
      "x": 2,
      "y": -3,
      "z": -3,
      "name": "Rock_Stone_Cyberverse"
    },
    {
      "x": 2,
      "y": -2,
      "z": -3,
      "name": "Rock_Stone_Cyberverse"
    },
    {
      "x": 2,
      "y": -1,
      "z": -3,
      "name": "Rock_Stone_Cyberverse"
    },
    {
      "x": 2,
      "y": 0,
      "z": -3,
      "name": "Empty"
    },
    {
      "x": 2,
      "y": -9,
      "z": -2,
      "name": "Live_Wires",
      "support": 15
    },
    {
      "x": 2,
      "y": -8,
      "z": -2,
      "name": "Empty"
    },
    {
      "x": 2,
      "y": -7,
      "z": -2,
      "name": "Empty"
    },
    {
      "x": 2,
      "y": -6,
      "z": -2,
      "name": "Empty"
    },
    {
      "x": 2,
      "y": -5,
      "z": -2,
      "name": "Empty"
    },
    {
      "x": 2,
      "y": -4,
      "z": -2,
      "name": "Empty"
    },
    {
      "x": 2,
      "y": -3,
      "z": -2,
      "name": "Live_Wires",
      "support": 15,
      "rotation": 7
    },
    {
      "x": 2,
      "y": -2,
      "z": -2,
      "name": "Live_Wires",
      "support": 15,
      "rotation": 4
    },
    {
      "x": 2,
      "y": -1,
      "z": -2,
      "name": "Rock_Stone_Cyberverse_Unstable"
    },
    {
      "x": 2,
      "y": 0,
      "z": -2,
      "name": "Empty"
    },
    {
      "x": 2,
      "y": -9,
      "z": -1,
      "name": "Live_Wires",
      "support": 15
    },
    {
      "x": 2,
      "y": -8,
      "z": -1,
      "name": "Empty"
    },
    {
      "x": 2,
      "y": -7,
      "z": -1,
      "name": "Empty"
    },
    {
      "x": 2,
      "y": -6,
      "z": -1,
      "name": "Empty"
    },
    {
      "x": 2,
      "y": -5,
      "z": -1,
      "name": "Empty"
    },
    {
      "x": 2,
      "y": -4,
      "z": -1,
      "name": "Empty"
    },
    {
      "x": 2,
      "y": -3,
      "z": -1,
      "name": "Empty"
    },
    {
      "x": 2,
      "y": -2,
      "z": -1,
      "name": "Live_Wires",
      "support": 15,
      "rotation": 7
    },
    {
      "x": 2,
      "y": -1,
      "z": -1,
      "name": "Rock_Stone_Cyberverse_Unstable"
    },
    {
      "x": 2,
      "y": 0,
      "z": -1,
      "name": "Empty"
    },
    {
      "x": 2,
      "y": -9,
      "z": 0,
      "name": "Live_Wires",
      "support": 15
    },
    {
      "x": 2,
      "y": -8,
      "z": 0,
      "name": "Empty"
    },
    {
      "x": 2,
      "y": -7,
      "z": 0,
      "name": "Empty"
    },
    {
      "x": 2,
      "y": -6,
      "z": 0,
      "name": "Empty"
    },
    {
      "x": 2,
      "y": -5,
      "z": 0,
      "name": "Empty"
    },
    {
      "x": 2,
      "y": -4,
      "z": 0,
      "name": "Empty"
    },
    {
      "x": 2,
      "y": -3,
      "z": 0,
      "name": "Empty"
    },
    {
      "x": 2,
      "y": -2,
      "z": 0,
      "name": "Empty"
    },
    {
      "x": 2,
      "y": -1,
      "z": 0,
      "name": "Rock_Stone_Cyberverse_Unstable"
    },
    {
      "x": 2,
      "y": 0,
      "z": 0,
      "name": "Empty"
    },
    {
      "x": 2,
      "y": -9,
      "z": 1,
      "name": "Live_Wires",
      "support": 15
    },
    {
      "x": 2,
      "y": -8,
      "z": 1,
      "name": "Empty"
    },
    {
      "x": 2,
      "y": -7,
      "z": 1,
      "name": "Empty"
    },
    {
      "x": 2,
      "y": -6,
      "z": 1,
      "name": "Empty"
    },
    {
      "x": 2,
      "y": -5,
      "z": 1,
      "name": "Empty"
    },
    {
      "x": 2,
      "y": -4,
      "z": 1,
      "name": "Live_Wires",
      "support": 15,
      "rotation": 7
    },
    {
      "x": 2,
      "y": -3,
      "z": 1,
      "name": "Live_Wires",
      "support": 15,
      "rotation": 7
    },
    {
      "x": 2,
      "y": -2,
      "z": 1,
      "name": "Empty"
    },
    {
      "x": 2,
      "y": -1,
      "z": 1,
      "name": "Rock_Stone_Cyberverse_Unstable"
    },
    {
      "x": 2,
      "y": 0,
      "z": 1,
      "name": "Empty"
    },
    {
      "x": 2,
      "y": -9,
      "z": 2,
      "name": "Live_Wires",
      "support": 15
    },
    {
      "x": 2,
      "y": -8,
      "z": 2,
      "name": "Empty"
    },
    {
      "x": 2,
      "y": -7,
      "z": 2,
      "name": "Live_Wires",
      "support": 15,
      "rotation": 6
    },
    {
      "x": 2,
      "y": -6,
      "z": 2,
      "name": "Live_Wires",
      "support": 15,
      "rotation": 6
    },
    {
      "x": 2,
      "y": -5,
      "z": 2,
      "name": "Live_Wires",
      "support": 15,
      "rotation": 7
    },
    {
      "x": 2,
      "y": -4,
      "z": 2,
      "name": "Live_Wires",
      "support": 15,
      "rotation": 7
    },
    {
      "x": 2,
      "y": -3,
      "z": 2,
      "name": "Live_Wires",
      "support": 15,
      "rotation": 7
    },
    {
      "x": 2,
      "y": -2,
      "z": 2,
      "name": "Empty"
    },
    {
      "x": 2,
      "y": -1,
      "z": 2,
      "name": "Rock_Stone_Cyberverse_Unstable"
    },
    {
      "x": 2,
      "y": 0,
      "z": 2,
      "name": "Empty"
    },
    {
      "x": 2,
      "y": -9,
      "z": 3,
      "name": "Rock_Stone_Cyberverse"
    },
    {
      "x": 2,
      "y": -8,
      "z": 3,
      "name": "Rock_Stone_Cyberverse"
    },
    {
      "x": 2,
      "y": -7,
      "z": 3,
      "name": "Rock_Stone_Cyberverse"
    },
    {
      "x": 2,
      "y": -6,
      "z": 3,
      "name": "Rock_Stone_Cyberverse"
    },
    {
      "x": 2,
      "y": -5,
      "z": 3,
      "name": "Rock_Stone_Cyberverse"
    },
    {
      "x": 2,
      "y": -4,
      "z": 3,
      "name": "Rock_Stone_Cyberverse"
    },
    {
      "x": 2,
      "y": -3,
      "z": 3,
      "name": "Rock_Stone_Cyberverse"
    },
    {
      "x": 2,
      "y": -2,
      "z": 3,
      "name": "Rock_Stone_Cyberverse"
    },
    {
      "x": 2,
      "y": -1,
      "z": 3,
      "name": "Rock_Stone_Cyberverse"
    },
    {
      "x": 2,
      "y": 0,
      "z": 3,
      "name": "Empty"
    },
    {
      "x": 3,
      "y": -9,
      "z": -3,
      "name": "Rock_Stone_Cyberverse"
    },
    {
      "x": 3,
      "y": -8,
      "z": -3,
      "name": "Rock_Stone_Cyberverse"
    },
    {
      "x": 3,
      "y": -7,
      "z": -3,
      "name": "Rock_Stone_Cyberverse"
    },
    {
      "x": 3,
      "y": -6,
      "z": -3,
      "name": "Rock_Stone_Cyberverse"
    },
    {
      "x": 3,
      "y": -5,
      "z": -3,
      "name": "Rock_Stone_Cyberverse"
    },
    {
      "x": 3,
      "y": -4,
      "z": -3,
      "name": "Rock_Stone_Cyberverse"
    },
    {
      "x": 3,
      "y": -3,
      "z": -3,
      "name": "Rock_Stone_Cyberverse"
    },
    {
      "x": 3,
      "y": -2,
      "z": -3,
      "name": "Rock_Stone_Cyberverse"
    },
    {
      "x": 3,
      "y": -1,
      "z": -3,
      "name": "Rock_Stone_Cyberverse"
    },
    {
      "x": 3,
      "y": 0,
      "z": -3,
      "name": "Empty"
    },
    {
      "x": 3,
      "y": -9,
      "z": -2,
      "name": "Rock_Stone_Cyberverse"
    },
    {
      "x": 3,
      "y": -8,
      "z": -2,
      "name": "Rock_Stone_Cyberverse"
    },
    {
      "x": 3,
      "y": -7,
      "z": -2,
      "name": "Rock_Stone_Cyberverse"
    },
    {
      "x": 3,
      "y": -6,
      "z": -2,
      "name": "Rock_Stone_Cyberverse"
    },
    {
      "x": 3,
      "y": -5,
      "z": -2,
      "name": "Rock_Stone_Cyberverse"
    },
    {
      "x": 3,
      "y": -4,
      "z": -2,
      "name": "Rock_Stone_Cyberverse"
    },
    {
      "x": 3,
      "y": -3,
      "z": -2,
      "name": "Rock_Stone_Cyberverse"
    },
    {
      "x": 3,
      "y": -2,
      "z": -2,
      "name": "Rock_Stone_Cyberverse"
    },
    {
      "x": 3,
      "y": -1,
      "z": -2,
      "name": "Rock_Stone_Cyberverse"
    },
    {
      "x": 3,
      "y": 0,
      "z": -2,
      "name": "Empty"
    },
    {
      "x": 3,
      "y": -9,
      "z": -1,
      "name": "Rock_Stone_Cyberverse"
    },
    {
      "x": 3,
      "y": -8,
      "z": -1,
      "name": "Rock_Stone_Cyberverse"
    },
    {
      "x": 3,
      "y": -7,
      "z": -1,
      "name": "Rock_Stone_Cyberverse"
    },
    {
      "x": 3,
      "y": -6,
      "z": -1,
      "name": "Rock_Stone_Cyberverse"
    },
    {
      "x": 3,
      "y": -5,
      "z": -1,
      "name": "Rock_Stone_Cyberverse"
    },
    {
      "x": 3,
      "y": -4,
      "z": -1,
      "name": "Rock_Stone_Cyberverse"
    },
    {
      "x": 3,
      "y": -3,
      "z": -1,
      "name": "Rock_Stone_Cyberverse"
    },
    {
      "x": 3,
      "y": -2,
      "z": -1,
      "name": "Rock_Stone_Cyberverse"
    },
    {
      "x": 3,
      "y": -1,
      "z": -1,
      "name": "Rock_Stone_Cyberverse"
    },
    {
      "x": 3,
      "y": 0,
      "z": -1,
      "name": "Empty"
    },
    {
      "x": 3,
      "y": -9,
      "z": 0,
      "name": "Rock_Stone_Cyberverse"
    },
    {
      "x": 3,
      "y": -8,
      "z": 0,
      "name": "Rock_Stone_Cyberverse"
    },
    {
      "x": 3,
      "y": -7,
      "z": 0,
      "name": "Rock_Stone_Cyberverse"
    },
    {
      "x": 3,
      "y": -6,
      "z": 0,
      "name": "Rock_Stone_Cyberverse"
    },
    {
      "x": 3,
      "y": -5,
      "z": 0,
      "name": "Rock_Stone_Cyberverse"
    },
    {
      "x": 3,
      "y": -4,
      "z": 0,
      "name": "Rock_Stone_Cyberverse"
    },
    {
      "x": 3,
      "y": -3,
      "z": 0,
      "name": "Rock_Stone_Cyberverse"
    },
    {
      "x": 3,
      "y": -2,
      "z": 0,
      "name": "Rock_Stone_Cyberverse"
    },
    {
      "x": 3,
      "y": -1,
      "z": 0,
      "name": "Rock_Stone_Cyberverse"
    },
    {
      "x": 3,
      "y": 0,
      "z": 0,
      "name": "Empty"
    },
    {
      "x": 3,
      "y": -9,
      "z": 1,
      "name": "Rock_Stone_Cyberverse"
    },
    {
      "x": 3,
      "y": -8,
      "z": 1,
      "name": "Rock_Stone_Cyberverse"
    },
    {
      "x": 3,
      "y": -7,
      "z": 1,
      "name": "Rock_Stone_Cyberverse"
    },
    {
      "x": 3,
      "y": -6,
      "z": 1,
      "name": "Rock_Stone_Cyberverse"
    },
    {
      "x": 3,
      "y": -5,
      "z": 1,
      "name": "Rock_Stone_Cyberverse"
    },
    {
      "x": 3,
      "y": -4,
      "z": 1,
      "name": "Rock_Stone_Cyberverse"
    },
    {
      "x": 3,
      "y": -3,
      "z": 1,
      "name": "Rock_Stone_Cyberverse"
    },
    {
      "x": 3,
      "y": -2,
      "z": 1,
      "name": "Rock_Stone_Cyberverse"
    },
    {
      "x": 3,
      "y": -1,
      "z": 1,
      "name": "Rock_Stone_Cyberverse"
    },
    {
      "x": 3,
      "y": 0,
      "z": 1,
      "name": "Empty"
    },
    {
      "x": 3,
      "y": -9,
      "z": 2,
      "name": "Rock_Stone_Cyberverse"
    },
    {
      "x": 3,
      "y": -8,
      "z": 2,
      "name": "Rock_Stone_Cyberverse"
    },
    {
      "x": 3,
      "y": -7,
      "z": 2,
      "name": "Rock_Stone_Cyberverse"
    },
    {
      "x": 3,
      "y": -6,
      "z": 2,
      "name": "Rock_Stone_Cyberverse"
    },
    {
      "x": 3,
      "y": -5,
      "z": 2,
      "name": "Rock_Stone_Cyberverse"
    },
    {
      "x": 3,
      "y": -4,
      "z": 2,
      "name": "Rock_Stone_Cyberverse"
    },
    {
      "x": 3,
      "y": -3,
      "z": 2,
      "name": "Rock_Stone_Cyberverse"
    },
    {
      "x": 3,
      "y": -2,
      "z": 2,
      "name": "Rock_Stone_Cyberverse"
    },
    {
      "x": 3,
      "y": -1,
      "z": 2,
      "name": "Rock_Stone_Cyberverse"
    },
    {
      "x": 3,
      "y": 0,
      "z": 2,
      "name": "Empty"
    },
    {
      "x": 3,
      "y": -9,
      "z": 3,
      "name": "Rock_Stone_Cyberverse"
    },
    {
      "x": 3,
      "y": -8,
      "z": 3,
      "name": "Rock_Stone_Cyberverse"
    },
    {
      "x": 3,
      "y": -7,
      "z": 3,
      "name": "Rock_Stone_Cyberverse"
    },
    {
      "x": 3,
      "y": -6,
      "z": 3,
      "name": "Rock_Stone_Cyberverse"
    },
    {
      "x": 3,
      "y": -5,
      "z": 3,
      "name": "Rock_Stone_Cyberverse"
    },
    {
      "x": 3,
      "y": -4,
      "z": 3,
      "name": "Rock_Stone_Cyberverse"
    },
    {
      "x": 3,
      "y": -3,
      "z": 3,
      "name": "Rock_Stone_Cyberverse"
    },
    {
      "x": 3,
      "y": -2,
      "z": 3,
      "name": "Rock_Stone_Cyberverse"
    },
    {
      "x": 3,
      "y": -1,
      "z": 3,
      "name": "Rock_Stone_Cyberverse"
    },
    {
      "x": 3,
      "y": 0,
      "z": 3,
      "name": "Empty"
    }
  ]
}