{
  "version": 8,
  "blockIdVersion": 11,
  "anchorX": 0,
  "anchorY": 0,
  "anchorZ": 0,
  "blocks": [
    {
      "x": -4,
      "y": -6,
      "z": -3,
      "name": "Rock_Stone_Cyberverse_Glitched"
    },
    {
      "x": -4,
      "y": -5,
      "z": -3,
      "name": "Rock_Stone_Cyberverse"
    },
    {
      "x": -4,
      "y": -4,
      "z": -3,
      "name": "Rock_Stone_Cyberverse"
    },
    {
      "x": -4,
      "y": -3,
      "z": -3,
      "name": "Rock_Stone_Cyberverse"
    },
    {
      "x": -4,
      "y": -2,
      "z": -3,
      "name": "Rock_Stone_Cyberverse_Brick"
    },
    {
      "x": -4,
      "y": -1,
      "z": -3,
      "name": "Rock_Stone_Cyberverse"
    },
    {
      "x": -4,
      "y": 0,
      "z": -3,
      "name": "Rock_Stone_Cyberverse_Brick"
    },
    {
      "x": -4,
      "y": 1,
      "z": -3,
      "name": "Rock_Stone_Cyberverse_Brick"
    },
    {
      "x": -4,
      "y": 2,
      "z": -3,
      "name": "Rock_Stone_Cyberverse_Brick"
    },
    {
      "x": -4,
      "y": 3,
      "z": -3,
      "name": "Rock_Stone_Cyberverse_Brick"
    },
    {
      "x": -4,
      "y": 4,
      "z": -3,
      "name": "Rock_Stone_Cyberverse_Brick"
    },
    {
      "x": -4,
      "y": 5,
      "z": -3,
      "name": "Rock_Cyberverse_Brick_Half"
    },
    {
      "x": -4,
      "y": 6,
      "z": -3,
      "name": "Empty"
    },
    {
      "x": -4,
      "y": 7,
      "z": -3,
      "name": "Empty"
    },
    {
      "x": -4,
      "y": -6,
      "z": -2,
      "name": "Rock_Stone_Cyberverse_Glitched"
    },
    {
      "x": -4,
      "y": -5,
      "z": -2,
      "name": "Rock_Stone_Cyberverse_Brick"
    },
    {
      "x": -4,
      "y": -4,
      "z": -2,
      "name": "Rock_Stone_Cyberverse_Brick"
    },
    {
      "x": -4,
      "y": -3,
      "z": -2,
      "name": "Rock_Stone_Cyberverse_Brick"
    },
    {
      "x": -4,
      "y": -2,
      "z": -2,
      "name": "Rock_Stone_Cyberverse_Brick"
    },
    {
      "x": -4,
      "y": -1,
      "z": -2,
      "name": "Rock_Stone_Cyberverse_Glitched"
    },
    {
      "x": -4,
      "y": 0,
      "z": -2,
      "name": "Rock_Stone_Cyberverse_Brick"
    },
    {
      "x": -4,
      "y": 1,
      "z": -2,
      "name": "Rock_Stone_Cyberverse_Brick"
    },
    {
      "x": -4,
      "y": 2,
      "z": -2,
      "name": "Rock_Stone_Cyberverse_Brick"
    },
    {
      "x": -4,
      "y": 3,
      "z": -2,
      "name": "Rock_Stone_Cyberverse_Brick"
    },
    {
      "x": -4,
      "y": 4,
      "z": -2,
      "name": "Rock_Stone_Cyberverse_Brick"
    },
    {
      "x": -4,
      "y": 5,
      "z": -2,
      "name": "Rock_Stone_Cyberverse_Brick"
    },
    {
      "x": -4,
      "y": 6,
      "z": -2,
      "name": "Empty"
    },
    {
      "x": -4,
      "y": 7,
      "z": -2,
      "name": "Empty"
    },
    {
      "x": -4,
      "y": -6,
      "z": -1,
      "name": "Rock_Stone_Cyberverse"
    },
    {
      "x": -4,
      "y": -5,
      "z": -1,
      "name": "Rock_Stone_Cyberverse_Brick"
    },
    {
      "x": -4,
      "y": -4,
      "z": -1,
      "name": "Rock_Stone_Cyberverse_Brick"
    },
    {
      "x": -4,
      "y": -3,
      "z": -1,
      "name": "Rock_Stone_Cyberverse_Brick"
    },
    {
      "x": -4,
      "y": -2,
      "z": -1,
      "name": "Rock_Stone_Cyberverse_Brick"
    },
    {
      "x": -4,
      "y": -1,
      "z": -1,
      "name": "Rock_Stone_Cyberverse_Brick"
    },
    {
      "x": -4,
      "y": 0,
      "z": -1,
      "name": "Rock_Stone_Cyberverse_Brick"
    },
    {
      "x": -4,
      "y": 1,
      "z": -1,
      "name": "Rock_Stone_Cyberverse_Brick"
    },
    {
      "x": -4,
      "y": 2,
      "z": -1,
      "name": "Rock_Stone_Cyberverse_Brick"
    },
    {
      "x": -4,
      "y": 3,
      "z": -1,
      "name": "Rock_Stone_Cyberverse_Brick"
    },
    {
      "x": -4,
      "y": 4,
      "z": -1,
      "name": "Rock_Stone_Cyberverse_Brick"
    },
    {
      "x": -4,
      "y": 5,
      "z": -1,
      "name": "Empty"
    },
    {
      "x": -4,
      "y": 6,
      "z": -1,
      "name": "Empty"
    },
    {
      "x": -4,
      "y": 7,
      "z": -1,
      "name": "Empty"
    },
    {
      "x": -4,
      "y": -6,
      "z": 0,
      "name": "Rock_Stone_Cyberverse"
    },
    {
      "x": -4,
      "y": -5,
      "z": 0,
      "name": "Rock_Stone_Cyberverse_Brick"
    },
    {
      "x": -4,
      "y": -4,
      "z": 0,
      "name": "Rock_Stone_Cyberverse_Brick"
    },
    {
      "x": -4,
      "y": -3,
      "z": 0,
      "name": "Rock_Stone_Cyberverse_Brick"
    },
    {
      "x": -4,
      "y": -2,
      "z": 0,
      "name": "Rock_Stone_Cyberverse_Brick"
    },
    {
      "x": -4,
      "y": -1,
      "z": 0,
      "name": "Rock_Stone_Cyberverse_Brick"
    },
    {
      "x": -4,
      "y": 0,
      "z": 0,
      "name": "Rock_Stone_Cyberverse_Brick"
    },
    {
      "x": -4,
      "y": 1,
      "z": 0,
      "name": "Rock_Stone_Cyberverse_Brick"
    },
    {
      "x": -4,
      "y": 2,
      "z": 0,
      "name": "Rock_Stone_Cyberverse_Brick"
    },
    {
      "x": -4,
      "y": 3,
      "z": 0,
      "name": "Rock_Stone_Cyberverse_Brick"
    },
    {
      "x": -4,
      "y": 4,
      "z": 0,
      "name": "Rock_Stone_Cyberverse_Brick"
    },
    {
      "x": -4,
      "y": 5,
      "z": 0,
      "name": "Empty"
    },
    {
      "x": -4,
      "y": 6,
      "z": 0,
      "name": "Empty"
    },
    {
      "x": -4,
      "y": 7,
      "z": 0,
      "name": "Empty"
    },
    {
      "x": -4,
      "y": -6,
      "z": 1,
      "name": "Rock_Stone_Cyberverse"
    },
    {
      "x": -4,
      "y": -5,
      "z": 1,
      "name": "Rock_Stone_Cyberverse_Brick"
    },
    {
      "x": -4,
      "y": -4,
      "z": 1,
      "name": "Rock_Stone_Cyberverse_Brick"
    },
    {
      "x": -4,
      "y": -3,
      "z": 1,
      "name": "Rock_Stone_Cyberverse_Brick"
    },
    {
      "x": -4,
      "y": -2,
      "z": 1,
      "name": "Rock_Stone_Cyberverse_Brick"
    },
    {
      "x": -4,
      "y": -1,
      "z": 1,
      "name": "Rock_Stone_Cyberverse_Brick"
    },
    {
      "x": -4,
      "y": 0,
      "z": 1,
      "name": "Rock_Stone_Cyberverse_Brick"
    },
    {
      "x": -4,
      "y": 1,
      "z": 1,
      "name": "Rock_Stone_Cyberverse_Brick"
    },
    {
      "x": -4,
      "y": 2,
      "z": 1,
      "name": "Rock_Stone_Cyberverse_Brick"
    },
    {
      "x": -4,
      "y": 3,
      "z": 1,
      "name": "Rock_Stone_Cyberverse_Brick"
    },
    {
      "x": -4,
      "y": 4,
      "z": 1,
      "name": "Rock_Stone_Cyberverse_Brick"
    },
    {
      "x": -4,
      "y": 5,
      "z": 1,
      "name": "Empty"
    },
    {
      "x": -4,
      "y": 6,
      "z": 1,
      "name": "Empty"
    },
    {
      "x": -4,
      "y": 7,
      "z": 1,
      "name": "Empty"
    },
    {
      "x": -4,
      "y": -6,
      "z": 2,
      "name": "Rock_Stone_Cyberverse"
    },
    {
      "x": -4,
      "y": -5,
      "z": 2,
      "name": "Rock_Stone_Cyberverse_Brick"
    },
    {
      "x": -4,
      "y": -4,
      "z": 2,
      "name": "Rock_Stone_Cyberverse_Brick"
    },
    {
      "x": -4,
      "y": -3,
      "z": 2,
      "name": "Rock_Stone_Cyberverse_Brick"
    },
    {
      "x": -4,
      "y": -2,
      "z": 2,
      "name": "Rock_Stone_Cyberverse_Brick"
    },
    {
      "x": -4,
      "y": -1,
      "z": 2,
      "name": "Rock_Stone_Cyberverse_Brick"
    },
    {
      "x": -4,
      "y": 0,
      "z": 2,
      "name": "Rock_Stone_Cyberverse_Brick"
    },
    {
      "x": -4,
      "y": 1,
      "z": 2,
      "name": "Rock_Stone_Cyberverse_Brick"
    },
    {
      "x": -4,
      "y": 2,
      "z": 2,
      "name": "Rock_Stone_Cyberverse_Brick"
    },
    {
      "x": -4,
      "y": 3,
      "z": 2,
      "name": "Rock_Stone_Cyberverse_Brick"
    },
    {
      "x": -4,
      "y": 4,
      "z": 2,
      "name": "Rock_Stone_Cyberverse_Brick"
    },
    {
      "x": -4,
      "y": 5,
      "z": 2,
      "name": "Empty"
    },
    {
      "x": -4,
      "y": 6,
      "z": 2,
      "name": "Empty"
    },
    {
      "x": -4,
      "y": 7,
      "z": 2,
      "name": "Empty"
    },
    {
      "x": -4,
      "y": -6,
      "z": 3,
      "name": "Rock_Stone_Cyberverse"
    },
    {
      "x": -4,
      "y": -5,
      "z": 3,
      "name": "Rock_Stone_Cyberverse"
    },
    {
      "x": -4,
      "y": -4,
      "z": 3,
      "name": "Rock_Stone_Cyberverse"
    },
    {
      "x": -4,
      "y": -3,
      "z": 3,
      "name": "Rock_Stone_Cyberverse_Glitched"
    },
    {
      "x": -4,
      "y": -2,
      "z": 3,
      "name": "Rock_Stone_Cyberverse"
    },
    {
      "x": -4,
      "y": -1,
      "z": 3,
      "name": "Rock_Stone_Cyberverse"
    },
    {
      "x": -4,
      "y": 0,
      "z": 3,
      "name": "Rock_Stone_Cyberverse_Brick"
    },
    {
      "x": -4,
      "y": 1,
      "z": 3,
      "name": "Rock_Stone_Cyberverse_Brick"
    },
    {
      "x": -4,
      "y": 2,
      "z": 3,
      "name": "Rock_Stone_Cyberverse_Brick"
    },
    {
      "x": -4,
      "y": 3,
      "z": 3,
      "name": "Rock_Stone_Cyberverse_Brick"
    },
    {
      "x": -4,
      "y": 4,
      "z": 3,
      "name": "Rock_Stone_Cyberverse_Brick"
    },
    {
      "x": -4,
      "y": 5,
      "z": 3,
      "name": "Rock_Cyberverse_Brick_Half"
    },
    {
      "x": -4,
      "y": 6,
      "z": 3,
      "name": "Empty"
    },
    {
      "x": -4,
      "y": 7,
      "z": 3,
      "name": "Empty"
    },
    {
      "x": -4,
      "y": -6,
      "z": 4,
      "name": "Rock_Stone_Cyberverse"
    },
    {
      "x": -4,
      "y": -5,
      "z": 4,
      "name": "Rock_Stone_Cyberverse_Glitched"
    },
    {
      "x": -4,
      "y": -4,
      "z": 4,
      "name": "Rock_Stone_Cyberverse"
    },
    {
      "x": -4,
      "y": -3,
      "z": 4,
      "name": "Rock_Stone_Cyberverse"
    },
    {
      "x": -4,
      "y": -2,
      "z": 4,
      "name": "Rock_Stone_Cyberverse"
    },
    {
      "x": -4,
      "y": -1,
      "z": 4,
      "name": "Rock_Stone_Cyberverse_Glitched"
    },
    {
      "x": -4,
      "y": 0,
      "z": 4,
      "name": "Rock_Stone_Cyberverse_Brick"
    },
    {
      "x": -4,
      "y": 1,
      "z": 4,
      "name": "Rock_Stone_Cyberverse_Brick"
    },
    {
      "x": -4,
      "y": 2,
      "z": 4,
      "name": "Rock_Stone_Cyberverse_Brick"
    },
    {
      "x": -4,
      "y": 3,
      "z": 4,
      "name": "Rock_Stone_Cyberverse_Brick"
    },
    {
      "x": -4,
      "y": 4,
      "z": 4,
      "name": "Rock_Stone_Cyberverse_Brick"
    },
    {
      "x": -4,
      "y": 5,
      "z": 4,
      "name": "Rock_Stone_Cyberverse_Brick"
    },
    {
      "x": -4,
      "y": 6,
      "z": 4,
      "name": "Plant_Wires_Glow",
      "support": 15,
      "rotation": 7
    },
    {
      "x": -4,
      "y": 7,
      "z": 4,
      "name": "Empty"
    },
    {
      "x": -3,
      "y": -6,
      "z": -3,
      "name": "Rock_Stone_Cyberverse"
    },
    {
      "x": -3,
      "y": -5,
      "z": -3,
      "name": "Rock_Stone_Cyberverse_Brick"
    },
    {
      "x": -3,
      "y": -4,
      "z": -3,
      "name": "Rock_Stone_Cyberverse_Brick"
    },
    {
      "x": -3,
      "y": -3,
      "z": -3,
      "name": "Rock_Stone_Cyberverse_Brick"
    },
    {
      "x": -3,
      "y": -2,
      "z": -3,
      "name": "Rock_Stone_Cyberverse_Brick"
    },
    {
      "x": -3,
      "y": -1,
      "z": -3,
      "name": "Rock_Stone_Cyberverse_Glitched"
    },
    {
      "x": -3,
      "y": 0,
      "z": -3,
      "name": "Rock_Stone_Cyberverse_Brick"
    },
    {
      "x": -3,
      "y": 1,
      "z": -3,
      "name": "Rock_Stone_Cyberverse_Brick"
    },
    {
      "x": -3,
      "y": 2,
      "z": -3,
      "name": "Rock_Stone_Cyberverse_Brick"
    },
    {
      "x": -3,
      "y": 3,
      "z": -3,
      "name": "Rock_Stone_Cyberverse_Brick"
    },
    {
      "x": -3,
      "y": 4,
      "z": -3,
      "name": "Rock_Stone_Cyberverse_Brick"
    },
    {
      "x": -3,
      "y": 5,
      "z": -3,
      "name": "Rock_Stone_Cyberverse_Brick"
    },
    {
      "x": -3,
      "y": 6,
      "z": -3,
      "name": "Empty"
    },
    {
      "x": -3,
      "y": 7,
      "z": -3,
      "name": "Empty"
    },
    {
      "x": -3,
      "y": -6,
      "z": -2,
      "name": "Rock_Stone_Cyberverse_Brick"
    },
    {
      "x": -3,
      "y": -5,
      "z": -2,
      "name": "Empty"
    },
    {
      "x": -3,
      "y": -4,
      "z": -2,
      "name": "Empty"
    },
    {
      "x": -3,
      "y": -3,
      "z": -2,
      "name": "Empty"
    },
    {
      "x": -3,
      "y": -2,
      "z": -2,
      "name": "Empty"
    },
    {
      "x": -3,
      "y": -1,
      "z": -2,
      "name": "Rock_Stone_Cyberverse_Brick"
    },
    {
      "x": -3,
      "y": 0,
      "z": -2,
      "name": "Empty"
    },
    {
      "x": -3,
      "y": 1,
      "z": -2,
      "name": "Empty"
    },
    {
      "x": -3,
      "y": 2,
      "z": -2,
      "name": "Empty"
    },
    {
      "x": -3,
      "y": 3,
      "z": -2,
      "name": "Empty"
    },
    {
      "x": -3,
      "y": 4,
      "z": -2,
      "name": "Rock_Stone_Cyberverse_Brick"
    },
    {
      "x": -3,
      "y": 5,
      "z": -2,
      "name": "File_Folder",
      "components": {
        "Components": {
          "PlacedByInteraction": {
            "WhoPlacedUuid": {
              "$binary": "MPHUpLOaS6efxfnko+aohw==",
              "$type": "04"
            }
          },
          "ItemContainerBlock": {
            "ItemContainer": {
              "Capacity": 9,
              "Items": {
                "0": {
                  "Id": "Spaghetti_Code",
                  "Quantity": 1,
                  "Durability": 0.0,
                  "MaxDurability": 0.0,
                  "OverrideDroppedItemAnimation": false
                },
                "3": {
                  "Id": "Spaghetti_Code",
                  "Quantity": 3,
                  "Durability": 0.0,
                  "MaxDurability": 0.0,
                  "OverrideDroppedItemAnimation": false
                },
                "8": {
                  "Id": "Ingredient_Bar_Iron",
                  "Quantity": 1,
                  "Durability": 0.0,
                  "MaxDurability": 0.0,
                  "OverrideDroppedItemAnimation": false
                },
                "7": {
                  "Id": "Ingredient_Bar_Iron",
                  "Quantity": 1,
                  "Durability": 0.0,
                  "MaxDurability": 0.0,
                  "OverrideDroppedItemAnimation": false
                },
                "6": {
                  "Id": "Ingredient_Bar_Iron",
                  "Quantity": 1,
                  "Durability": 0.0,
                  "MaxDurability": 0.0,
                  "OverrideDroppedItemAnimation": false
                }
              }
            },
            "Capacity": 9
          }
        }
      },
      "rotation": 3
    },
    {
      "x": -3,
      "y": 6,
      "z": -2,
      "name": "Empty"
    },
    {
      "x": -3,
      "y": 7,
      "z": -2,
      "name": "Empty"
    },
    {
      "x": -3,
      "y": -6,
      "z": -1,
      "name": "Rock_Stone_Cyberverse_Brick"
    },
    {
      "x": -3,
      "y": -5,
      "z": -1,
      "name": "Rock_Cyberberse_Brick_Stairs",
      "rotation": 2
    },
    {
      "x": -3,
      "y": -4,
      "z": -1,
      "name": "Empty"
    },
    {
      "x": -3,
      "y": -3,
      "z": -1,
      "name": "Empty"
    },
    {
      "x": -3,
      "y": -2,
      "z": -1,
      "name": "Empty"
    },
    {
      "x": -3,
      "y": -1,
      "z": -1,
      "name": "Empty"
    },
    {
      "x": -3,
      "y": 0,
      "z": -1,
      "name": "Rock_Cyberverse_Brick_Half",
      "rotation": 8
    },
    {
      "x": -3,
      "y": 1,
      "z": -1,
      "name": "Empty"
    },
    {
      "x": -3,
      "y": 2,
      "z": -1,
      "name": "Empty"
    },
    {
      "x": -3,
      "y": 3,
      "z": -1,
      "name": "Empty"
    },
    {
      "x": -3,
      "y": 4,
      "z": -1,
      "name": "Rock_Stone_Cyberverse_Brick"
    },
    {
      "x": -3,
      "y": 5,
      "z": -1,
      "name": "Rock_Stone_Cyberverse_Brick"
    },
    {
      "x": -3,
      "y": 6,
      "z": -1,
      "name": "Empty"
    },
    {
      "x": -3,
      "y": 7,
      "z": -1,
      "name": "Empty"
    },
    {
      "x": -3,
      "y": -6,
      "z": 0,
      "name": "Rock_Stone_Cyberverse_Brick"
    },
    {
      "x": -3,
      "y": -5,
      "z": 0,
      "name": "Rock_Stone_Cyberverse_Brick"
    },
    {
      "x": -3,
      "y": -4,
      "z": 0,
      "name": "Rock_Cyberberse_Brick_Stairs",
      "rotation": 2
    },
    {
      "x": -3,
      "y": -3,
      "z": 0,
      "name": "Empty"
    },
    {
      "x": -3,
      "y": -2,
      "z": 0,
      "name": "Empty"
    },
    {
      "x": -3,
      "y": -1,
      "z": 0,
      "name": "Empty"
    },
    {
      "x": -3,
      "y": 0,
      "z": 0,
      "name": "Empty"
    },
    {
      "x": -3,
      "y": 1,
      "z": 0,
      "name": "Rock_Cyberverse_Brick_Half",
      "rotation": 8
    },
    {
      "x": -3,
      "y": 2,
      "z": 0,
      "name": "Empty"
    },
    {
      "x": -3,
      "y": 3,
      "z": 0,
      "name": "Empty"
    },
    {
      "x": -3,
      "y": 4,
      "z": 0,
      "name": "Empty"
    },
    {
      "x": -3,
      "y": 5,
      "z": 0,
      "name": "Empty"
    },
    {
      "x": -3,
      "y": 6,
      "z": 0,
      "name": "Empty"
    },
    {
      "x": -3,
      "y": 7,
      "z": 0,
      "name": "Empty"
    },
    {
      "x": -3,
      "y": -6,
      "z": 1,
      "name": "Rock_Stone_Cyberverse_Brick"
    },
    {
      "x": -3,
      "y": -5,
      "z": 1,
      "name": "Rock_Stone_Cyberverse_Brick"
    },
    {
      "x": -3,
      "y": -4,
      "z": 1,
      "name": "Rock_Stone_Cyberverse_Brick"
    },
    {
      "x": -3,
      "y": -3,
      "z": 1,
      "name": "Rock_Cyberberse_Brick_Stairs",
      "rotation": 2
    },
    {
      "x": -3,
      "y": -2,
      "z": 1,
      "name": "Empty"
    },
    {
      "x": -3,
      "y": -1,
      "z": 1,
      "name": "Empty"
    },
    {
      "x": -3,
      "y": 0,
      "z": 1,
      "name": "Empty"
    },
    {
      "x": -3,
      "y": 1,
      "z": 1,
      "name": "Empty"
    },
    {
      "x": -3,
      "y": 2,
      "z": 1,
      "name": "Rock_Cyberverse_Brick_Half",
      "rotation": 8
    },
    {
      "x": -3,
      "y": 3,
      "z": 1,
      "name": "Empty"
    },
    {
      "x": -3,
      "y": 4,
      "z": 1,
      "name": "Empty"
    },
    {
      "x": -3,
      "y": 5,
      "z": 1,
      "name": "Empty"
    },
    {
      "x": -3,
      "y": 6,
      "z": 1,
      "name": "Empty"
    },
    {
      "x": -3,
      "y": 7,
      "z": 1,
      "name": "Empty"
    },
    {
      "x": -3,
      "y": -6,
      "z": 2,
      "name": "Rock_Stone_Cyberverse_Brick"
    },
    {
      "x": -3,
      "y": -5,
      "z": 2,
      "name": "Rock_Stone_Cyberverse_Brick"
    },
    {
      "x": -3,
      "y": -4,
      "z": 2,
      "name": "Rock_Stone_Cyberverse_Brick"
    },
    {
      "x": -3,
      "y": -3,
      "z": 2,
      "name": "Rock_Stone_Cyberverse_Brick"
    },
    {
      "x": -3,
      "y": -2,
      "z": 2,
      "name": "Rock_Cyberberse_Brick_Stairs",
      "rotation": 2
    },
    {
      "x": -3,
      "y": -1,
      "z": 2,
      "name": "Empty"
    },
    {
      "x": -3,
      "y": 0,
      "z": 2,
      "name": "Empty"
    },
    {
      "x": -3,
      "y": 1,
      "z": 2,
      "name": "Empty"
    },
    {
      "x": -3,
      "y": 2,
      "z": 2,
      "name": "Empty"
    },
    {
      "x": -3,
      "y": 3,
      "z": 2,
      "name": "Rock_Cyberverse_Brick_Half",
      "rotation": 8
    },
    {
      "x": -3,
      "y": 4,
      "z": 2,
      "name": "Empty"
    },
    {
      "x": -3,
      "y": 5,
      "z": 2,
      "name": "Empty"
    },
    {
      "x": -3,
      "y": 6,
      "z": 2,
      "name": "Empty"
    },
    {
      "x": -3,
      "y": 7,
      "z": 2,
      "name": "Empty"
    },
    {
      "x": -3,
      "y": -6,
      "z": 3,
      "name": "Rock_Stone_Cyberverse"
    },
    {
      "x": -3,
      "y": -5,
      "z": 3,
      "name": "Rock_Stone_Cyberverse_Brick"
    },
    {
      "x": -3,
      "y": -4,
      "z": 3,
      "name": "Rock_Stone_Cyberverse_Brick"
    },
    {
      "x": -3,
      "y": -3,
      "z": 3,
      "name": "Rock_Stone_Cyberverse_Brick"
    },
    {
      "x": -3,
      "y": -2,
      "z": 3,
      "name": "Rock_Stone_Cyberverse_Brick"
    },
    {
      "x": -3,
      "y": -1,
      "z": 3,
      "name": "Rock_Cyberberse_Brick_Stairs",
      "rotation": 2
    },
    {
      "x": -3,
      "y": 0,
      "z": 3,
      "name": "Empty"
    },
    {
      "x": -3,
      "y": 1,
      "z": 3,
      "name": "Empty"
    },
    {
      "x": -3,
      "y": 2,
      "z": 3,
      "name": "Empty"
    },
    {
      "x": -3,
      "y": 3,
      "z": 3,
      "name": "Empty"
    },
    {
      "x": -3,
      "y": 4,
      "z": 3,
      "name": "Rock_Stone_Cyberverse_Brick"
    },
    {
      "x": -3,
      "y": 5,
      "z": 3,
      "name": "Plant_Wires_Glow",
      "support": 15,
      "rotation": 6
    },
    {
      "x": -3,
      "y": 6,
      "z": 3,
      "name": "Plant_Wires_Glow",
      "support": 15,
      "rotation": 6
    },
    {
      "x": -3,
      "y": 7,
      "z": 3,
      "name": "Empty"
    },
    {
      "x": -3,
      "y": -6,
      "z": 4,
      "name": "Rock_Stone_Cyberverse"
    },
    {
      "x": -3,
      "y": -5,
      "z": 4,
      "name": "Rock_Stone_Cyberverse_Glitched"
    },
    {
      "x": -3,
      "y": -4,
      "z": 4,
      "name": "Rock_Stone_Cyberverse"
    },
    {
      "x": -3,
      "y": -3,
      "z": 4,
      "name": "Rock_Stone_Cyberverse"
    },
    {
      "x": -3,
      "y": -2,
      "z": 4,
      "name": "Rock_Stone_Cyberverse"
    },
    {
      "x": -3,
      "y": -1,
      "z": 4,
      "name": "Rock_Stone_Cyberverse"
    },
    {
      "x": -3,
      "y": 0,
      "z": 4,
      "name": "Rock_Stone_Cyberverse_Brick"
    },
    {
      "x": -3,
      "y": 1,
      "z": 4,
      "name": "Rock_Stone_Cyberverse_Brick"
    },
    {
      "x": -3,
      "y": 2,
      "z": 4,
      "name": "Rock_Stone_Cyberverse_Brick"
    },
    {
      "x": -3,
      "y": 3,
      "z": 4,
      "name": "Rock_Stone_Cyberverse_Brick"
    },
    {
      "x": -3,
      "y": 4,
      "z": 4,
      "name": "Rock_Stone_Cyberverse_Brick"
    },
    {
      "x": -3,
      "y": 5,
      "z": 4,
      "name": "Rock_Stone_Cyberverse_Brick"
    },
    {
      "x": -3,
      "y": 6,
      "z": 4,
      "name": "Rock_Stone_Cyberverse_Brick"
    },
    {
      "x": -3,
      "y": 7,
      "z": 4,
      "name": "Plant_Wires_Glow",
      "support": 15
    },
    {
      "x": -2,
      "y": -6,
      "z": -3,
      "name": "Rock_Stone_Cyberverse"
    },
    {
      "x": -2,
      "y": -5,
      "z": -3,
      "name": "Rock_Stone_Cyberverse_Brick"
    },
    {
      "x": -2,
      "y": -4,
      "z": -3,
      "name": "Rock_Stone_Cyberverse_Brick"
    },
    {
      "x": -2,
      "y": -3,
      "z": -3,
      "name": "Rock_Stone_Cyberverse_Brick"
    },
    {
      "x": -2,
      "y": -2,
      "z": -3,
      "name": "Rock_Stone_Cyberverse_Brick"
    },
    {
      "x": -2,
      "y": -1,
      "z": -3,
      "name": "Rock_Stone_Cyberverse_Glitched"
    },
    {
      "x": -2,
      "y": 0,
      "z": -3,
      "name": "Rock_Cyberverse_Brick_Half",
      "rotation": 5
    },
    {
      "x": -2,
      "y": 1,
      "z": -3,
      "name": "Rock_Cyberverse_Brick_Half",
      "rotation": 5
    },
    {
      "x": -2,
      "y": 2,
      "z": -3,
      "name": "Rock_Cyberberse_Brick_Stairs",
      "rotation": 11
    },
    {
      "x": -2,
      "y": 3,
      "z": -3,
      "name": "Rock_Stone_Cyberverse_Brick"
    },
    {
      "x": -2,
      "y": 4,
      "z": -3,
      "name": "Rock_Stone_Cyberverse_Brick"
    },
    {
      "x": -2,
      "y": 5,
      "z": -3,
      "name": "Empty"
    },
    {
      "x": -2,
      "y": 6,
      "z": -3,
      "name": "Empty"
    },
    {
      "x": -2,
      "y": 7,
      "z": -3,
      "name": "Empty"
    },
    {
      "x": -2,
      "y": -6,
      "z": -2,
      "name": "Rock_Stone_Cyberverse_Brick"
    },
    {
      "x": -2,
      "y": -5,
      "z": -2,
      "name": "Empty"
    },
    {
      "x": -2,
      "y": -4,
      "z": -2,
      "name": "Empty"
    },
    {
      "x": -2,
      "y": -3,
      "z": -2,
      "name": "Empty"
    },
    {
      "x": -2,
      "y": -2,
      "z": -2,
      "name": "Empty"
    },
    {
      "x": -2,
      "y": -1,
      "z": -2,
      "name": "Rock_Stone_Cyberverse_Brick"
    },
    {
      "x": -2,
      "y": 0,
      "z": -2,
      "name": "Empty"
    },
    {
      "x": -2,
      "y": 1,
      "z": -2,
      "name": "Empty"
    },
    {
      "x": -2,
      "y": 2,
      "z": -2,
      "name": "Empty"
    },
    {
      "x": -2,
      "y": 3,
      "z": -2,
      "name": "Empty"
    },
    {
      "x": -2,
      "y": 4,
      "z": -2,
      "name": "Rock_Stone_Cyberverse_Brick"
    },
    {
      "x": -2,
      "y": 5,
      "z": -2,
      "name": "Empty"
    },
    {
      "x": -2,
      "y": 6,
      "z": -2,
      "name": "Empty"
    },
    {
      "x": -2,
      "y": 7,
      "z": -2,
      "name": "Empty"
    },
    {
      "x": -2,
      "y": -6,
      "z": -1,
      "name": "Rock_Stone_Cyberverse_Brick"
    },
    {
      "x": -2,
      "y": -5,
      "z": -1,
      "name": "Empty"
    },
    {
      "x": -2,
      "y": -4,
      "z": -1,
      "name": "Empty"
    },
    {
      "x": -2,
      "y": -3,
      "z": -1,
      "name": "Empty"
    },
    {
      "x": -2,
      "y": -2,
      "z": -1,
      "name": "Empty"
    },
    {
      "x": -2,
      "y": -1,
      "z": -1,
      "name": "Rock_Stone_Cyberverse_Brick"
    },
    {
      "x": -2,
      "y": 0,
      "z": -1,
      "name": "Empty"
    },
    {
      "x": -2,
      "y": 1,
      "z": -1,
      "name": "Empty"
    },
    {
      "x": -2,
      "y": 2,
      "z": -1,
      "name": "Empty"
    },
    {
      "x": -2,
      "y": 3,
      "z": -1,
      "name": "Empty"
    },
    {
      "x": -2,
      "y": 4,
      "z": -1,
      "name": "Rock_Stone_Cyberverse_Brick"
    },
    {
      "x": -2,
      "y": 5,
      "z": -1,
      "name": "Empty"
    },
    {
      "x": -2,
      "y": 6,
      "z": -1,
      "name": "Empty"
    },
    {
      "x": -2,
      "y": 7,
      "z": -1,
      "name": "Empty"
    },
    {
      "x": -2,
      "y": -6,
      "z": 0,
      "name": "Rock_Stone_Cyberverse_Brick"
    },
    {
      "x": -2,
      "y": -5,
      "z": 0,
      "name": "Empty"
    },
    {
      "x": -2,
      "y": -4,
      "z": 0,
      "name": "Empty"
    },
    {
      "x": -2,
      "y": -3,
      "z": 0,
      "name": "Empty"
    },
    {
      "x": -2,
      "y": -2,
      "z": 0,
      "name": "Empty"
    },
    {
      "x": -2,
      "y": -1,
      "z": 0,
      "name": "Rock_Stone_Cyberverse_Brick"
    },
    {
      "x": -2,
      "y": 0,
      "z": 0,
      "name": "Empty"
    },
    {
      "x": -2,
      "y": 1,
      "z": 0,
      "name": "Empty"
    },
    {
      "x": -2,
      "y": 2,
      "z": 0,
      "name": "Empty"
    },
    {
      "x": -2,
      "y": 3,
      "z": 0,
      "name": "Empty"
    },
    {
      "x": -2,
      "y": 4,
      "z": 0,
      "name": "Rock_Stone_Cyberverse_Brick"
    },
    {
      "x": -2,
      "y": 5,
      "z": 0,
      "name": "Empty"
    },
    {
      "x": -2,
      "y": 6,
      "z": 0,
      "name": "Empty"
    },
    {
      "x": -2,
      "y": 7,
      "z": 0,
      "name": "Empty"
    },
    {
      "x": -2,
      "y": -6,
      "z": 1,
      "name": "Rock_Stone_Cyberverse_Brick"
    },
    {
      "x": -2,
      "y": -5,
      "z": 1,
      "name": "Empty"
    },
    {
      "x": -2,
      "y": -4,
      "z": 1,
      "name": "Empty"
    },
    {
      "x": -2,
      "y": -3,
      "z": 1,
      "name": "Empty"
    },
    {
      "x": -2,
      "y": -2,
      "z": 1,
      "name": "Empty"
    },
    {
      "x": -2,
      "y": -1,
      "z": 1,
      "name": "Rock_Stone_Cyberverse_Brick"
    },
    {
      "x": -2,
      "y": 0,
      "z": 1,
      "name": "Empty"
    },
    {
      "x": -2,
      "y": 1,
      "z": 1,
      "name": "Empty"
    },
    {
      "x": -2,
      "y": 2,
      "z": 1,
      "name": "Empty"
    },
    {
      "x": -2,
      "y": 3,
      "z": 1,
      "name": "Empty"
    },
    {
      "x": -2,
      "y": 4,
      "z": 1,
      "name": "Rock_Stone_Cyberverse_Brick"
    },
    {
      "x": -2,
      "y": 5,
      "z": 1,
      "name": "Empty"
    },
    {
      "x": -2,
      "y": 6,
      "z": 1,
      "name": "Empty"
    },
    {
      "x": -2,
      "y": 7,
      "z": 1,
      "name": "Empty"
    },
    {
      "x": -2,
      "y": -6,
      "z": 2,
      "name": "Rock_Stone_Cyberverse_Brick"
    },
    {
      "x": -2,
      "y": -5,
      "z": 2,
      "name": "File_Folder",
      "components": {
        "Components": {
          "PlacedByInteraction": {
            "WhoPlacedUuid": {
              "$binary": "MPHUpLOaS6efxfnko+aohw==",
              "$type": "04"
            }
          },
          "ItemContainerBlock": {
            "ItemContainer": {
              "Capacity": 9,
              "Items": {
                "7": {
                  "Id": "Spaghetti_Code",
                  "Quantity": 5,
                  "Durability": 0.0,
                  "MaxDurability": 0.0,
                  "OverrideDroppedItemAnimation": false
                },
                "5": {
                  "Id": "Spaghetti_Code",
                  "Quantity": 3,
                  "Durability": 0.0,
                  "MaxDurability": 0.0,
                  "OverrideDroppedItemAnimation": false
                }
              }
            },
            "Capacity": 9
          }
        }
      }
    },
    {
      "x": -2,
      "y": -4,
      "z": 2,
      "name": "Empty"
    },
    {
      "x": -2,
      "y": -3,
      "z": 2,
      "name": "Empty"
    },
    {
      "x": -2,
      "y": -2,
      "z": 2,
      "name": "Empty"
    },
    {
      "x": -2,
      "y": -1,
      "z": 2,
      "name": "Rock_Stone_Cyberverse_Brick"
    },
    {
      "x": -2,
      "y": 0,
      "z": 2,
      "name": "Empty"
    },
    {
      "x": -2,
      "y": 1,
      "z": 2,
      "name": "Empty"
    },
    {
      "x": -2,
      "y": 2,
      "z": 2,
      "name": "Empty"
    },
    {
      "x": -2,
      "y": 3,
      "z": 2,
      "name": "Empty"
    },
    {
      "x": -2,
      "y": 4,
      "z": 2,
      "name": "Rock_Stone_Cyberverse_Brick"
    },
    {
      "x": -2,
      "y": 5,
      "z": 2,
      "name": "Empty"
    },
    {
      "x": -2,
      "y": 6,
      "z": 2,
      "name": "Empty"
    },
    {
      "x": -2,
      "y": 7,
      "z": 2,
      "name": "Empty"
    },
    {
      "x": -2,
      "y": -6,
      "z": 3,
      "name": "Rock_Stone_Cyberverse_Glitched"
    },
    {
      "x": -2,
      "y": -5,
      "z": 3,
      "name": "Rock_Stone_Cyberverse_Brick"
    },
    {
      "x": -2,
      "y": -4,
      "z": 3,
      "name": "Rock_Stone_Cyberverse_Brick"
    },
    {
      "x": -2,
      "y": -3,
      "z": 3,
      "name": "Rock_Stone_Cyberverse_Brick"
    },
    {
      "x": -2,
      "y": -2,
      "z": 3,
      "name": "Rock_Stone_Cyberverse_Brick"
    },
    {
      "x": -2,
      "y": -1,
      "z": 3,
      "name": "Rock_Stone_Cyberverse_Brick"
    },
    {
      "x": -2,
      "y": 0,
      "z": 3,
      "name": "Empty"
    },
    {
      "x": -2,
      "y": 1,
      "z": 3,
      "name": "Empty"
    },
    {
      "x": -2,
      "y": 2,
      "z": 3,
      "name": "Empty"
    },
    {
      "x": -2,
      "y": 3,
      "z": 3,
      "name": "Empty"
    },
    {
      "x": -2,
      "y": 4,
      "z": 3,
      "name": "Rock_Stone_Cyberverse_Brick"
    },
    {
      "x": -2,
      "y": 5,
      "z": 3,
      "name": "Plant_Wires_Glow",
      "support": 15,
      "rotation": 6
    },
    {
      "x": -2,
      "y": 6,
      "z": 3,
      "name": "Plant_Wires_Glow",
      "support": 15,
      "rotation": 6
    },
    {
      "x": -2,
      "y": 7,
      "z": 3,
      "name": "Empty"
    },
    {
      "x": -2,
      "y": -6,
      "z": 4,
      "name": "Rock_Stone_Cyberverse"
    },
    {
      "x": -2,
      "y": -5,
      "z": 4,
      "name": "Rock_Stone_Cyberverse"
    },
    {
      "x": -2,
      "y": -4,
      "z": 4,
      "name": "Rock_Stone_Cyberverse"
    },
    {
      "x": -2,
      "y": -3,
      "z": 4,
      "name": "Rock_Stone_Cyberverse"
    },
    {
      "x": -2,
      "y": -2,
      "z": 4,
      "name": "Rock_Stone_Cyberverse"
    },
    {
      "x": -2,
      "y": -1,
      "z": 4,
      "name": "Rock_Stone_Cyberverse"
    },
    {
      "x": -2,
      "y": 0,
      "z": 4,
      "name": "Rock_Stone_Cyberverse_Brick"
    },
    {
      "x": -2,
      "y": 1,
      "z": 4,
      "name": "Rock_Stone_Cyberverse_Brick"
    },
    {
      "x": -2,
      "y": 2,
      "z": 4,
      "name": "Rock_Stone_Cyberverse_Brick"
    },
    {
      "x": -2,
      "y": 3,
      "z": 4,
      "name": "Rock_Stone_Cyberverse_Brick"
    },
    {
      "x": -2,
      "y": 4,
      "z": 4,
      "name": "Rock_Stone_Cyberverse_Brick"
    },
    {
      "x": -2,
      "y": 5,
      "z": 4,
      "name": "Rock_Stone_Cyberverse_Brick"
    },
    {
      "x": -2,
      "y": 6,
      "z": 4,
      "name": "Rock_Stone_Cyberverse_Brick"
    },
    {
      "x": -2,
      "y": 7,
      "z": 4,
      "name": "Plant_Wires_Glow",
      "support": 15
    },
    {
      "x": -1,
      "y": -6,
      "z": -3,
      "name": "Rock_Stone_Cyberverse"
    },
    {
      "x": -1,
      "y": -5,
      "z": -3,
      "name": "Rock_Stone_Cyberverse_Brick"
    },
    {
      "x": -1,
      "y": -4,
      "z": -3,
      "name": "Rock_Stone_Cyberverse_Brick"
    },
    {
      "x": -1,
      "y": -3,
      "z": -3,
      "name": "Rock_Stone_Cyberverse_Brick"
    },
    {
      "x": -1,
      "y": -2,
      "z": -3,
      "name": "Rock_Stone_Cyberverse_Brick"
    },
    {
      "x": -1,
      "y": -1,
      "z": -3,
      "name": "Rock_Stone_Cyberverse_Brick"
    },
    {
      "x": -1,
      "y": 0,
      "z": -3,
      "name": "Empty"
    },
    {
      "x": -1,
      "y": 1,
      "z": -3,
      "name": "Empty"
    },
    {
      "x": -1,
      "y": 2,
      "z": -3,
      "name": "Rock_Cyberverse_Brick_Half",
      "rotation": 8
    },
    {
      "x": -1,
      "y": 3,
      "z": -3,
      "name": "Rock_Stone_Cyberverse_Brick"
    },
    {
      "x": -1,
      "y": 4,
      "z": -3,
      "name": "Rock_Stone_Cyberverse_Brick"
    },
    {
      "x": -1,
      "y": 5,
      "z": -3,
      "name": "Empty"
    },
    {
      "x": -1,
      "y": 6,
      "z": -3,
      "name": "Empty"
    },
    {
      "x": -1,
      "y": 7,
      "z": -3,
      "name": "Empty"
    },
    {
      "x": -1,
      "y": -6,
      "z": -2,
      "name": "Rock_Stone_Cyberverse_Brick"
    },
    {
      "x": -1,
      "y": -5,
      "z": -2,
      "name": "Empty"
    },
    {
      "x": -1,
      "y": -4,
      "z": -2,
      "name": "Empty"
    },
    {
      "x": -1,
      "y": -3,
      "z": -2,
      "name": "Empty"
    },
    {
      "x": -1,
      "y": -2,
      "z": -2,
      "name": "Empty"
    },
    {
      "x": -1,
      "y": -1,
      "z": -2,
      "name": "Rock_Stone_Cyberverse_Brick"
    },
    {
      "x": -1,
      "y": 0,
      "z": -2,
      "name": "Empty"
    },
    {
      "x": -1,
      "y": 1,
      "z": -2,
      "name": "Empty"
    },
    {
      "x": -1,
      "y": 2,
      "z": -2,
      "name": "Empty"
    },
    {
      "x": -1,
      "y": 3,
      "z": -2,
      "name": "Empty"
    },
    {
      "x": -1,
      "y": 4,
      "z": -2,
      "name": "Rock_Stone_Cyberverse_Brick"
    },
    {
      "x": -1,
      "y": 5,
      "z": -2,
      "name": "Empty"
    },
    {
      "x": -1,
      "y": 6,
      "z": -2,
      "name": "Empty"
    },
    {
      "x": -1,
      "y": 7,
      "z": -2,
      "name": "Empty"
    },
    {
      "x": -1,
      "y": -6,
      "z": -1,
      "name": "Rock_Stone_Cyberverse_Brick"
    },
    {
      "x": -1,
      "y": -5,
      "z": -1,
      "name": "Empty"
    },
    {
      "x": -1,
      "y": -4,
      "z": -1,
      "name": "Empty"
    },
    {
      "x": -1,
      "y": -3,
      "z": -1,
      "name": "Plant_Wires_Glow",
      "support": 15,
      "rotation": 7
    },
    {
      "x": -1,
      "y": -2,
      "z": -1,
      "name": "Empty"
    },
    {
      "x": -1,
      "y": -1,
      "z": -1,
      "name": "Rock_Stone_Cyberverse_Brick"
    },
    {
      "x": -1,
      "y": 0,
      "z": -1,
      "name": "Empty"
    },
    {
      "x": -1,
      "y": 1,
      "z": -1,
      "name": "Empty"
    },
    {
      "x": -1,
      "y": 2,
      "z": -1,
      "name": "Empty"
    },
    {
      "x": -1,
      "y": 3,
      "z": -1,
      "name": "Empty"
    },
    {
      "x": -1,
      "y": 4,
      "z": -1,
      "name": "Rock_Stone_Cyberverse_Brick"
    },
    {
      "x": -1,
      "y": 5,
      "z": -1,
      "name": "Empty"
    },
    {
      "x": -1,
      "y": 6,
      "z": -1,
      "name": "Empty"
    },
    {
      "x": -1,
      "y": 7,
      "z": -1,
      "name": "Empty"
    },
    {
      "x": -1,
      "y": -6,
      "z": 0,
      "name": "Rock_Stone_Cyberverse_Brick"
    },
    {
      "x": -1,
      "y": -5,
      "z": 0,
      "name": "Empty"
    },
    {
      "x": -1,
      "y": -4,
      "z": 0,
      "name": "Empty"
    },
    {
      "x": -1,
      "y": -3,
      "z": 0,
      "name": "Empty"
    },
    {
      "x": -1,
      "y": -2,
      "z": 0,
      "name": "Empty"
    },
    {
      "x": -1,
      "y": -1,
      "z": 0,
      "name": "Rock_Stone_Cyberverse_Brick"
    },
    {
      "x": -1,
      "y": 0,
      "z": 0,
      "name": "Empty"
    },
    {
      "x": -1,
      "y": 1,
      "z": 0,
      "name": "Empty"
    },
    {
      "x": -1,
      "y": 2,
      "z": 0,
      "name": "Empty"
    },
    {
      "x": -1,
      "y": 3,
      "z": 0,
      "name": "Empty"
    },
    {
      "x": -1,
      "y": 4,
      "z": 0,
      "name": "Rock_Stone_Cyberverse_Brick"
    },
    {
      "x": -1,
      "y": 5,
      "z": 0,
      "name": "Empty"
    },
    {
      "x": -1,
      "y": 6,
      "z": 0,
      "name": "Empty"
    },
    {
      "x": -1,
      "y": 7,
      "z": 0,
      "name": "Empty"
    },
    {
      "x": -1,
      "y": -6,
      "z": 1,
      "name": "Rock_Stone_Cyberverse_Brick"
    },
    {
      "x": -1,
      "y": -5,
      "z": 1,
      "name": "Plant_Wires_Glow",
      "support": 15,
      "rotation": 7
    },
    {
      "x": -1,
      "y": -4,
      "z": 1,
      "name": "Empty"
    },
    {
      "x": -1,
      "y": -3,
      "z": 1,
      "name": "Empty"
    },
    {
      "x": -1,
      "y": -2,
      "z": 1,
      "name": "Empty"
    },
    {
      "x": -1,
      "y": -1,
      "z": 1,
      "name": "Rock_Stone_Cyberverse_Brick"
    },
    {
      "x": -1,
      "y": 0,
      "z": 1,
      "name": "Empty"
    },
    {
      "x": -1,
      "y": 1,
      "z": 1,
      "name": "Empty"
    },
    {
      "x": -1,
      "y": 2,
      "z": 1,
      "name": "Empty"
    },
    {
      "x": -1,
      "y": 3,
      "z": 1,
      "name": "Empty"
    },
    {
      "x": -1,
      "y": 4,
      "z": 1,
      "name": "Rock_Stone_Cyberverse_Brick"
    },
    {
      "x": -1,
      "y": 5,
      "z": 1,
      "name": "Empty"
    },
    {
      "x": -1,
      "y": 6,
      "z": 1,
      "name": "Empty"
    },
    {
      "x": -1,
      "y": 7,
      "z": 1,
      "name": "Empty"
    },
    {
      "x": -1,
      "y": -6,
      "z": 2,
      "name": "Rock_Stone_Cyberverse_Brick"
    },
    {
      "x": -1,
      "y": -5,
      "z": 2,
      "name": "Empty"
    },
    {
      "x": -1,
      "y": -4,
      "z": 2,
      "name": "Empty"
    },
    {
      "x": -1,
      "y": -3,
      "z": 2,
      "name": "Empty"
    },
    {
      "x": -1,
      "y": -2,
      "z": 2,
      "name": "Empty"
    },
    {
      "x": -1,
      "y": -1,
      "z": 2,
      "name": "Rock_Stone_Cyberverse_Brick"
    },
    {
      "x": -1,
      "y": 0,
      "z": 2,
      "name": "Empty"
    },
    {
      "x": -1,
      "y": 1,
      "z": 2,
      "name": "Empty"
    },
    {
      "x": -1,
      "y": 2,
      "z": 2,
      "name": "Empty"
    },
    {
      "x": -1,
      "y": 3,
      "z": 2,
      "name": "Empty"
    },
    {
      "x": -1,
      "y": 4,
      "z": 2,
      "name": "Rock_Stone_Cyberverse_Brick"
    },
    {
      "x": -1,
      "y": 5,
      "z": 2,
      "name": "Empty"
    },
    {
      "x": -1,
      "y": 6,
      "z": 2,
      "name": "Empty"
    },
    {
      "x": -1,
      "y": 7,
      "z": 2,
      "name": "Empty"
    },
    {
      "x": -1,
      "y": -6,
      "z": 3,
      "name": "Rock_Stone_Cyberverse_Glitched"
    },
    {
      "x": -1,
      "y": -5,
      "z": 3,
      "name": "Rock_Stone_Cyberverse_Brick"
    },
    {
      "x": -1,
      "y": -4,
      "z": 3,
      "name": "Rock_Stone_Cyberverse_Brick"
    },
    {
      "x": -1,
      "y": -3,
      "z": 3,
      "name": "Rock_Stone_Cyberverse_Brick"
    },
    {
      "x": -1,
      "y": -2,
      "z": 3,
      "name": "Rock_Stone_Cyberverse_Brick"
    },
    {
      "x": -1,
      "y": -1,
      "z": 3,
      "name": "Rock_Stone_Cyberverse_Brick"
    },
    {
      "x": -1,
      "y": 0,
      "z": 3,
      "name": "Plant_Wires_Glow",
      "support": 15
    },
    {
      "x": -1,
      "y": 1,
      "z": 3,
      "name": "Empty"
    },
    {
      "x": -1,
      "y": 2,
      "z": 3,
      "name": "Empty"
    },
    {
      "x": -1,
      "y": 3,
      "z": 3,
      "name": "Empty"
    },
    {
      "x": -1,
      "y": 4,
      "z": 3,
      "name": "Rock_Stone_Cyberverse_Brick"
    },
    {
      "x": -1,
      "y": 5,
      "z": 3,
      "name": "Empty"
    },
    {
      "x": -1,
      "y": 6,
      "z": 3,
      "name": "Empty"
    },
    {
      "x": -1,
      "y": 7,
      "z": 3,
      "name": "Empty"
    },
    {
      "x": -1,
      "y": -6,
      "z": 4,
      "name": "Rock_Stone_Cyberverse"
    },
    {
      "x": -1,
      "y": -5,
      "z": 4,
      "name": "Rock_Stone_Cyberverse_Glitched"
    },
    {
      "x": -1,
      "y": -4,
      "z": 4,
      "name": "Rock_Stone_Cyberverse"
    },
    {
      "x": -1,
      "y": -3,
      "z": 4,
      "name": "Rock_Stone_Cyberverse"
    },
    {
      "x": -1,
      "y": -2,
      "z": 4,
      "name": "Rock_Stone_Cyberverse"
    },
    {
      "x": -1,
      "y": -1,
      "z": 4,
      "name": "Rock_Stone_Cyberverse_Glitched"
    },
    {
      "x": -1,
      "y": 0,
      "z": 4,
      "name": "Rock_Stone_Cyberverse_Brick"
    },
    {
      "x": -1,
      "y": 1,
      "z": 4,
      "name": "Rock_Stone_Cyberverse_Brick"
    },
    {
      "x": -1,
      "y": 2,
      "z": 4,
      "name": "Rock_Stone_Cyberverse_Brick"
    },
    {
      "x": -1,
      "y": 3,
      "z": 4,
      "name": "Rock_Stone_Cyberverse_Brick"
    },
    {
      "x": -1,
      "y": 4,
      "z": 4,
      "name": "Rock_Stone_Cyberverse_Brick"
    },
    {
      "x": -1,
      "y": 5,
      "z": 4,
      "name": "Rock_Stone_Cyberverse_Brick"
    },
    {
      "x": -1,
      "y": 6,
      "z": 4,
      "name": "Rock_Cyberverse_Brick_Half"
    },
    {
      "x": -1,
      "y": 7,
      "z": 4,
      "name": "Empty"
    },
    {
      "x": 0,
      "y": -6,
      "z": -3,
      "name": "Rock_Stone_Cyberverse_Glitched"
    },
    {
      "x": 0,
      "y": -5,
      "z": -3,
      "name": "Rock_Stone_Cyberverse_Brick"
    },
    {
      "x": 0,
      "y": -4,
      "z": -3,
      "name": "Rock_Stone_Cyberverse_Brick"
    },
    {
      "x": 0,
      "y": -3,
      "z": -3,
      "name": "Rock_Stone_Cyberverse_Brick"
    },
    {
      "x": 0,
      "y": -2,
      "z": -3,
      "name": "Rock_Stone_Cyberverse_Brick"
    },
    {
      "x": 0,
      "y": -1,
      "z": -3,
      "name": "Rock_Stone_Cyberverse"
    },
    {
      "x": 0,
      "y": 0,
      "z": -3,
      "name": "Rock_Cyberverse_Brick_Half",
      "rotation": 7
    },
    {
      "x": 0,
      "y": 1,
      "z": -3,
      "name": "Rock_Cyberverse_Brick_Half",
      "rotation": 7
    },
    {
      "x": 0,
      "y": 2,
      "z": -3,
      "name": "Rock_Cyberberse_Brick_Stairs",
      "rotation": 9
    },
    {
      "x": 0,
      "y": 3,
      "z": -3,
      "name": "Rock_Stone_Cyberverse_Brick"
    },
    {
      "x": 0,
      "y": 4,
      "z": -3,
      "name": "Rock_Stone_Cyberverse_Brick"
    },
    {
      "x": 0,
      "y": 5,
      "z": -3,
      "name": "Rock_Cyberverse_Brick_Half"
    },
    {
      "x": 0,
      "y": 6,
      "z": -3,
      "name": "Empty"
    },
    {
      "x": 0,
      "y": 7,
      "z": -3,
      "name": "Empty"
    },
    {
      "x": 0,
      "y": -6,
      "z": -2,
      "name": "Rock_Stone_Cyberverse_Brick"
    },
    {
      "x": 0,
      "y": -5,
      "z": -2,
      "name": "Empty"
    },
    {
      "x": 0,
      "y": -4,
      "z": -2,
      "name": "Empty"
    },
    {
      "x": 0,
      "y": -3,
      "z": -2,
      "name": "Plant_Wires_Glow",
      "support": 15,
      "rotation": 6
    },
    {
      "x": 0,
      "y": -2,
      "z": -2,
      "name": "Empty"
    },
    {
      "x": 0,
      "y": -1,
      "z": -2,
      "name": "Rock_Stone_Cyberverse_Brick"
    },
    {
      "x": 0,
      "y": 0,
      "z": -2,
      "name": "Empty"
    },
    {
      "x": 0,
      "y": 1,
      "z": -2,
      "name": "Empty"
    },
    {
      "x": 0,
      "y": 2,
      "z": -2,
      "name": "Empty"
    },
    {
      "x": 0,
      "y": 3,
      "z": -2,
      "name": "Empty"
    },
    {
      "x": 0,
      "y": 4,
      "z": -2,
      "name": "Rock_Stone_Cyberverse_Brick"
    },
    {
      "x": 0,
      "y": 5,
      "z": -2,
      "name": "Empty"
    },
    {
      "x": 0,
      "y": 6,
      "z": -2,
      "name": "Empty"
    },
    {
      "x": 0,
      "y": 7,
      "z": -2,
      "name": "Empty"
    },
    {
      "x": 0,
      "y": -6,
      "z": -1,
      "name": "Rock_Stone_Cyberverse_Brick"
    },
    {
      "x": 0,
      "y": -5,
      "z": -1,
      "name": "Computer_Casing_Glow"
    },
    {
      "x": 0,
      "y": -4,
      "z": -1,
      "name": "Computer_Casing_Glow"
    },
    {
      "x": 0,
      "y": -3,
      "z": -1,
      "name": "Computer_Casing_Glow"
    },
    {
      "x": 0,
      "y": -2,
      "z": -1,
      "name": "Plant_Wires_Glow",
      "support": 15
    },
    {
      "x": 0,
      "y": -1,
      "z": -1,
      "name": "Rock_Stone_Cyberverse_Brick"
    },
    {
      "x": 0,
      "y": 0,
      "z": -1,
      "name": "Empty"
    },
    {
      "x": 0,
      "y": 1,
      "z": -1,
      "name": "Empty"
    },
    {
      "x": 0,
      "y": 2,
      "z": -1,
      "name": "Empty"
    },
    {
      "x": 0,
      "y": 3,
      "z": -1,
      "name": "Empty"
    },
    {
      "x": 0,
      "y": 4,
      "z": -1,
      "name": "Rock_Stone_Cyberverse_Brick"
    },
    {
      "x": 0,
      "y": 5,
      "z": -1,
      "name": "Empty"
    },
    {
      "x": 0,
      "y": 6,
      "z": -1,
      "name": "Empty"
    },
    {
      "x": 0,
      "y": 7,
      "z": -1,
      "name": "Empty"
    },
    {
      "x": 0,
      "y": -6,
      "z": 0,
      "name": "Rock_Stone_Cyberverse_Brick"
    },
    {
      "x": 0,
      "y": -5,
      "z": 0,
      "name": "Computer_Casing_Glow"
    },
    {
      "x": 0,
      "y": -4,
      "z": 0,
      "name": "Computer_Casing_Glow"
    },
    {
      "x": 0,
      "y": -3,
      "z": 0,
      "name": "Computer_Casing_Glow"
    },
    {
      "x": 0,
      "y": -2,
      "z": 0,
      "name": "Plant_Wires_Glow",
      "support": 15
    },
    {
      "x": 0,
      "y": -1,
      "z": 0,
      "name": "Rock_Stone_Cyberverse_Brick"
    },
    {
      "x": 0,
      "y": 0,
      "z": 0,
      "name": "Empty"
    },
    {
      "x": 0,
      "y": 1,
      "z": 0,
      "name": "Empty"
    },
    {
      "x": 0,
      "y": 2,
      "z": 0,
      "name": "Empty"
    },
    {
      "x": 0,
      "y": 3,
      "z": 0,
      "name": "Empty"
    },
    {
      "x": 0,
      "y": 4,
      "z": 0,
      "name": "Rock_Stone_Cyberverse_Brick"
    },
    {
      "x": 0,
      "y": 5,
      "z": 0,
      "name": "Empty"
    },
    {
      "x": 0,
      "y": 6,
      "z": 0,
      "name": "Empty"
    },
    {
      "x": 0,
      "y": 7,
      "z": 0,
      "name": "Empty"
    },
    {
      "x": 0,
      "y": -6,
      "z": 1,
      "name": "Rock_Stone_Cyberverse_Brick"
    },
    {
      "x": 0,
      "y": -5,
      "z": 1,
      "name": "Computer_Casing_Glow"
    },
    {
      "x": 0,
      "y": -4,
      "z": 1,
      "name": "Computer_Casing_Glow"
    },
    {
      "x": 0,
      "y": -3,
      "z": 1,
      "name": "Computer_Casing_Glow"
    },
    {
      "x": 0,
      "y": -2,
      "z": 1,
      "name": "Plant_Wires_Glow",
      "support": 15
    },
    {
      "x": 0,
      "y": -1,
      "z": 1,
      "name": "Rock_Stone_Cyberverse_Brick"
    },
    {
      "x": 0,
      "y": 0,
      "z": 1,
      "name": "Empty"
    },
    {
      "x": 0,
      "y": 1,
      "z": 1,
      "name": "Empty"
    },
    {
      "x": 0,
      "y": 2,
      "z": 1,
      "name": "Empty"
    },
    {
      "x": 0,
      "y": 3,
      "z": 1,
      "name": "Empty"
    },
    {
      "x": 0,
      "y": 4,
      "z": 1,
      "name": "Rock_Stone_Cyberverse_Brick"
    },
    {
      "x": 0,
      "y": 5,
      "z": 1,
      "name": "Empty"
    },
    {
      "x": 0,
      "y": 6,
      "z": 1,
      "name": "Empty"
    },
    {
      "x": 0,
      "y": 7,
      "z": 1,
      "name": "Empty"
    },
    {
      "x": 0,
      "y": -6,
      "z": 2,
      "name": "Rock_Stone_Cyberverse_Brick"
    },
    {
      "x": 0,
      "y": -5,
      "z": 2,
      "name": "Empty"
    },
    {
      "x": 0,
      "y": -4,
      "z": 2,
      "name": "Empty"
    },
    {
      "x": 0,
      "y": -3,
      "z": 2,
      "name": "Empty"
    },
    {
      "x": 0,
      "y": -2,
      "z": 2,
      "name": "Empty"
    },
    {
      "x": 0,
      "y": -1,
      "z": 2,
      "name": "Rock_Stone_Cyberverse_Brick"
    },
    {
      "x": 0,
      "y": 0,
      "z": 2,
      "name": "Plant_Wires_Glow",
      "support": 15
    },
    {
      "x": 0,
      "y": 1,
      "z": 2,
      "name": "Empty"
    },
    {
      "x": 0,
      "y": 2,
      "z": 2,
      "name": "Empty"
    },
    {
      "x": 0,
      "y": 3,
      "z": 2,
      "name": "Empty"
    },
    {
      "x": 0,
      "y": 4,
      "z": 2,
      "name": "Rock_Stone_Cyberverse_Brick"
    },
    {
      "x": 0,
      "y": 5,
      "z": 2,
      "name": "Empty"
    },
    {
      "x": 0,
      "y": 6,
      "z": 2,
      "name": "Empty"
    },
    {
      "x": 0,
      "y": 7,
      "z": 2,
      "name": "Empty"
    },
    {
      "x": 0,
      "y": -6,
      "z": 3,
      "name": "Rock_Stone_Cyberverse_Glitched"
    },
    {
      "x": 0,
      "y": -5,
      "z": 3,
      "name": "Rock_Stone_Cyberverse_Brick"
    },
    {
      "x": 0,
      "y": -4,
      "z": 3,
      "name": "Rock_Stone_Cyberverse_Brick"
    },
    {
      "x": 0,
      "y": -3,
      "z": 3,
      "name": "Rock_Stone_Cyberverse_Brick"
    },
    {
      "x": 0,
      "y": -2,
      "z": 3,
      "name": "Rock_Stone_Cyberverse_Brick"
    },
    {
      "x": 0,
      "y": -1,
      "z": 3,
      "name": "Rock_Stone_Cyberverse_Brick"
    },
    {
      "x": 0,
      "y": 0,
      "z": 3,
      "name": "Plant_Wires_Glow",
      "support": 15
    },
    {
      "x": 0,
      "y": 1,
      "z": 3,
      "name": "Empty"
    },
    {
      "x": 0,
      "y": 2,
      "z": 3,
      "name": "Empty"
    },
    {
      "x": 0,
      "y": 3,
      "z": 3,
      "name": "Empty"
    },
    {
      "x": 0,
      "y": 4,
      "z": 3,
      "name": "Rock_Stone_Cyberverse_Brick"
    },
    {
      "x": 0,
      "y": 5,
      "z": 3,
      "name": "Rock_Cyberverse_Brick_Half"
    },
    {
      "x": 0,
      "y": 6,
      "z": 3,
      "name": "Empty"
    },
    {
      "x": 0,
      "y": 7,
      "z": 3,
      "name": "Empty"
    },
    {
      "x": 0,
      "y": -6,
      "z": 4,
      "name": "Rock_Stone_Cyberverse"
    },
    {
      "x": 0,
      "y": -5,
      "z": 4,
      "name": "Rock_Stone_Cyberverse"
    },
    {
      "x": 0,
      "y": -4,
      "z": 4,
      "name": "Rock_Stone_Cyberverse"
    },
    {
      "x": 0,
      "y": -3,
      "z": 4,
      "name": "Rock_Stone_Cyberverse"
    },
    {
      "x": 0,
      "y": -2,
      "z": 4,
      "name": "Rock_Stone_Cyberverse"
    },
    {
      "x": 0,
      "y": -1,
      "z": 4,
      "name": "Rock_Stone_Cyberverse"
    },
    {
      "x": 0,
      "y": 0,
      "z": 4,
      "name": "Rock_Stone_Cyberverse_Brick"
    },
    {
      "x": 0,
      "y": 1,
      "z": 4,
      "name": "Rock_Stone_Cyberverse_Brick"
    },
    {
      "x": 0,
      "y": 2,
      "z": 4,
      "name": "Rock_Stone_Cyberverse_Brick"
    },
    {
      "x": 0,
      "y": 3,
      "z": 4,
      "name": "Rock_Stone_Cyberverse_Brick"
    },
    {
      "x": 0,
      "y": 4,
      "z": 4,
      "name": "Rock_Stone_Cyberverse_Brick"
    },
    {
      "x": 0,
      "y": 5,
      "z": 4,
      "name": "Empty"
    },
    {
      "x": 0,
      "y": 6,
      "z": 4,
      "name": "Empty"
    },
    {
      "x": 0,
      "y": 7,
      "z": 4,
      "name": "Empty"
    },
    {
      "x": 1,
      "y": -6,
      "z": -3,
      "name": "Rock_Stone_Cyberverse_Glitched"
    },
    {
      "x": 1,
      "y": -5,
      "z": -3,
      "name": "Rock_Stone_Cyberverse_Brick"
    },
    {
      "x": 1,
      "y": -4,
      "z": -3,
      "name": "Rock_Stone_Cyberverse_Brick"
    },
    {
      "x": 1,
      "y": -3,
      "z": -3,
      "name": "Rock_Stone_Cyberverse_Brick"
    },
    {
      "x": 1,
      "y": -2,
      "z": -3,
      "name": "Rock_Stone_Cyberverse_Brick"
    },
    {
      "x": 1,
      "y": -1,
      "z": -3,
      "name": "Rock_Stone_Cyberverse"
    },
    {
      "x": 1,
      "y": 0,
      "z": -3,
      "name": "Rock_Stone_Cyberverse_Brick"
    },
    {
      "x": 1,
      "y": 1,
      "z": -3,
      "name": "Rock_Stone_Cyberverse_Brick"
    },
    {
      "x": 1,
      "y": 2,
      "z": -3,
      "name": "Rock_Stone_Cyberverse_Brick"
    },
    {
      "x": 1,
      "y": 3,
      "z": -3,
      "name": "Rock_Stone_Cyberverse"
    },
    {
      "x": 1,
      "y": 4,
      "z": -3,
      "name": "Rock_Stone_Cyberverse_Brick"
    },
    {
      "x": 1,
      "y": 5,
      "z": -3,
      "name": "Rock_Stone_Cyberverse_Brick"
    },
    {
      "x": 1,
      "y": 6,
      "z": -3,
      "name": "Empty"
    },
    {
      "x": 1,
      "y": 7,
      "z": -3,
      "name": "Empty"
    },
    {
      "x": 1,
      "y": -6,
      "z": -2,
      "name": "Rock_Stone_Cyberverse_Brick"
    },
    {
      "x": 1,
      "y": -5,
      "z": -2,
      "name": "Empty"
    },
    {
      "x": 1,
      "y": -4,
      "z": -2,
      "name": "Empty"
    },
    {
      "x": 1,
      "y": -3,
      "z": -2,
      "name": "Empty"
    },
    {
      "x": 1,
      "y": -2,
      "z": -2,
      "name": "Empty"
    },
    {
      "x": 1,
      "y": -1,
      "z": -2,
      "name": "Rock_Stone_Cyberverse_Brick"
    },
    {
      "x": 1,
      "y": 0,
      "z": -2,
      "name": "Plant_Wires_Glow",
      "support": 15
    },
    {
      "x": 1,
      "y": 1,
      "z": -2,
      "name": "Empty"
    },
    {
      "x": 1,
      "y": 2,
      "z": -2,
      "name": "Empty"
    },
    {
      "x": 1,
      "y": 3,
      "z": -2,
      "name": "Empty"
    },
    {
      "x": 1,
      "y": 4,
      "z": -2,
      "name": "Rock_Stone_Cyberverse_Brick"
    },
    {
      "x": 1,
      "y": 5,
      "z": -2,
      "name": "Empty"
    },
    {
      "x": 1,
      "y": 6,
      "z": -2,
      "name": "Empty"
    },
    {
      "x": 1,
      "y": 7,
      "z": -2,
      "name": "Empty"
    },
    {
      "x": 1,
      "y": -6,
      "z": -1,
      "name": "Rock_Stone_Cyberverse_Brick"
    },
    {
      "x": 1,
      "y": -5,
      "z": -1,
      "name": "Computer_Casing_Glow"
    },
    {
      "x": 1,
      "y": -4,
      "z": -1,
      "name": "Computer_Casing_Glow"
    },
    {
      "x": 1,
      "y": -3,
      "z": -1,
      "name": "Computer_Casing_Glow"
    },
    {
      "x": 1,
      "y": -2,
      "z": -1,
      "name": "Plant_Wires_Glow",
      "support": 15
    },
    {
      "x": 1,
      "y": -1,
      "z": -1,
      "name": "Rock_Stone_Cyberverse_Brick"
    },
    {
      "x": 1,
      "y": 0,
      "z": -1,
      "name": "Plant_Wires_Glow",
      "support": 15
    },
    {
      "x": 1,
      "y": 1,
      "z": -1,
      "name": "Empty"
    },
    {
      "x": 1,
      "y": 2,
      "z": -1,
      "name": "Empty"
    },
    {
      "x": 1,
      "y": 3,
      "z": -1,
      "name": "Empty"
    },
    {
      "x": 1,
      "y": 4,
      "z": -1,
      "name": "Rock_Stone_Cyberverse_Brick"
    },
    {
      "x": 1,
      "y": 5,
      "z": -1,
      "name": "Empty"
    },
    {
      "x": 1,
      "y": 6,
      "z": -1,
      "name": "Empty"
    },
    {
      "x": 1,
      "y": 7,
      "z": -1,
      "name": "Empty"
    },
    {
      "x": 1,
      "y": -6,
      "z": 0,
      "name": "Rock_Stone_Cyberverse_Brick"
    },
    {
      "x": 1,
      "y": -5,
      "z": 0,
      "name": "Computer_Casing_Glow"
    },
    {
      "x": 1,
      "y": -4,
      "z": 0,
      "name": "Computer_Casing_Glow"
    },
    {
      "x": 1,
      "y": -3,
      "z": 0,
      "name": "Computer_Casing_Glow"
    },
    {
      "x": 1,
      "y": -2,
      "z": 0,
      "name": "Plant_Wires_Glow",
      "support": 15
    },
    {
      "x": 1,
      "y": -1,
      "z": 0,
      "name": "Rock_Stone_Cyberverse_Brick"
    },
    {
      "x": 1,
      "y": 0,
      "z": 0,
      "name": "Plant_Wires_Glow",
      "support": 15
    },
    {
      "x": 1,
      "y": 1,
      "z": 0,
      "name": "Empty"
    },
    {
      "x": 1,
      "y": 2,
      "z": 0,
      "name": "Empty"
    },
    {
      "x": 1,
      "y": 3,
      "z": 0,
      "name": "Empty"
    },
    {
      "x": 1,
      "y": 4,
      "z": 0,
      "name": "Rock_Stone_Cyberverse_Brick"
    },
    {
      "x": 1,
      "y": 5,
      "z": 0,
      "name": "Empty"
    },
    {
      "x": 1,
      "y": 6,
      "z": 0,
      "name": "Empty"
    },
    {
      "x": 1,
      "y": 7,
      "z": 0,
      "name": "Empty"
    },
    {
      "x": 1,
      "y": -6,
      "z": 1,
      "name": "Rock_Stone_Cyberverse_Brick"
    },
    {
      "x": 1,
      "y": -5,
      "z": 1,
      "name": "Computer_Casing_Glow"
    },
    {
      "x": 1,
      "y": -4,
      "z": 1,
      "name": "Computer_Casing_Glow"
    },
    {
      "x": 1,
      "y": -3,
      "z": 1,
      "name": "Computer_Casing_Glow"
    },
    {
      "x": 1,
      "y": -2,
      "z": 1,
      "name": "Plant_Wires_Glow",
      "support": 15
    },
    {
      "x": 1,
      "y": -1,
      "z": 1,
      "name": "Rock_Stone_Cyberverse_Brick"
    },
    {
      "x": 1,
      "y": 0,
      "z": 1,
      "name": "Plant_Wires_Glow",
      "support": 15
    },
    {
      "x": 1,
      "y": 1,
      "z": 1,
      "name": "Empty"
    },
    {
      "x": 1,
      "y": 2,
      "z": 1,
      "name": "Empty"
    },
    {
      "x": 1,
      "y": 3,
      "z": 1,
      "name": "Empty"
    },
    {
      "x": 1,
      "y": 4,
      "z": 1,
      "name": "Rock_Stone_Cyberverse_Brick"
    },
    {
      "x": 1,
      "y": 5,
      "z": 1,
      "name": "Empty"
    },
    {
      "x": 1,
      "y": 6,
      "z": 1,
      "name": "Empty"
    },
    {
      "x": 1,
      "y": 7,
      "z": 1,
      "name": "Empty"
    },
    {
      "x": 1,
      "y": -6,
      "z": 2,
      "name": "Rock_Stone_Cyberverse_Brick"
    },
    {
      "x": 1,
      "y": -5,
      "z": 2,
      "name": "Empty"
    },
    {
      "x": 1,
      "y": -4,
      "z": 2,
      "name": "Plant_Wires_Glow",
      "support": 15,
      "rotation": 4
    },
    {
      "x": 1,
      "y": -3,
      "z": 2,
      "name": "Empty"
    },
    {
      "x": 1,
      "y": -2,
      "z": 2,
      "name": "Empty"
    },
    {
      "x": 1,
      "y": -1,
      "z": 2,
      "name": "Rock_Stone_Cyberverse_Brick"
    },
    {
      "x": 1,
      "y": 0,
      "z": 2,
      "name": "Plant_Wires_Glow",
      "support": 15
    },
    {
      "x": 1,
      "y": 1,
      "z": 2,
      "name": "Empty"
    },
    {
      "x": 1,
      "y": 2,
      "z": 2,
      "name": "Empty"
    },
    {
      "x": 1,
      "y": 3,
      "z": 2,
      "name": "Empty"
    },
    {
      "x": 1,
      "y": 4,
      "z": 2,
      "name": "Rock_Stone_Cyberverse_Brick"
    },
    {
      "x": 1,
      "y": 5,
      "z": 2,
      "name": "Empty"
    },
    {
      "x": 1,
      "y": 6,
      "z": 2,
      "name": "Empty"
    },
    {
      "x": 1,
      "y": 7,
      "z": 2,
      "name": "Empty"
    },
    {
      "x": 1,
      "y": -6,
      "z": 3,
      "name": "Rock_Stone_Cyberverse_Glitched"
    },
    {
      "x": 1,
      "y": -5,
      "z": 3,
      "name": "Rock_Stone_Cyberverse_Brick"
    },
    {
      "x": 1,
      "y": -4,
      "z": 3,
      "name": "Rock_Stone_Cyberverse_Brick"
    },
    {
      "x": 1,
      "y": -3,
      "z": 3,
      "name": "Rock_Stone_Cyberverse_Brick"
    },
    {
      "x": 1,
      "y": -2,
      "z": 3,
      "name": "Rock_Stone_Cyberverse_Brick"
    },
    {
      "x": 1,
      "y": -1,
      "z": 3,
      "name": "Rock_Stone_Cyberverse_Brick"
    },
    {
      "x": 1,
      "y": 0,
      "z": 3,
      "name": "Plant_Wires_Glow",
      "support": 15
    },
    {
      "x": 1,
      "y": 1,
      "z": 3,
      "name": "Empty"
    },
    {
      "x": 1,
      "y": 2,
      "z": 3,
      "name": "Empty"
    },
    {
      "x": 1,
      "y": 3,
      "z": 3,
      "name": "Empty"
    },
    {
      "x": 1,
      "y": 4,
      "z": 3,
      "name": "Rock_Stone_Cyberverse_Brick"
    },
    {
      "x": 1,
      "y": 5,
      "z": 3,
      "name": "Empty"
    },
    {
      "x": 1,
      "y": 6,
      "z": 3,
      "name": "Empty"
    },
    {
      "x": 1,
      "y": 7,
      "z": 3,
      "name": "Empty"
    },
    {
      "x": 1,
      "y": -6,
      "z": 4,
      "name": "Rock_Stone_Cyberverse"
    },
    {
      "x": 1,
      "y": -5,
      "z": 4,
      "name": "Rock_Stone_Cyberverse"
    },
    {
      "x": 1,
      "y": -4,
      "z": 4,
      "name": "Rock_Stone_Cyberverse"
    },
    {
      "x": 1,
      "y": -3,
      "z": 4,
      "name": "Rock_Stone_Cyberverse"
    },
    {
      "x": 1,
      "y": -2,
      "z": 4,
      "name": "Rock_Stone_Cyberverse"
    },
    {
      "x": 1,
      "y": -1,
      "z": 4,
      "name": "Rock_Stone_Cyberverse"
    },
    {
      "x": 1,
      "y": 0,
      "z": 4,
      "name": "Rock_Stone_Cyberverse_Brick"
    },
    {
      "x": 1,
      "y": 1,
      "z": 4,
      "name": "Rock_Stone_Cyberverse_Brick"
    },
    {
      "x": 1,
      "y": 2,
      "z": 4,
      "name": "Rock_Stone_Cyberverse_Brick"
    },
    {
      "x": 1,
      "y": 3,
      "z": 4,
      "name": "Rock_Stone_Cyberverse_Brick"
    },
    {
      "x": 1,
      "y": 4,
      "z": 4,
      "name": "Rock_Stone_Cyberverse_Brick"
    },
    {
      "x": 1,
      "y": 5,
      "z": 4,
      "name": "Empty"
    },
    {
      "x": 1,
      "y": 6,
      "z": 4,
      "name": "Empty"
    },
    {
      "x": 1,
      "y": 7,
      "z": 4,
      "name": "Empty"
    },
    {
      "x": 2,
      "y": -6,
      "z": -3,
      "name": "Rock_Stone_Cyberverse_Glitched"
    },
    {
      "x": 2,
      "y": -5,
      "z": -3,
      "name": "Rock_Stone_Cyberverse_Brick"
    },
    {
      "x": 2,
      "y": -4,
      "z": -3,
      "name": "Rock_Stone_Cyberverse_Brick"
    },
    {
      "x": 2,
      "y": -3,
      "z": -3,
      "name": "Rock_Stone_Cyberverse_Brick"
    },
    {
      "x": 2,
      "y": -2,
      "z": -3,
      "name": "Rock_Stone_Cyberverse_Brick"
    },
    {
      "x": 2,
      "y": -1,
      "z": -3,
      "name": "Rock_Stone_Cyberverse_Glitched"
    },
    {
      "x": 2,
      "y": 0,
      "z": -3,
      "name": "Rock_Stone_Cyberverse_Brick"
    },
    {
      "x": 2,
      "y": 1,
      "z": -3,
      "name": "Rock_Stone_Cyberverse_Brick"
    },
    {
      "x": 2,
      "y": 2,
      "z": -3,
      "name": "Rock_Stone_Cyberverse_Brick"
    },
    {
      "x": 2,
      "y": 3,
      "z": -3,
      "name": "Rock_Stone_Cyberverse_Brick"
    },
    {
      "x": 2,
      "y": 4,
      "z": -3,
      "name": "Rock_Stone_Cyberverse_Brick"
    },
    {
      "x": 2,
      "y": 5,
      "z": -3,
      "name": "Rock_Stone_Cyberverse_Brick"
    },
    {
      "x": 2,
      "y": 6,
      "z": -3,
      "name": "Empty"
    },
    {
      "x": 2,
      "y": 7,
      "z": -3,
      "name": "Empty"
    },
    {
      "x": 2,
      "y": -6,
      "z": -2,
      "name": "Rock_Stone_Cyberverse_Brick"
    },
    {
      "x": 2,
      "y": -5,
      "z": -2,
      "name": "Empty"
    },
    {
      "x": 2,
      "y": -4,
      "z": -2,
      "name": "Empty"
    },
    {
      "x": 2,
      "y": -3,
      "z": -2,
      "name": "Empty"
    },
    {
      "x": 2,
      "y": -2,
      "z": -2,
      "name": "Empty"
    },
    {
      "x": 2,
      "y": -1,
      "z": -2,
      "name": "Rock_Stone_Cyberverse_Brick"
    },
    {
      "x": 2,
      "y": 0,
      "z": -2,
      "name": "Plant_Wires_Glow",
      "support": 15
    },
    {
      "x": 2,
      "y": 1,
      "z": -2,
      "name": "Empty"
    },
    {
      "x": 2,
      "y": 2,
      "z": -2,
      "name": "Empty"
    },
    {
      "x": 2,
      "y": 3,
      "z": -2,
      "name": "Empty"
    },
    {
      "x": 2,
      "y": 4,
      "z": -2,
      "name": "Rock_Stone_Cyberverse_Brick"
    },
    {
      "x": 2,
      "y": 5,
      "z": -2,
      "name": "Plant_Wires_Glow",
      "support": 15
    },
    {
      "x": 2,
      "y": 6,
      "z": -2,
      "name": "Empty"
    },
    {
      "x": 2,
      "y": 7,
      "z": -2,
      "name": "Empty"
    },
    {
      "x": 2,
      "y": -6,
      "z": -1,
      "name": "Rock_Stone_Cyberverse_Brick"
    },
    {
      "x": 2,
      "y": -5,
      "z": -1,
      "name": "Empty"
    },
    {
      "x": 2,
      "y": -4,
      "z": -1,
      "name": "Plant_Wires_Glow",
      "support": 15,
      "rotation": 5
    },
    {
      "x": 2,
      "y": -3,
      "z": -1,
      "name": "Empty"
    },
    {
      "x": 2,
      "y": -2,
      "z": -1,
      "name": "Empty"
    },
    {
      "x": 2,
      "y": -1,
      "z": -1,
      "name": "Rock_Stone_Cyberverse_Brick"
    },
    {
      "x": 2,
      "y": 0,
      "z": -1,
      "name": "Plant_Wires_Glow",
      "support": 15
    },
    {
      "x": 2,
      "y": 1,
      "z": -1,
      "name": "Empty"
    },
    {
      "x": 2,
      "y": 2,
      "z": -1,
      "name": "Empty"
    },
    {
      "x": 2,
      "y": 3,
      "z": -1,
      "name": "Empty"
    },
    {
      "x": 2,
      "y": 4,
      "z": -1,
      "name": "Rock_Stone_Cyberverse_Brick"
    },
    {
      "x": 2,
      "y": 5,
      "z": -1,
      "name": "Empty"
    },
    {
      "x": 2,
      "y": 6,
      "z": -1,
      "name": "Empty"
    },
    {
      "x": 2,
      "y": 7,
      "z": -1,
      "name": "Empty"
    },
    {
      "x": 2,
      "y": -6,
      "z": 0,
      "name": "Rock_Stone_Cyberverse_Brick"
    },
    {
      "x": 2,
      "y": -5,
      "z": 0,
      "name": "Empty"
    },
    {
      "x": 2,
      "y": -4,
      "z": 0,
      "name": "Empty"
    },
    {
      "x": 2,
      "y": -3,
      "z": 0,
      "name": "Empty"
    },
    {
      "x": 2,
      "y": -2,
      "z": 0,
      "name": "Empty"
    },
    {
      "x": 2,
      "y": -1,
      "z": 0,
      "name": "Rock_Stone_Cyberverse_Brick"
    },
    {
      "x": 2,
      "y": 0,
      "z": 0,
      "name": "Plant_Wires_Glow",
      "support": 15
    },
    {
      "x": 2,
      "y": 1,
      "z": 0,
      "name": "Empty"
    },
    {
      "x": 2,
      "y": 2,
      "z": 0,
      "name": "Empty"
    },
    {
      "x": 2,
      "y": 3,
      "z": 0,
      "name": "Empty"
    },
    {
      "x": 2,
      "y": 4,
      "z": 0,
      "name": "Rock_Stone_Cyberverse_Brick"
    },
    {
      "x": 2,
      "y": 5,
      "z": 0,
      "name": "Empty"
    },
    {
      "x": 2,
      "y": 6,
      "z": 0,
      "name": "Empty"
    },
    {
      "x": 2,
      "y": 7,
      "z": 0,
      "name": "Empty"
    },
    {
      "x": 2,
      "y": -6,
      "z": 1,
      "name": "Rock_Stone_Cyberverse_Brick"
    },
    {
      "x": 2,
      "y": -5,
      "z": 1,
      "name": "Empty"
    },
    {
      "x": 2,
      "y": -4,
      "z": 1,
      "name": "Empty"
    },
    {
      "x": 2,
      "y": -3,
      "z": 1,
      "name": "Plant_Wires_Glow",
      "support": 15,
      "rotation": 5
    },
    {
      "x": 2,
      "y": -2,
      "z": 1,
      "name": "Empty"
    },
    {
      "x": 2,
      "y": -1,
      "z": 1,
      "name": "Rock_Stone_Cyberverse_Brick"
    },
    {
      "x": 2,
      "y": 0,
      "z": 1,
      "name": "Plant_Wires_Glow",
      "support": 15
    },
    {
      "x": 2,
      "y": 1,
      "z": 1,
      "name": "Empty"
    },
    {
      "x": 2,
      "y": 2,
      "z": 1,
      "name": "Empty"
    },
    {
      "x": 2,
      "y": 3,
      "z": 1,
      "name": "Empty"
    },
    {
      "x": 2,
      "y": 4,
      "z": 1,
      "name": "Rock_Stone_Cyberverse_Brick"
    },
    {
      "x": 2,
      "y": 5,
      "z": 1,
      "name": "Empty"
    },
    {
      "x": 2,
      "y": 6,
      "z": 1,
      "name": "Empty"
    },
    {
      "x": 2,
      "y": 7,
      "z": 1,
      "name": "Empty"
    },
    {
      "x": 2,
      "y": -6,
      "z": 2,
      "name": "Rock_Stone_Cyberverse_Brick"
    },
    {
      "x": 2,
      "y": -5,
      "z": 2,
      "name": "Empty"
    },
    {
      "x": 2,
      "y": -4,
      "z": 2,
      "name": "Empty"
    },
    {
      "x": 2,
      "y": -3,
      "z": 2,
      "name": "Empty"
    },
    {
      "x": 2,
      "y": -2,
      "z": 2,
      "name": "Empty"
    },
    {
      "x": 2,
      "y": -1,
      "z": 2,
      "name": "Rock_Stone_Cyberverse_Brick"
    },
    {
      "x": 2,
      "y": 0,
      "z": 2,
      "name": "Empty"
    },
    {
      "x": 2,
      "y": 1,
      "z": 2,
      "name": "Empty"
    },
    {
      "x": 2,
      "y": 2,
      "z": 2,
      "name": "Empty"
    },
    {
      "x": 2,
      "y": 3,
      "z": 2,
      "name": "Empty"
    },
    {
      "x": 2,
      "y": 4,
      "z": 2,
      "name": "Rock_Stone_Cyberverse_Brick"
    },
    {
      "x": 2,
      "y": 5,
      "z": 2,
      "name": "Empty"
    },
    {
      "x": 2,
      "y": 6,
      "z": 2,
      "name": "Empty"
    },
    {
      "x": 2,
      "y": 7,
      "z": 2,
      "name": "Empty"
    },
    {
      "x": 2,
      "y": -6,
      "z": 3,
      "name": "Rock_Stone_Cyberverse"
    },
    {
      "x": 2,
      "y": -5,
      "z": 3,
      "name": "Rock_Stone_Cyberverse_Brick"
    },
    {
      "x": 2,
      "y": -4,
      "z": 3,
      "name": "Rock_Stone_Cyberverse_Brick"
    },
    {
      "x": 2,
      "y": -3,
      "z": 3,
      "name": "Rock_Stone_Cyberverse_Brick"
    },
    {
      "x": 2,
      "y": -2,
      "z": 3,
      "name": "Rock_Stone_Cyberverse_Brick"
    },
    {
      "x": 2,
      "y": -1,
      "z": 3,
      "name": "Rock_Stone_Cyberverse_Brick"
    },
    {
      "x": 2,
      "y": 0,
      "z": 3,
      "name": "Empty"
    },
    {
      "x": 2,
      "y": 1,
      "z": 3,
      "name": "Empty"
    },
    {
      "x": 2,
      "y": 2,
      "z": 3,
      "name": "Empty"
    },
    {
      "x": 2,
      "y": 3,
      "z": 3,
      "name": "Empty"
    },
    {
      "x": 2,
      "y": 4,
      "z": 3,
      "name": "Rock_Stone_Cyberverse_Brick"
    },
    {
      "x": 2,
      "y": 5,
      "z": 3,
      "name": "Plant_Wires_Glow",
      "support": 15
    },
    {
      "x": 2,
      "y": 6,
      "z": 3,
      "name": "Empty"
    },
    {
      "x": 2,
      "y": 7,
      "z": 3,
      "name": "Empty"
    },
    {
      "x": 2,
      "y": -6,
      "z": 4,
      "name": "Rock_Stone_Cyberverse"
    },
    {
      "x": 2,
      "y": -5,
      "z": 4,
      "name": "Rock_Stone_Cyberverse"
    },
    {
      "x": 2,
      "y": -4,
      "z": 4,
      "name": "Rock_Stone_Cyberverse"
    },
    {
      "x": 2,
      "y": -3,
      "z": 4,
      "name": "Rock_Stone_Cyberverse"
    },
    {
      "x": 2,
      "y": -2,
      "z": 4,
      "name": "Rock_Stone_Cyberverse"
    },
    {
      "x": 2,
      "y": -1,
      "z": 4,
      "name": "Rock_Stone_Cyberverse"
    },
    {
      "x": 2,
      "y": 0,
      "z": 4,
      "name": "Rock_Stone_Cyberverse_Brick"
    },
    {
      "x": 2,
      "y": 1,
      "z": 4,
      "name": "Rock_Stone_Cyberverse_Brick"
    },
    {
      "x": 2,
      "y": 2,
      "z": 4,
      "name": "Rock_Stone_Cyberverse_Brick"
    },
    {
      "x": 2,
      "y": 3,
      "z": 4,
      "name": "Rock_Stone_Cyberverse_Brick"
    },
    {
      "x": 2,
      "y": 4,
      "z": 4,
      "name": "Rock_Stone_Cyberverse_Brick"
    },
    {
      "x": 2,
      "y": 5,
      "z": 4,
      "name": "Rock_Cyberverse_Brick_Half"
    },
    {
      "x": 2,
      "y": 6,
      "z": 4,
      "name": "Empty"
    },
    {
      "x": 2,
      "y": 7,
      "z": 4,
      "name": "Empty"
    },
    {
      "x": 3,
      "y": -6,
      "z": -3,
      "name": "Rock_Stone_Cyberverse"
    },
    {
      "x": 3,
      "y": -5,
      "z": -3,
      "name": "Rock_Stone_Cyberverse"
    },
    {
      "x": 3,
      "y": -4,
      "z": -3,
      "name": "Rock_Stone_Cyberverse"
    },
    {
      "x": 3,
      "y": -3,
      "z": -3,
      "name": "Rock_Stone_Cyberverse"
    },
    {
      "x": 3,
      "y": -2,
      "z": -3,
      "name": "Rock_Stone_Cyberverse_Brick"
    },
    {
      "x": 3,
      "y": -1,
      "z": -3,
      "name": "Rock_Stone_Cyberverse"
    },
    {
      "x": 3,
      "y": 0,
      "z": -3,
      "name": "Rock_Stone_Cyberverse_Brick"
    },
    {
      "x": 3,
      "y": 1,
      "z": -3,
      "name": "Rock_Stone_Cyberverse_Brick"
    },
    {
      "x": 3,
      "y": 2,
      "z": -3,
      "name": "Rock_Stone_Cyberverse_Brick"
    },
    {
      "x": 3,
      "y": 3,
      "z": -3,
      "name": "Rock_Stone_Cyberverse_Brick"
    },
    {
      "x": 3,
      "y": 4,
      "z": -3,
      "name": "Rock_Stone_Cyberverse_Brick"
    },
    {
      "x": 3,
      "y": 5,
      "z": -3,
      "name": "Rock_Stone_Cyberverse_Brick"
    },
    {
      "x": 3,
      "y": 6,
      "z": -3,
      "name": "Rock_Stone_Cyberverse_Brick"
    },
    {
      "x": 3,
      "y": 7,
      "z": -3,
      "name": "Empty"
    },
    {
      "x": 3,
      "y": -6,
      "z": -2,
      "name": "Rock_Stone_Cyberverse"
    },
    {
      "x": 3,
      "y": -5,
      "z": -2,
      "name": "Rock_Stone_Cyberverse_Brick"
    },
    {
      "x": 3,
      "y": -4,
      "z": -2,
      "name": "Rock_Stone_Cyberverse_Brick"
    },
    {
      "x": 3,
      "y": -3,
      "z": -2,
      "name": "Rock_Stone_Cyberverse_Brick"
    },
    {
      "x": 3,
      "y": -2,
      "z": -2,
      "name": "Rock_Stone_Cyberverse_Brick"
    },
    {
      "x": 3,
      "y": -1,
      "z": -2,
      "name": "Rock_Stone_Cyberverse_Brick"
    },
    {
      "x": 3,
      "y": 0,
      "z": -2,
      "name": "Plant_Wires_Glow",
      "support": 15
    },
    {
      "x": 3,
      "y": 1,
      "z": -2,
      "name": "Empty"
    },
    {
      "x": 3,
      "y": 2,
      "z": -2,
      "name": "Empty"
    },
    {
      "x": 3,
      "y": 3,
      "z": -2,
      "name": "Empty"
    },
    {
      "x": 3,
      "y": 4,
      "z": -2,
      "name": "Rock_Stone_Cyberverse_Brick"
    },
    {
      "x": 3,
      "y": 5,
      "z": -2,
      "name": "Plant_Wires_Glow",
      "support": 15
    },
    {
      "x": 3,
      "y": 6,
      "z": -2,
      "name": "Empty"
    },
    {
      "x": 3,
      "y": 7,
      "z": -2,
      "name": "Empty"
    },
    {
      "x": 3,
      "y": -6,
      "z": -1,
      "name": "Rock_Stone_Cyberverse_Glitched"
    },
    {
      "x": 3,
      "y": -5,
      "z": -1,
      "name": "Rock_Stone_Cyberverse_Brick"
    },
    {
      "x": 3,
      "y": -4,
      "z": -1,
      "name": "Rock_Stone_Cyberverse_Brick"
    },
    {
      "x": 3,
      "y": -3,
      "z": -1,
      "name": "Rock_Stone_Cyberverse_Brick"
    },
    {
      "x": 3,
      "y": -2,
      "z": -1,
      "name": "Rock_Stone_Cyberverse_Brick"
    },
    {
      "x": 3,
      "y": -1,
      "z": -1,
      "name": "Rock_Stone_Cyberverse_Brick"
    },
    {
      "x": 3,
      "y": 0,
      "z": -1,
      "name": "Rock_Cyberverse_Brick_Half",
      "rotation": 7
    },
    {
      "x": 3,
      "y": 1,
      "z": -1,
      "name": "Rock_Cyberverse_Brick_Half",
      "rotation": 7
    },
    {
      "x": 3,
      "y": 2,
      "z": -1,
      "name": "Rock_Cyberverse_Brick_Half",
      "rotation": 7
    },
    {
      "x": 3,
      "y": 3,
      "z": -1,
      "name": "Rock_Cyberverse_Brick_Half",
      "rotation": 7
    },
    {
      "x": 3,
      "y": 4,
      "z": -1,
      "name": "Rock_Stone_Cyberverse_Brick"
    },
    {
      "x": 3,
      "y": 5,
      "z": -1,
      "name": "Plant_Wires_Glow",
      "support": 15
    },
    {
      "x": 3,
      "y": 6,
      "z": -1,
      "name": "Empty"
    },
    {
      "x": 3,
      "y": 7,
      "z": -1,
      "name": "Empty"
    },
    {
      "x": 3,
      "y": -6,
      "z": 0,
      "name": "Rock_Stone_Cyberverse_Glitched"
    },
    {
      "x": 3,
      "y": -5,
      "z": 0,
      "name": "Rock_Stone_Cyberverse_Brick"
    },
    {
      "x": 3,
      "y": -4,
      "z": 0,
      "name": "Rock_Stone_Cyberverse_Brick"
    },
    {
      "x": 3,
      "y": -3,
      "z": 0,
      "name": "Rock_Stone_Cyberverse_Brick"
    },
    {
      "x": 3,
      "y": -2,
      "z": 0,
      "name": "Rock_Stone_Cyberverse_Brick"
    },
    {
      "x": 3,
      "y": -1,
      "z": 0,
      "name": "Rock_Stone_Cyberverse_Brick"
    },
    {
      "x": 3,
      "y": 0,
      "z": 0,
      "name": "Plant_Wires_Glow",
      "support": 15,
      "rotation": 7
    },
    {
      "x": 3,
      "y": 1,
      "z": 0,
      "name": "Plant_Wires_Glow",
      "support": 15,
      "rotation": 7
    },
    {
      "x": 3,
      "y": 2,
      "z": 0,
      "name": "Plant_Wires_Glow",
      "support": 15,
      "rotation": 7
    },
    {
      "x": 3,
      "y": 3,
      "z": 0,
      "name": "Plant_Wires_Glow",
      "support": 15,
      "rotation": 7
    },
    {
      "x": 3,
      "y": 4,
      "z": 0,
      "name": "Rock_Stone_Cyberverse_Brick"
    },
    {
      "x": 3,
      "y": 5,
      "z": 0,
      "name": "Empty"
    },
    {
      "x": 3,
      "y": 6,
      "z": 0,
      "name": "Empty"
    },
    {
      "x": 3,
      "y": 7,
      "z": 0,
      "name": "Empty"
    },
    {
      "x": 3,
      "y": -6,
      "z": 1,
      "name": "Rock_Stone_Cyberverse_Glitched"
    },
    {
      "x": 3,
      "y": -5,
      "z": 1,
      "name": "Rock_Stone_Cyberverse_Brick"
    },
    {
      "x": 3,
      "y": -4,
      "z": 1,
      "name": "Rock_Stone_Cyberverse_Brick"
    },
    {
      "x": 3,
      "y": -3,
      "z": 1,
      "name": "Rock_Stone_Cyberverse_Brick"
    },
    {
      "x": 3,
      "y": -2,
      "z": 1,
      "name": "Rock_Stone_Cyberverse_Brick"
    },
    {
      "x": 3,
      "y": -1,
      "z": 1,
      "name": "Rock_Stone_Cyberverse_Brick"
    },
    {
      "x": 3,
      "y": 0,
      "z": 1,
      "name": "Plant_Wires_Glow",
      "support": 15,
      "rotation": 7
    },
    {
      "x": 3,
      "y": 1,
      "z": 1,
      "name": "Plant_Wires_Glow",
      "support": 15,
      "rotation": 7
    },
    {
      "x": 3,
      "y": 2,
      "z": 1,
      "name": "Plant_Wires_Glow",
      "support": 15,
      "rotation": 7
    },
    {
      "x": 3,
      "y": 3,
      "z": 1,
      "name": "Plant_Wires_Glow",
      "support": 15,
      "rotation": 7
    },
    {
      "x": 3,
      "y": 4,
      "z": 1,
      "name": "Rock_Stone_Cyberverse_Brick"
    },
    {
      "x": 3,
      "y": 5,
      "z": 1,
      "name": "Empty"
    },
    {
      "x": 3,
      "y": 6,
      "z": 1,
      "name": "Empty"
    },
    {
      "x": 3,
      "y": 7,
      "z": 1,
      "name": "Empty"
    },
    {
      "x": 3,
      "y": -6,
      "z": 2,
      "name": "Rock_Stone_Cyberverse"
    },
    {
      "x": 3,
      "y": -5,
      "z": 2,
      "name": "Rock_Stone_Cyberverse_Brick"
    },
    {
      "x": 3,
      "y": -4,
      "z": 2,
      "name": "Rock_Stone_Cyberverse_Brick"
    },
    {
      "x": 3,
      "y": -3,
      "z": 2,
      "name": "Rock_Stone_Cyberverse_Brick"
    },
    {
      "x": 3,
      "y": -2,
      "z": 2,
      "name": "Rock_Stone_Cyberverse_Brick"
    },
    {
      "x": 3,
      "y": -1,
      "z": 2,
      "name": "Rock_Stone_Cyberverse_Brick"
    },
    {
      "x": 3,
      "y": 0,
      "z": 2,
      "name": "Rock_Cyberverse_Brick_Half",
      "rotation": 7
    },
    {
      "x": 3,
      "y": 1,
      "z": 2,
      "name": "Rock_Cyberverse_Brick_Half",
      "rotation": 7
    },
    {
      "x": 3,
      "y": 2,
      "z": 2,
      "name": "Rock_Cyberverse_Brick_Half",
      "rotation": 7
    },
    {
      "x": 3,
      "y": 3,
      "z": 2,
      "name": "Rock_Cyberverse_Brick_Half",
      "rotation": 7
    },
    {
      "x": 3,
      "y": 4,
      "z": 2,
      "name": "Rock_Stone_Cyberverse_Brick"
    },
    {
      "x": 3,
      "y": 5,
      "z": 2,
      "name": "Plant_Wires_Glow",
      "support": 15
    },
    {
      "x": 3,
      "y": 6,
      "z": 2,
      "name": "Empty"
    },
    {
      "x": 3,
      "y": 7,
      "z": 2,
      "name": "Empty"
    },
    {
      "x": 3,
      "y": -6,
      "z": 3,
      "name": "Rock_Stone_Cyberverse"
    },
    {
      "x": 3,
      "y": -5,
      "z": 3,
      "name": "Rock_Stone_Cyberverse"
    },
    {
      "x": 3,
      "y": -4,
      "z": 3,
      "name": "Rock_Stone_Cyberverse"
    },
    {
      "x": 3,
      "y": -3,
      "z": 3,
      "name": "Rock_Stone_Cyberverse"
    },
    {
      "x": 3,
      "y": -2,
      "z": 3,
      "name": "Rock_Stone_Cyberverse_Brick"
    },
    {
      "x": 3,
      "y": -1,
      "z": 3,
      "name": "Rock_Stone_Cyberverse_Brick"
    },
    {
      "x": 3,
      "y": 0,
      "z": 3,
      "name": "Empty"
    },
    {
      "x": 3,
      "y": 1,
      "z": 3,
      "name": "Empty"
    },
    {
      "x": 3,
      "y": 2,
      "z": 3,
      "name": "Empty"
    },
    {
      "x": 3,
      "y": 3,
      "z": 3,
      "name": "Empty"
    },
    {
      "x": 3,
      "y": 4,
      "z": 3,
      "name": "Rock_Stone_Cyberverse_Brick"
    },
    {
      "x": 3,
      "y": 5,
      "z": 3,
      "name": "Plant_Wires_Glow",
      "support": 15,
      "rotation": 6
    },
    {
      "x": 3,
      "y": 6,
      "z": 3,
      "name": "Empty"
    },
    {
      "x": 3,
      "y": 7,
      "z": 3,
      "name": "Empty"
    },
    {
      "x": 3,
      "y": -6,
      "z": 4,
      "name": "Rock_Stone_Cyberverse"
    },
    {
      "x": 3,
      "y": -5,
      "z": 4,
      "name": "Rock_Stone_Cyberverse"
    },
    {
      "x": 3,
      "y": -4,
      "z": 4,
      "name": "Rock_Stone_Cyberverse"
    },
    {
      "x": 3,
      "y": -3,
      "z": 4,
      "name": "Rock_Stone_Cyberverse"
    },
    {
      "x": 3,
      "y": -2,
      "z": 4,
      "name": "Rock_Stone_Cyberverse"
    },
    {
      "x": 3,
      "y": -1,
      "z": 4,
      "name": "Rock_Stone_Cyberverse"
    },
    {
      "x": 3,
      "y": 0,
      "z": 4,
      "name": "Rock_Stone_Cyberverse_Brick"
    },
    {
      "x": 3,
      "y": 1,
      "z": 4,
      "name": "Rock_Stone_Cyberverse_Brick"
    },
    {
      "x": 3,
      "y": 2,
      "z": 4,
      "name": "Rock_Stone_Cyberverse_Brick"
    },
    {
      "x": 3,
      "y": 3,
      "z": 4,
      "name": "Rock_Stone_Cyberverse_Brick"
    },
    {
      "x": 3,
      "y": 4,
      "z": 4,
      "name": "Rock_Stone_Cyberverse_Brick"
    },
    {
      "x": 3,
      "y": 5,
      "z": 4,
      "name": "Rock_Stone_Cyberverse_Brick"
    },
    {
      "x": 3,
      "y": 6,
      "z": 4,
      "name": "Rock_Cyberverse_Brick_Half"
    },
    {
      "x": 3,
      "y": 7,
      "z": 4,
      "name": "Empty"
    },
    {
      "x": 4,
      "y": -6,
      "z": -3,
      "name": "Rock_Stone_Cyberverse"
    },
    {
      "x": 4,
      "y": -5,
      "z": -3,
      "name": "Rock_Stone_Cyberverse"
    },
    {
      "x": 4,
      "y": -4,
      "z": -3,
      "name": "Rock_Stone_Cyberverse"
    },
    {
      "x": 4,
      "y": -3,
      "z": -3,
      "name": "Rock_Stone_Cyberverse"
    },
    {
      "x": 4,
      "y": -2,
      "z": -3,
      "name": "Rock_Stone_Cyberverse"
    },
    {
      "x": 4,
      "y": -1,
      "z": -3,
      "name": "Rock_Stone_Cyberverse"
    },
    {
      "x": 4,
      "y": 0,
      "z": -3,
      "name": "Rock_Stone_Cyberverse_Brick"
    },
    {
      "x": 4,
      "y": 1,
      "z": -3,
      "name": "Rock_Stone_Cyberverse_Brick"
    },
    {
      "x": 4,
      "y": 2,
      "z": -3,
      "name": "Rock_Stone_Cyberverse"
    },
    {
      "x": 4,
      "y": 3,
      "z": -3,
      "name": "Rock_Stone_Cyberverse_Brick"
    },
    {
      "x": 4,
      "y": 4,
      "z": -3,
      "name": "Rock_Stone_Cyberverse_Brick"
    },
    {
      "x": 4,
      "y": 5,
      "z": -3,
      "name": "Rock_Stone_Cyberverse_Brick"
    },
    {
      "x": 4,
      "y": 6,
      "z": -3,
      "name": "Rock_Stone_Cyberverse_Brick"
    },
    {
      "x": 4,
      "y": 7,
      "z": -3,
      "name": "Rock_Stone_Cyberverse_Brick"
    },
    {
      "x": 4,
      "y": -6,
      "z": -2,
      "name": "Rock_Stone_Cyberverse"
    },
    {
      "x": 4,
      "y": -5,
      "z": -2,
      "name": "Rock_Stone_Cyberverse"
    },
    {
      "x": 4,
      "y": -4,
      "z": -2,
      "name": "Rock_Stone_Cyberverse"
    },
    {
      "x": 4,
      "y": -3,
      "z": -2,
      "name": "Rock_Stone_Cyberverse"
    },
    {
      "x": 4,
      "y": -2,
      "z": -2,
      "name": "Rock_Stone_Cyberverse"
    },
    {
      "x": 4,
      "y": -1,
      "z": -2,
      "name": "Rock_Stone_Cyberverse"
    },
    {
      "x": 4,
      "y": 0,
      "z": -2,
      "name": "Rock_Stone_Cyberverse_Brick"
    },
    {
      "x": 4,
      "y": 1,
      "z": -2,
      "name": "Rock_Stone_Cyberverse_Brick"
    },
    {
      "x": 4,
      "y": 2,
      "z": -2,
      "name": "Rock_Stone_Cyberverse_Brick"
    },
    {
      "x": 4,
      "y": 3,
      "z": -2,
      "name": "Rock_Stone_Cyberverse_Brick"
    },
    {
      "x": 4,
      "y": 4,
      "z": -2,
      "name": "Rock_Stone_Cyberverse_Brick"
    },
    {
      "x": 4,
      "y": 5,
      "z": -2,
      "name": "Rock_Stone_Cyberverse_Brick"
    },
    {
      "x": 4,
      "y": 6,
      "z": -2,
      "name": "Rock_Cyberverse_Brick_Half"
    },
    {
      "x": 4,
      "y": 7,
      "z": -2,
      "name": "Empty"
    },
    {
      "x": 4,
      "y": -6,
      "z": -1,
      "name": "Rock_Stone_Cyberverse"
    },
    {
      "x": 4,
      "y": -5,
      "z": -1,
      "name": "Rock_Stone_Cyberverse"
    },
    {
      "x": 4,
      "y": -4,
      "z": -1,
      "name": "Rock_Stone_Cyberverse"
    },
    {
      "x": 4,
      "y": -3,
      "z": -1,
      "name": "Rock_Stone_Cyberverse"
    },
    {
      "x": 4,
      "y": -2,
      "z": -1,
      "name": "Rock_Stone_Cyberverse"
    },
    {
      "x": 4,
      "y": -1,
      "z": -1,
      "name": "Rock_Stone_Cyberverse"
    },
    {
      "x": 4,
      "y": 0,
      "z": -1,
      "name": "Rock_Stone_Cyberverse_Brick"
    },
    {
      "x": 4,
      "y": 1,
      "z": -1,
      "name": "Rock_Stone_Cyberverse_Brick"
    },
    {
      "x": 4,
      "y": 2,
      "z": -1,
      "name": "Rock_Stone_Cyberverse_Brick"
    },
    {
      "x": 4,
      "y": 3,
      "z": -1,
      "name": "Rock_Stone_Cyberverse_Brick"
    },
    {
      "x": 4,
      "y": 4,
      "z": -1,
      "name": "Rock_Stone_Cyberverse_Brick"
    },
    {
      "x": 4,
      "y": 5,
      "z": -1,
      "name": "Empty"
    },
    {
      "x": 4,
      "y": 6,
      "z": -1,
      "name": "Empty"
    },
    {
      "x": 4,
      "y": 7,
      "z": -1,
      "name": "Empty"
    },
    {
      "x": 4,
      "y": -6,
      "z": 0,
      "name": "Rock_Stone_Cyberverse"
    },
    {
      "x": 4,
      "y": -5,
      "z": 0,
      "name": "Rock_Stone_Cyberverse"
    },
    {
      "x": 4,
      "y": -4,
      "z": 0,
      "name": "Rock_Stone_Cyberverse"
    },
    {
      "x": 4,
      "y": -3,
      "z": 0,
      "name": "Rock_Stone_Cyberverse"
    },
    {
      "x": 4,
      "y": -2,
      "z": 0,
      "name": "Rock_Stone_Cyberverse"
    },
    {
      "x": 4,
      "y": -1,
      "z": 0,
      "name": "Rock_Stone_Cyberverse"
    },
    {
      "x": 4,
      "y": 0,
      "z": 0,
      "name": "Rock_Stone_Cyberverse_Brick"
    },
    {
      "x": 4,
      "y": 1,
      "z": 0,
      "name": "Rock_Stone_Cyberverse_Brick"
    },
    {
      "x": 4,
      "y": 2,
      "z": 0,
      "name": "Rock_Stone_Cyberverse_Brick"
    },
    {
      "x": 4,
      "y": 3,
      "z": 0,
      "name": "Rock_Stone_Cyberverse_Brick"
    },
    {
      "x": 4,
      "y": 4,
      "z": 0,
      "name": "Rock_Stone_Cyberverse_Brick"
    },
    {
      "x": 4,
      "y": 5,
      "z": 0,
      "name": "Empty"
    },
    {
      "x": 4,
      "y": 6,
      "z": 0,
      "name": "Empty"
    },
    {
      "x": 4,
      "y": 7,
      "z": 0,
      "name": "Empty"
    },
    {
      "x": 4,
      "y": -6,
      "z": 1,
      "name": "Rock_Stone_Cyberverse"
    },
    {
      "x": 4,
      "y": -5,
      "z": 1,
      "name": "Rock_Stone_Cyberverse"
    },
    {
      "x": 4,
      "y": -4,
      "z": 1,
      "name": "Rock_Stone_Cyberverse"
    },
    {
      "x": 4,
      "y": -3,
      "z": 1,
      "name": "Rock_Stone_Cyberverse"
    },
    {
      "x": 4,
      "y": -2,
      "z": 1,
      "name": "Rock_Stone_Cyberverse"
    },
    {
      "x": 4,
      "y": -1,
      "z": 1,
      "name": "Rock_Stone_Cyberverse"
    },
    {
      "x": 4,
      "y": 0,
      "z": 1,
      "name": "Rock_Stone_Cyberverse_Brick"
    },
    {
      "x": 4,
      "y": 1,
      "z": 1,
      "name": "Rock_Stone_Cyberverse_Brick"
    },
    {
      "x": 4,
      "y": 2,
      "z": 1,
      "name": "Rock_Stone_Cyberverse_Brick"
    },
    {
      "x": 4,
      "y": 3,
      "z": 1,
      "name": "Rock_Stone_Cyberverse_Brick"
    },
    {
      "x": 4,
      "y": 4,
      "z": 1,
      "name": "Rock_Stone_Cyberverse_Brick"
    },
    {
      "x": 4,
      "y": 5,
      "z": 1,
      "name": "Rock_Cyberverse_Brick_Half"
    },
    {
      "x": 4,
      "y": 6,
      "z": 1,
      "name": "Empty"
    },
    {
      "x": 4,
      "y": 7,
      "z": 1,
      "name": "Empty"
    },
    {
      "x": 4,
      "y": -6,
      "z": 2,
      "name": "Rock_Stone_Cyberverse"
    },
    {
      "x": 4,
      "y": -5,
      "z": 2,
      "name": "Rock_Stone_Cyberverse"
    },
    {
      "x": 4,
      "y": -4,
      "z": 2,
      "name": "Rock_Stone_Cyberverse"
    },
    {
      "x": 4,
      "y": -3,
      "z": 2,
      "name": "Rock_Stone_Cyberverse"
    },
    {
      "x": 4,
      "y": -2,
      "z": 2,
      "name": "Rock_Stone_Cyberverse"
    },
    {
      "x": 4,
      "y": -1,
      "z": 2,
      "name": "Rock_Stone_Cyberverse"
    },
    {
      "x": 4,
      "y": 0,
      "z": 2,
      "name": "Rock_Stone_Cyberverse_Brick"
    },
    {
      "x": 4,
      "y": 1,
      "z": 2,
      "name": "Rock_Stone_Cyberverse_Brick"
    },
    {
      "x": 4,
      "y": 2,
      "z": 2,
      "name": "Rock_Stone_Cyberverse_Brick"
    },
    {
      "x": 4,
      "y": 3,
      "z": 2,
      "name": "Rock_Stone_Cyberverse_Brick"
    },
    {
      "x": 4,
      "y": 4,
      "z": 2,
      "name": "Rock_Stone_Cyberverse_Brick"
    },
    {
      "x": 4,
      "y": 5,
      "z": 2,
      "name": "Rock_Stone_Cyberverse_Brick"
    },
    {
      "x": 4,
      "y": 6,
      "z": 2,
      "name": "Empty"
    },
    {
      "x": 4,
      "y": 7,
      "z": 2,
      "name": "Empty"
    },
    {
      "x": 4,
      "y": -6,
      "z": 3,
      "name": "Rock_Stone_Cyberverse"
    },
    {
      "x": 4,
      "y": -5,
      "z": 3,
      "name": "Rock_Stone_Cyberverse"
    },
    {
      "x": 4,
      "y": -4,
      "z": 3,
      "name": "Rock_Stone_Cyberverse"
    },
    {
      "x": 4,
      "y": -3,
      "z": 3,
      "name": "Rock_Stone_Cyberverse"
    },
    {
      "x": 4,
      "y": -2,
      "z": 3,
      "name": "Rock_Stone_Cyberverse"
    },
    {
      "x": 4,
      "y": -1,
      "z": 3,
      "name": "Rock_Stone_Cyberverse"
    },
    {
      "x": 4,
      "y": 0,
      "z": 3,
      "name": "Rock_Stone_Cyberverse_Brick"
    },
    {
      "x": 4,
      "y": 1,
      "z": 3,
      "name": "Rock_Stone_Cyberverse_Brick"
    },
    {
      "x": 4,
      "y": 2,
      "z": 3,
      "name": "Rock_Stone_Cyberverse_Brick"
    },
    {
      "x": 4,
      "y": 3,
      "z": 3,
      "name": "Rock_Stone_Cyberverse_Brick"
    },
    {
      "x": 4,
      "y": 4,
      "z": 3,
      "name": "Rock_Stone_Cyberverse_Brick"
    },
    {
      "x": 4,
      "y": 5,
      "z": 3,
      "name": "Rock_Stone_Cyberverse_Brick"
    },
    {
      "x": 4,
      "y": 6,
      "z": 3,
      "name": "Rock_Cyberverse_Brick_Half"
    },
    {
      "x": 4,
      "y": 7,
      "z": 3,
      "name": "Empty"
    },
    {
      "x": 4,
      "y": -6,
      "z": 4,
      "name": "Rock_Stone_Cyberverse"
    },
    {
      "x": 4,
      "y": -5,
      "z": 4,
      "name": "Rock_Stone_Cyberverse"
    },
    {
      "x": 4,
      "y": -4,
      "z": 4,
      "name": "Rock_Stone_Cyberverse"
    },
    {
      "x": 4,
      "y": -3,
      "z": 4,
      "name": "Rock_Stone_Cyberverse"
    },
    {
      "x": 4,
      "y": -2,
      "z": 4,
      "name": "Rock_Stone_Cyberverse"
    },
    {
      "x": 4,
      "y": -1,
      "z": 4,
      "name": "Rock_Stone_Cyberverse"
    },
    {
      "x": 4,
      "y": 0,
      "z": 4,
      "name": "Rock_Stone_Cyberverse_Brick"
    },
    {
      "x": 4,
      "y": 1,
      "z": 4,
      "name": "Rock_Stone_Cyberverse_Brick"
    },
    {
      "x": 4,
      "y": 2,
      "z": 4,
      "name": "Rock_Stone_Cyberverse_Brick"
    },
    {
      "x": 4,
      "y": 3,
      "z": 4,
      "name": "Rock_Stone_Cyberverse_Brick"
    },
    {
      "x": 4,
      "y": 4,
      "z": 4,
      "name": "Rock_Stone_Cyberverse_Brick"
    },
    {
      "x": 4,
      "y": 5,
      "z": 4,
      "name": "Rock_Cyberverse_Brick_Half"
    },
    {
      "x": 4,
      "y": 6,
      "z": 4,
      "name": "Empty"
    },
    {
      "x": 4,
      "y": 7,
      "z": 4,
      "name": "Empty"
    }
  ]
}